Workbook
Name AUD: FX!$C$5
Name CHF: FX!$C$3
Name CNY: FX!$C$11
Name DKK: FX!$C$2
Name DKKUSD: #REF!
Name EUR: FX!$C$4
Name GBP: FX!$C$6
Name HKD: FX!$C$8
Name INR: FX!$C$10
Name JPY: FX!$C$7
Name KRW: FX!$C$9

Sheet Main
D2: =RANDBETWEEN(1,D304) -> 198 | H2: =SUM(H5:H458)-H15-H12-H9-H23-H20-H26-H50-China!F17 -> 6139258.2 | M2: =MIN(M5:M67) -> 45540 | O2: =AVERAGE(O5:O36) -> -0.066630371 | S2: EV/EPS | AB2: EPS | AO2: =AVERAGE(AO5:AO106) -> 0.061854076 | AP2: =AVERAGE(AP5:AP106) -> 0.044232656 | AQ2: =AVERAGE(AQ5:AQ106) -> 0.045486892 | AR2: =AVERAGE(AR5:AR106) -> 0.28833087
B3: R | C3: C | E3: Name | F3: Ticker | G3: Price | H3: MC | I3: NC | J3: EV | K3: Update | L3: SO | M3: Last | N3: NPV | O3: Upside | P3: ROIC | Q3: Terminal | R3: Discount | S3: 2022 | T3: 2023 | U3: 2024 | V3: 2025 | W3: 2026 | X3: 2027 | Y3: 2028 | Z3: 2029 | AA3: 2030 | AB3: 2022 | AC3: 2023 | AD3: 2024 | AE3: 2025 | AF3: 2026 | AG3: 2027 | AH3: 2028 | AI3: 2029 | AJ3: 2030 | AK3: 2031 | AL3: Founded | AM3: Location | AN3: Country | AO3: YTD | AP3: MTD | AQ3: M/M | AR3: Y/Y | AS3: 2025 | AT3: 2024 | AU3: 2023 | AV3: 2022 | AW3: 2021 | AX3: 2020 | BD3: 46199 | BE3: =+BD3-1 -> 46198 | BF3: =+BE3-1 -> 46197 | BG3: =+BF3-1 -> 46196 | BH3: =+BG3-1 -> 46195 | BI3: 46192 | BJ3: =+BH3-4 -> 46191 | BK3: =+BJ3-1 -> 46190 | BL3: =+BK3-1 -> 46189 | BM3: =+BL3-1 -> 46188 | BN3: =+BM3-3 -> 46185 | BO3: =+BN3-1 -> 46184 | BP3: =+BO3-1 -> 46183 | BQ3: =+BP3-1 -> 46182 | BR3: =+BQ3-1 -> 46181 | BS3: =+BR3-3 -> 46178 | BT3: =+BS3-1 -> 46177 | BU3: =+BT3-1 -> 46176 | BV3: =+BU3-1 -> 46175 | BW3: =+BV3-1 -> 46174 | BX3: =+BW3-3 -> 46171 | BY3: =+BX3-1 -> 46170 | BZ3: =+BY3-1 -> 46169 | CA3: =+BZ3-1 -> 46168 | CB3: =+CA3-4 -> 46164 | CC3: =+CB3-1 -> 46163 | CD3: =+CC3-1 -> 46162 | CE3: =+CD3-1 -> 46161 | CF3: =+CE3-1 -> 46160 | CG3: =+CF3-3 -> 46157 | CH3: =+CG3-1 -> 46156 | CI3: =+CH3-1 -> 46155 | CJ3: =+CI3-1 -> 46154 | CK3: =+CJ3-1 -> 46153 | CL3: =+CK3-3 -> 46150 | CM3: =+CL3-1 -> 46149 | CN3: =+CM3-1 -> 46148 | CO3: =+CN3-1 -> 46147 | CP3: =+CO3-1 -> 46146 | CQ3: =+CP3-3 -> 46143 | CR3: =+CQ3-1 -> 46142 | CS3: =+CR3-1 -> 46141 | CT3: =+CS3-1 -> 46140 | CU3: =+CT3-1 -> 46139 | CV3: =+CU3-3 -> 46136 | CW3: =+CV3-1 -> 46135 | CX3: =+CW3-1 -> 46134 | CY3: =+CX3-1 -> 46133 | CZ3: =+CY3-1 -> 46132 | DA3: =+CZ3-3 -> 46129 | DB3: =+DA3-1 -> 46128 | DC3: =+DB3-1 -> 46127 | DD3: =+DC3-1 -> 46126 | DE3: =+DD3-1 -> 46125 | DF3: =+DE3-3 -> 46122 | DG3: =+DF3-1 -> 46121 | DH3: =+DG3-1 -> 46120 | DI3: =+DH3-1 -> 46119 | DJ3: =+DI3-1 -> 46118 | DK3: =+DJ3-4 -> 46114 | DL3: =+DK3-1 -> 46113 | DM3: =+DL3-1 -> 46112 | DN3: =+DM3-1 -> 46111 | DO3: =+DN3-3 -> 46108 | DP3: =+DO3-1 -> 46107 | DQ3: =+DP3-1 -> 46106 | DR3: =+DQ3-1 -> 46105 | DS3: =+DR3-1 -> 46104 | DT3: =+DS3-3 -> 46101 | DU3: =+DT3-1 -> 46100 | DV3: =+DU3-1 -> 46099 | DW3: =+DV3-1 -> 46098 | DX3: =+DW3-1 -> 46097 | DY3: =+DX3-3 -> 46094 | DZ3: =+DY3-1 -> 46093 | EA3: =+DZ3-1 -> 46092 | EB3: =+EA3-1 -> 46091 | EC3: =+EB3-1 -> 46090 | ED3: =+EC3-3 -> 46087 | EE3: =+ED3-1 -> 46086 | EF3: =+EE3-1 -> 46085 | EG3: =+EF3-1 -> 46084 | EH3: =+EG3-1 -> 46083 | EI3: =+EH3-3 -> 46080 | EJ3: =+EI3-1 -> 46079 | EK3: =+EJ3-1 -> 46078 | EL3: =+EK3-1 -> 46077 | EM3: =+EL3-1 -> 46076 | EN3: =+EM3-3 -> 46073 | EO3: =+EN3-1 -> 46072 | EP3: =+EO3-1 -> 46071 | EQ3: =+EP3-1 -> 46070 | ER3: =+EQ3-4 -> 46066 | ES3: =+ER3-1 -> 46065 | ET3: =+ES3-1 -> 46064 | EU3: =+ET3-1 -> 46063 | EV3: =+EU3-1 -> 46062 | EW3: =+EV3-3 -> 46059 | EX3: =+EW3-1 -> 46058 | EY3: =+EX3-1 -> 46057 | EZ3: =+EY3-1 -> 46056 | FA3: =+EZ3-1 -> 46055 | FB3: =+FA3-3 -> 46052 | FC3: =+FB3-1 -> 46051 | FD3: =+FC3-1 -> 46050 | FE3: =+FD3-1 -> 46049 | FF3: =+FE3-1 -> 46048 | FG3: =+FF3-3 -> 46045 | FH3: =+FG3-1 -> 46044 | FI3: =+FH3-1 -> 46043 | FJ3: =+FI3-1 -> 46042 | FK3: =+FJ3-4 -> 46038 | FL3: =+FK3-1 -> 46037 | FM3: =+FL3-1 -> 46036 | FN3: =+FM3-1 -> 46035 | FO3: =+FN3-1 -> 46034 | FP3: =+FO3-3 -> 46031 | FQ3: =+FP3-1 -> 46030 | FR3: =+FQ3-1 -> 46029 | FS3: =+FR3-1 -> 46028 | FT3: =+FS3-1 -> 46027 | FU3: =+FT3-3 -> 46024 | FV3: =FU3-2 -> 46022 | FW3: =+FV3-1 -> 46021 | FX3: =+FW3-1 -> 46020 | FY3: =+FX3-3 -> 46017 | FZ3: =+FY3-2 -> 46015 | GA3: =+FZ3-1 -> 46014 | GB3: =+GA3-1 -> 46013 | GC3: =+GB3-3 -> 46010 | GD3: =+GC3-1 -> 46009 | GE3: =+GD3-1 -> 46008 | GF3: =+GE3-1 -> 46007 | GG3: =+GF3-1 -> 46006 | GH3: =+GG3-3 -> 46003 | GI3: =+GH3-1 -> 46002 | GJ3: =+GI3-1 -> 46001 | GK3: =+GJ3-1 -> 46000 | GL3: =+GK3-1 -> 45999 | GM3: =+GL3-3 -> 45996 | GN3: =+GM3-1 -> 45995 | GO3: =+GN3-1 -> 45994 | GP3: =+GO3-1 -> 45993 | GQ3: =+GP3-1 -> 45992 | GR3: =+GQ3-3 -> 45989 | GS3: =+GR3-2 -> 45987 | GT3: =+GS3-1 -> 45986 | GU3: =+GT3-1 -> 45985 | GV3: =+GU3-3 -> 45982 | GW3: =+GV3-1 -> 45981 | GX3: =+GW3-1 -> 45980 | GY3: =+GX3-1 -> 45979 | GZ3: =+GY3-1 -> 45978 | HA3: =+GZ3-3 -> 45975 | HB3: =+HA3-1 -> 45974 | HC3: =+HB3-1 -> 45973 | HD3: =+HC3-1 -> 45972 | HE3: =+HD3-1 -> 45971 | HF3: =HE3-3 -> 45968 | HG3: =+HF3-1 -> 45967 | HH3: =+HG3-1 -> 45966 | HI3: =+HH3-1 -> 45965 | HJ3: =+HI3-1 -> 45964 | HK3: =+HJ3-3 -> 45961 | HL3: =+HK3-1 -> 45960 | HM3: =+HL3-1 -> 45959 | HN3: =+HM3-1 -> 45958 | HO3: =+HN3-1 -> 45957 | HP3: =+HO3-3 -> 45954 | HQ3: =+HP3-1 -> 45953 | HR3: =+HQ3-1 -> 45952 | HS3: =+HR3-1 -> 45951 | HT3: =+HS3-1 -> 45950 | HU3: =+HT3-3 -> 45947 | HV3: =+HU3-1 -> 45946 | HW3: =+HV3-1 -> 45945 | HX3: =+HW3-1 -> 45944 | HY3: =+HX3-1 -> 45943 | HZ3: =+HY3-3 -> 45940 | IA3: =+HZ3-1 -> 45939 | IB3: =+IA3-1 -> 45938 | IC3: =+IB3-1 -> 45937 | ID3: =+IC3-1 -> 45936 | IE3: =+ID3-3 -> 45933 | IF3: =+IE3-1 -> 45932 | IG3: =+IF3-1 -> 45931 | IH3: =+IG3-1 -> 45930 | II3: =+IH3-1 -> 45929 | IJ3: =+II3-3 -> 45926 | IK3: =+IJ3-1 -> 45925 | IL3: =+IK3-1 -> 45924 | IM3: =+IL3-1 -> 45923 | IN3: =+IM3-1 -> 45922 | IO3: =+IN3-3 -> 45919 | IP3: =+IO3-1 -> 45918 | IQ3: =+IP3-1 -> 45917 | IR3: =+IQ3-1 -> 45916 | IS3: =+IR3-1 -> 45915 | IT3: =+IS3-3 -> 45912 | IU3: =+IT3-1 -> 45911 | IV3: =+IU3-1 -> 45910 | IW3: =+IV3-1 -> 45909 | IX3: =+IW3-1 -> 45908 | IY3: =+IX3-3 -> 45905 | IZ3: =+IY3-1 -> 45904 | JA3: =+IZ3-1 -> 45903 | JB3: =+JA3-1 -> 45902 | JC3: =+JB3-4 -> 45898 | JD3: =+JC3-1 -> 45897 | JE3: =+JD3-1 -> 45896 | JF3: =+JE3-1 -> 45895 | JG3: =+JF3-1 -> 45894 | JH3: =+JG3-3 -> 45891 | JI3: =+JH3-1 -> 45890 | JJ3: =+JI3-1 -> 45889 | JK3: =+JJ3-1 -> 45888 | JL3: =+JK3-1 -> 45887 | JM3: =+JL3-3 -> 45884 | JN3: =+JM3-1 -> 45883 | JO3: =+JN3-1 -> 45882 | JP3: =+JO3-1 -> 45881 | JQ3: =+JP3-1 -> 45880 | JR3: =+JQ3-3 -> 45877 | JS3: =+JR3-1 -> 45876 | JT3: =+JS3-1 -> 45875 | JU3: =+JT3-1 -> 45874 | JV3: =+JU3-1 -> 45873 | JW3: =+JV3-3 -> 45870 | JX3: =+JW3-1 -> 45869 | JY3: =+JX3-1 -> 45868 | JZ3: =+JY3-1 -> 45867 | KA3: =+JZ3-1 -> 45866 | KB3: =+KA3-3 -> 45863 | KC3: =+KB3-1 -> 45862 | KD3: =+KC3-1 -> 45861 | KE3: =+KD3-1 -> 45860 | KF3: =+KE3-1 -> 45859 | KG3: =+KF3-3 -> 45856 | KH3: =+KG3-1 -> 45855 | KI3: =+KH3-1 -> 45854 | KJ3: =+KI3-1 -> 45853 | KK3: =+KJ3-1 -> 45852 | KL3: =+KK3-3 -> 45849 | KM3: =+KL3-1 -> 45848 | KN3: =+KM3-1 -> 45847 | KO3: =+KN3-1 -> 45846 | KP3: =+KO3-1 -> 45845 | KQ3: =+KP3-4 -> 45841 | KR3: =+KQ3-1 -> 45840 | KS3: =+KR3-1 -> 45839 | KT3: =+KS3-1 -> 45838
S4: =TRIMMEAN(S5:S345,10%) -> 42.279125 | T4: =TRIMMEAN(T5:T345,10%) -> 35.327268 | U4: =TRIMMEAN(U5:U345,10%) -> 29.58952 | V4: =TRIMMEAN(V5:V345,10%) -> 24.145118 | W4: =TRIMMEAN(W5:W345,10%) -> 18.035849 | X4: =TRIMMEAN(X5:X345,10%) -> 16.263831 | Y4: =TRIMMEAN(Y5:Y345,10%) -> 14.91945 | Z4: =TRIMMEAN(Z5:Z345,10%) -> 14.27409 | AA4: =TRIMMEAN(AA5:AA345,10%) -> 13.223686 | AB4: - | AC4: - | AD4: - | AE4: - | AF4: - | AG4: - | AH4: - | AI4: - | AJ4: - | AK4: - | AL4: =AVERAGE(AL5:AL271) -> 1965.2188
A5: x | D5: 1 | E5: Eli Lilly | F5: LLY | G5: 1185.85 | H5: =+G5*L5 -> 1060149.9 | I5: =+[1]Main!$J$5-[1]Main!$J$6 -> -42102 | J5: =H5-I5 -> 1102251.9 | K5: Q226 | L5: =+[1]Main!$J$3 -> 894 | M5: 46243 | N5: =[1]Model!$GL$102 -> 1227.0562 | O5: =+N5/G5-1 -> 0.03474822 | P5: =[1]Model!$GL$98 -> 0.02 | Q5: =[1]Model!$GL$99 -> 0 | R5: =[1]Model!$GL$100 -> 0.07 | S5: =($J5/$L5)/AB5 -> 162.87239 | T5: =($J5/$L5)/AC5 -> 134.74797 | U5: =($J5/$L5)/AD5 -> 81.275146 | V5: =($J5/$L5)/AE5 -> 47.148909 | W5: =($J5/$L5)/AF5 -> 34.267481 | X5: =($J5/$L5)/AG5 -> 26.687099 | Y5: =($J5/$L5)/AH5 -> 23.06724 | Z5: =($J5/$L5)/AI5 -> 20.767121 | AA5: =($J5/$L5)/AJ5 -> 19.000523 | AB5: 7.57 | AC5: 9.15 | AD5: 15.17 | AE5: 26.15 | AF5: 35.98 | AG5: 46.2 | AH5: 53.45 | AI5: 59.37 | AJ5: 64.89 | AK5: 70.98 | AL5: 1876 | AM5: Indiana | AN5: United States | AO5: =BD5/FV5-1 -> 0.12416719 | AP5: =BD5/BX5-1 -> 0.093321267 | AQ5: =BD5/CA5-1 -> 0.13466198 | AR5: =BD5/KT5-1 -> 0.54980565 | BD5: 1208.12 | BE5: 1127.69 | BF5: 1117.26 | BG5: 1107.08 | BH5: 1102.08 | BJ5: 1098.57 | BK5: 1112 | BL5: 1122.5 | BM5: 1129.35 | BN5: 1133 | BO5: 1160.95 | BP5: 1136.37 | BQ5: 1144.68 | BR5: 1149.15 | BS5: 1131.42 | BT5: 1125.27 | BU5: 1078.78 | BV5: 1064.15 | BW5: 1082.2 | BX5: 1105 | BY5: 1126.8 | BZ5: 1082.92 | CA5: 1064.74 | CB5: 1065 | CC5: 1041.65 | CD5: 1018.87 | CE5: 1021.41 | CF5: 988.09 | CG5: 1004.92 | CH5: 1006.7 | CI5: 1015.75 | CJ5: 989.87 | CK5: 966.99 | CL5: 948.45 | CM5: 974.96 | CN5: 987.05 | CO5: 988.87 | CP5: 967.93 | CQ5: 963.33 | CR5: 934.6 | CS5: 851.21 | CT5: 874 | CU5: 868.27 | CV5: 883.96 | CW5: 917.65 | CX5: 921.48 | CY5: 903.02 | CZ5: 919.9 | DA5: 927.03 | DB5: 903.99 | DC5: 905.03 | DD5: 922.5 | DE5: 929.55 | DF5: 939.47 | DG5: 955.19 | DH5: 953.3 | DI5: 931.09 | DJ5: 927.06 | DK5: 935.58 | DL5: 954.52 | DM5: 919.77 | DN5: 886.63 | DO5: 878.24 | DP5: 897 | DQ5: 916.31 | DR5: 903.02 | DS5: 910.55 | DT5: 906.7 | DU5: 917.5 | DV5: 918.05 | DW5: 930.35 | DX5: 989.12 | DY5: 985.08 | DZ5: 977.25 | EA5: 999.84 | EB5: 1001.35 | EC5: 1008.39 | ED5: 990.33 | EE5: 983.26 | EF5: 1003.57 | EG5: 1007.73 | EH5: 1017.97 | EI5: 1051.99 | EJ5: 1022.02 | EK5: 1028.83 | EL5: 1042.15 | EM5: 1058.56 | EN5: 1009.52 | EO5: 1023.22 | EP5: 1020.56 | EQ5: 1036.05 | ER5: 1040 | ES5: 1038.27 | ET5: 1015.21 | EU5: 1025 | EV5: 1044.67 | EW5: 1058.18 | EX5: 1020.84 | EY5: 1107.12 | EZ5: 1003.46 | FA5: 1044.13 | FB5: 1037.15 | FC5: 1024.14 | FD5: 1023.8 | FE5: 1039.51 | FF5: 1062.75 | FG5: 1064.29 | FH5: 1087.38 | FI5: 1078.52 | FJ5: 1041.29 | FK5: 1038.4 | FL5: 1032.97 | FM5: 1073.29 | FN5: 1077.19 | FO5: 1081 | FP5: 1063.56 | FQ5: 1085.19 | FR5: 1108.09 | FS5: 1064.04 | FT5: 1041.51 | FU5: 1080.36 | FV5: 1074.68 | FW5: 1079.75 | FX5: 1078.73 | FY5: 1077.75 | FZ5: 1076.98 | GA5: 1071.64 | GB5: 1076.48 | GC5: 1071.44 | GD5: 1056.88 | GE5: 1041.79 | GF5: 1054.29 | GG5: 1062.19 | GH5: 1027.51 | GI5: 1009.38 | GJ5: 993.64 | GK5: 982.22 | GL5: 997.59 | GM5: 1010.31 | GN5: 1014.49 | GO5: 1033.56 | GP5: 1046.12 | GQ5: 1057.89 | GR5: 1075.47 | GS5: 1104.34 | GT5: 1109.94 | GU5: 1070.16 | GV5: 1059.7 | GW5: 1043.29 | GX5: 1049.6 | GY5: 1030.05 | GZ5: 1021.7 | HA5: 1025.28 | HB5: 1022.87 | HC5: 1017.78 | HD5: 988.62 | HE5: 966.64 | HF5: 924.37 | HG5: 937.44 | HH5: 925.81 | HI5: 906.86 | HJ5: 896.53 | HK5: 862.86 | HL5: 844.5 | HM5: 813.53 | HN5: 820.1 | HO5: 826.41 | HP5: 825.45 | HQ5: 821.04 | HR5: 812.43 | HS5: 799.57 | HT5: 808.96 | HU5: 802.83 | HV5: 819.38 | HW5: 826.57 | HX5: 812.35 | HY5: 819.4 | HZ5: 833.49 | IA5: 855.35 | IB5: 845.72 | IC5: 843.63 | ID5: 845.05 | IE5: 839.87 | IF5: 819.85 | IG5: 825.42 | IH5: 763 | II5: 726.51 | IJ5: 724.54 | IK5: 714.59 | IL5: 741.85 | IM5: 746.98 | IN5: 754.95 | IO5: 751.99 | IP5: 762.93 | IQ5: 760.13 | IR5: 764.71 | IS5: 748.19 | IT5: 755.39 | IU5: 756.28 | IV5: 754.62 | IW5: 750.61 | IX5: 738.64 | IY5: 727.21 | IZ5: 742.91 | JA5: 737.83 | JB5: 735.19 | JC5: 732.58 | JD5: 731.96 | JE5: 734.17 | JF5: 736.03 | JG5: 695.33 | JH5: 711.68 | JI5: 709.82 | JJ5: 705.44 | JK5: 703.21 | JL5: 698.05 | JM5: 701.23 | JN5: 684.43 | JO5: 660.49 | JP5: 639.43 | JQ5: 635.22 | JR5: 625.65 | JS5: 640.86 | JT5: 746.37 | JU5: 765.95 | JV5: 769 | JW5: 762.33 | JX5: 740.07 | JY5: 760.08 | JZ5: 762.95 | KA5: 808.11 | KB5: 812.69 | KC5: 805.43 | KD5: 798.89 | KE5: 776.44 | KF5: 762.18 | KG5: 771.71 | KH5: 761.5 | KI5: 789.8 | KJ5: 771.75 | KK5: 799.34 | KL5: 793.01 | KM5: 790.65 | KN5: 786.92 | KO5: 777.66 | KP5: 772.87 | KQ5: 780.67 | KR5: 779.28 | KS5: 775.9 | KT5: 779.53
A6: x | D6: 2 | E6: J&J | F6: JNJ | G6: 259.72 | H6: =+G6*L6 -> 625405.76 | I6: =+[2]Main!$L$5-[2]Main!$L$6 -> -28278 | J6: =H6-I6 -> 653683.76 | K6: Q226 | L6: =+[2]Main!$L$3 -> 2408 | M6: 46243 | N6: =[2]Model!$FV$85 -> 175.06971 | O6: =N6/G6-1 -> -0.32592903 | P6: =+[2]Model!$FV$78 -> 0.02 | Q6: =[2]Model!$FR$79 -> 0 | R6: =[2]Model!$FR$80 -> 0 | S6: =($J6/$L6)/AB6 -> 35.531853 | T6: =($J6/$L6)/AC6 -> 32.049983 | U6: =($J6/$L6)/AD6 -> 32.394195 | V6: =($J6/$L6)/AE6 -> 29.410981 | W6: =($J6/$L6)/AF6 -> 23.503321 | X6: =($J6/$L6)/AG6 -> 21.442603 | Y6: =($J6/$L6)/AH6 -> 19.22545 | Z6: =($J6/$L6)/AI6 -> 16.871557 | AA6: =($J6/$L6)/AJ6 -> 15.098073 | AB6: 7.64 | AC6: 8.47 | AD6: 8.38 | AE6: 9.23 | AF6: 11.55 | AG6: 12.66 | AH6: 14.12 | AI6: 16.09 | AJ6: 17.98 | AK6: 20.57 | AL6: 1886 | AM6: New Jersey | AN6: United States | AO6: =BD6/FV6-1 -> 0.23053878 | AP6: =BD6/BX6-1 -> 0.13016465 | AQ6: =BD6/CA6-1 -> 0.10635155 | AR6: =BD6/KT6-1 -> 0.66716858 | BD6: 254.66 | BE6: 244.88 | BF6: 241 | BG6: 239.08 | BH6: 231.29 | BJ6: 228.39 | BK6: 234.2 | BL6: 235.18 | BM6: 235.66 | BN6: 240.87 | BO6: 238.33 | BP6: 238.49 | BQ6: 237 | BR6: 232.16 | BS6: 232.77 | BT6: 228.17 | BU6: 223.24 | BV6: 222.89 | BW6: 223.51 | BX6: 225.33 | BY6: 230.8 | BZ6: 231.29 | CA6: 230.18 | CB6: 234.34 | CC6: 231.73 | CD6: 229.32 | CE6: 230 | CF6: 228.92 | CG6: 226.71 | CH6: 230.8 | CI6: 230.42 | CJ6: 224.26 | CK6: 221.43 | CL6: 221.32 | CM6: 222.51 | CN6: 224.62 | CO6: 225.55 | CP6: 224.2 | CQ6: 227.19 | CR6: 229.85 | CS6: 227.35 | CT6: 227.79 | CU6: 225.34 | CV6: 227.5 | CW6: 230.65 | CX6: 226.1 | CY6: 226.16 | CZ6: 230.69 | DA6: 234.18 | DB6: 234.54 | DC6: 238.67 | DD6: 240.1 | DE6: 237.96 | DF6: 238.46 | DG6: 241.31 | DH6: 241.3 | DI6: 238.41 | DJ6: 240.97 | DK6: 243.04 | DL6: 244.12 | DM6: 244.44 | DN6: 242.49 | DO6: 240.45 | DP6: 239.24 | DQ6: 239.93 | DR6: 235.27 | DS6: 235.42 | DT6: 235.37 | DU6: 237.6 | DV6: 237.28 | DW6: 238.11 | DX6: 243.19 | DY6: 241.52 | DZ6: 242.04 | EA6: 242.99 | EB6: 243.71 | EC6: 242.59 | ED6: 240.4 | EE6: 239.63 | EF6: 245.3 | EG6: 246.75 | EH6: 248.56 | EI6: 248.43 | EJ6: 243.47 | EK6: 245.17 | EL6: 246.28 | EM6: 245.84 | EN6: 242.49 | EO6: 246.91 | EP6: 244.99 | EQ6: 243.33 | ER6: 243.45 | ES6: 244.55 | ET6: 240.86 | EU6: 238.35 | EV6: 238.64 | EW6: 239.99 | EX6: 237.79 | EY6: 234.47 | EZ6: 233.1 | FA6: 230.75 | FB6: 227.25 | FC6: 227.29 | FD6: 227.72 | FE6: 224.44 | FF6: 221.49 | FG6: 220.14 | FH6: 218.49 | FI6: 218.01 | FJ6: 218.21 | FK6: 218.66 | FL6: 219.57 | FM6: 218.55 | FN6: 213.65 | FO6: 209.72 | FP6: 204.39 | FQ6: 205.75 | FR6: 207.49 | FS6: 204.79 | FT6: 204.31 | FU6: 207.35 | FV6: 206.95 | FW6: 206.91 | FX6: 207.56 | FY6: 207.63 | FZ6: 207.78 | GA6: 205.78 | GB6: 207.32 | GC6: 206.37 | GD6: 208.31 | GE6: 210.33 | GF6: 209.3 | GG6: 214.17 | GH6: 211.58 | GI6: 210.01 | GJ6: 206.54 | GK6: 199.96 | GL6: 201.62 | GM6: 201.93 | GN6: 202.48 | GO6: 205.33 | GP6: 205.42 | GQ6: 205.34 | GR6: 206.92 | GS6: 207.56 | GT6: 206.67 | GU6: 206.05 | GV6: 203.9 | GW6: 203.07 | GX6: 202.51 | GY6: 200 | GZ6: 199.58 | HA6: 195.93 | HB6: 195.25 | HC6: 194.39 | HD6: 193.83 | HE6: 188.41 | HF6: 186.57 | HG6: 186.97 | HH6: 186 | HI6: 186.86 | HJ6: 186.26 | HK6: 188.87 | HL6: 189.05 | HM6: 186.6 | HN6: 186.93 | HO6: 190.3 | HP6: 190.4 | HQ6: 192.47 | HR6: 192.94 | HS6: 191.88 | HT6: 193.72 | HU6: 193.22 | HV6: 192.12 | HW6: 191.17 | HX6: 190.85 | HY6: 190.9 | HZ6: 190.72 | IA6: 191.08 | IB6: 189.69 | IC6: 188.89 | ID6: 188.16 | IE6: 188.64 | IF6: 185.98 | IG6: 186.05 | IH6: 185.42 | II6: 181.62 | IJ6: 179.71 | IK6: 177.73 | IL6: 176.69 | IM6: 176.58 | IN6: 174.21 | IO6: 176.19 | IP6: 174.16 | IQ6: 177.2 | IR6: 176.46 | IS6: 177.4 | IT6: 178.06 | IU6: 178.5 | IV6: 175.79 | IW6: 176.96 | IX6: 178.13 | IY6: 178.43 | IZ6: 178.76 | JA6: 178 | JB6: 178.06 | JC6: 177.17 | JD6: 175.45 | JE6: 176.79 | JF6: 176.49 | JG6: 178.41 | JH6: 179.29 | JI6: 178.93 | JJ6: 178.84 | JK6: 177.8 | JL6: 176.25 | JM6: 176.64 | JN6: 174.72 | JO6: 174.42 | JP6: 172.78 | JQ6: 173.82 | JR6: 173.33 | JS6: 171.53 | JT6: 170.59 | JU6: 170.74 | JV6: 171.04 | JW6: 167.33 | JX6: 164.74 | JY6: 167.26 | JZ6: 168.11 | KA6: 166.22 | KB6: 168.3 | KC6: 169.56 | KD6: 169.1 | KE6: 167.93 | KF6: 164.36 | KG6: 163.7 | KH6: 162.98 | KI6: 164.78 | KJ6: 155.17 | KK6: 156.82 | KL6: 156.9 | KM6: 157.69 | KN6: 156.28 | KO6: 155.79 | KP6: 155.27 | KQ6: 156.01 | KR6: 155.56 | KS6: 155.92 | KT6: 152.75
A7: x | D7: 3 | E7: AbbVie | F7: ABBV | G7: 246.04 | H7: =+G7*L7 -> 435736.84 | I7: =+[3]Main!$K$5-[3]Main!$K$6 -> -63987 | J7: =H7-I7 -> 499723.84 | K7: Q226 | L7: =+[3]Main!$K$3 -> 1771 | M7: 46243 | N7: =[3]Model!$DX$79 -> 224.94848 | O7: =+N7/G7-1 -> -0.085723936 | P7: =[3]Model!$DX$77 -> 0 | Q7: =[3]Model!$DX$76 -> -0.01 | R7: =[3]Model!$DX$75 -> 0.06 | S7: =($J7/$L7)/AB7 -> 26.695405 | T7: =($J7/$L7)/AC7 -> 36.315371 | U7: =($J7/$L7)/AD7 -> 36.597981 | V7: =($J7/$L7)/AE7 -> 32.321928 | W7: =($J7/$L7)/AF7 -> 20.069021 | X7: =($J7/$L7)/AG7 -> 17.353655 | Y7: =($J7/$L7)/AH7 -> 15.887975 | Z7: =($J7/$L7)/AI7 -> 14.89026 | AA7: =($J7/$L7)/AJ7 -> 14.455453 | AB7: 10.57 | AC7: 7.77 | AD7: 7.71 | AE7: 8.73 | AF7: 14.06 | AG7: 16.26 | AH7: 17.76 | AI7: 18.95 | AJ7: 19.52 | AK7: 20.98 | AL7: 1888 | AM7: Illinois | AN7: United States | AO7: =BD7/FV7-1 -> 0.10880126 | AP7: =BD7/BX7-1 -> 0.16365056 | AQ7: =BD7/CA7-1 -> 0.18876689 | AR7: =BD7/KT7-1 -> 0.36488525 | BD7: 253.35 | BE7: 243.14 | BF7: 234.89 | BG7: 234.76 | BH7: 230.01 | BJ7: 216.49 | BK7: 221.23 | BL7: 222.47 | BM7: 221.59 | BN7: 227.73 | BO7: 224.77 | BP7: 224.95 | BQ7: 225.42 | BR7: 223.07 | BS7: 227.23 | BT7: 224.94 | BU7: 217.13 | BV7: 215.4 | BW7: 212.93 | BX7: 217.72 | BY7: 218.63 | BZ7: 215.4 | CA7: 213.12 | CB7: 215.7 | CC7: 214.5 | CD7: 212.3 | CE7: 213.76 | CF7: 209.41 | CG7: 210.39 | CH7: 210.77 | CI7: 208.5 | CJ7: 207.86 | CK7: 202.78 | CL7: 201.55 | CM7: 202.71 | CN7: 205.03 | CO7: 206.11 | CP7: 208.16 | CQ7: 206.6 | CR7: 211.32 | CS7: 203.89 | CT7: 197.69 | CU7: 197.38 | CV7: 198.71 | CW7: 200.95 | CX7: 200.5 | CY7: 205.12 | CZ7: 203.71 | DA7: 208.38 | DB7: 208.99 | DC7: 208.42 | DD7: 210.26 | DE7: 206.47 | DF7: 207.94 | DG7: 212.4 | DH7: 211.59 | DI7: 206.37 | DJ7: 206.69 | DK7: 208.84 | DL7: 214.98 | DM7: 217.49 | DN7: 213.12 | DO7: 209.4 | DP7: 211.12 | DQ7: 207.18 | DR7: 205.2 | DS7: 204.93 | DT7: 205.07 | DU7: 206.23 | DV7: 208.34 | DW7: 219.76 | DX7: 221.45 | DY7: 219.68 | DZ7: 225.37 | EA7: 227.68 | EB7: 227.01 | EC7: 227.45 | ED7: 230.11 | EE7: 232.35 | EF7: 236.19 | EG7: 233.86 | EH7: 234.26 | EI7: 232.08 | EJ7: 224.69 | EK7: 226.92 | EL7: 228.44 | EM7: 229.48 | EN7: 224.81 | EO7: 224.35 | EP7: 228.72 | EQ7: 232.86 | ER7: 231.5 | ES7: 227.5 | ET7: 220.89 | EU7: 222.44 | EV7: 223.26 | EW7: 223.43 | EX7: 219.02 | EY7: 217.11 | EZ7: 225.66 | FA7: 225.64 | FB7: 223.01 | FC7: 220.43 | FD7: 218.67 | FE7: 223.93 | FF7: 220.77 | FG7: 219.26 | FH7: 218.11 | FI7: 216.15 | FJ7: 214.04 | FK7: 214.35 | FL7: 216.75 | FM7: 221.89 | FN7: 220.75 | FO7: 220.04 | FP7: 220.08 | FQ7: 224.13 | FR7: 233.42 | FS7: 223.93 | FT7: 220.18 | FU7: 229.31 | FV7: 228.49 | FW7: 229.74 | FX7: 230.84 | FY7: 229.98 | FZ7: 229.89 | GA7: 228.79 | GB7: 227.91 | GC7: 226.82 | GD7: 222.82 | GE7: 224.31 | GF7: 223.67 | GG7: 227.45 | GH7: 223.32 | GI7: 223.98 | GJ7: 225.18 | GK7: 222.99 | GL7: 223.12 | GM7: 226.08 | GN7: 228.71 | GO7: 230.24 | GP7: 224.37 | GQ7: 225.11 | GR7: 227.7 | GS7: 227.66 | GT7: 231.8 | GU7: 229.51 | GV7: 236.28 | GW7: 229.45 | GX7: 232.91 | GY7: 233.87 | GZ7: 234 | HA7: 232.36 | HB7: 232.29 | HC7: 233.23 | HD7: 225.17 | HE7: 218.71 | HF7: 219.16 | HG7: 219.04 | HH7: 216.77 | HI7: 215.89 | HJ7: 211.96 | HK7: 218.04 | HL7: 228.2 | HM7: 225.14 | HN7: 227.54 | HO7: 228.03 | HP7: 227.99 | HQ7: 228.25 | HR7: 228.68 | HS7: 231.39 | HT7: 232.06 | HU7: 229.57 | HV7: 226.87 | HW7: 226.22 | HX7: 229.13 | HY7: 230.3 | HZ7: 230.5 | IA7: 230.69 | IB7: 231.24 | IC7: 232.83 | ID7: 230.19 | IE7: 233.91 | IF7: 236.56 | IG7: 244.38 | IH7: 231.54 | II7: 223.16 | IJ7: 220.61 | IK7: 218.54 | IL7: 219.99 | IM7: 222.61 | IN7: 222.59 | IO7: 222.47 | IP7: 221.99 | IQ7: 220.81 | IR7: 216.26 | IS7: 217.61 | IT7: 218.34 | IU7: 220.22 | IV7: 211.64 | IW7: 210.42 | IX7: 209.79 | IY7: 212.56 | IZ7: 213 | JA7: 211.86 | JB7: 211.92 | JC7: 210.4 | JD7: 207.92 | JE7: 208.06 | JF7: 208.36 | JG7: 207.55 | JH7: 210.6 | JI7: 209.5 | JJ7: 209.15 | JK7: 206.19 | JL7: 206.57 | JM7: 206.69 | JN7: 204.68 | JO7: 201.47 | JP7: 198.64 | JQ7: 198.64 | JR7: 198.05 | JS7: 198.86 | JT7: 196.3 | JU7: 198.55 | JV7: 197.19 | JW7: 195.22 | JX7: 189.02 | JY7: 189.31 | JZ7: 191.22 | KA7: 188.52 | KB7: 190.28 | KC7: 190.83 | KD7: 190.55 | KE7: 187.11 | KF7: 184.85 | KG7: 189.26 | KH7: 191.4 | KI7: 190.58 | KJ7: 186.39 | KK7: 191.52 | KL7: 192.45 | KM7: 195 | KN7: 190.62 | KO7: 189.77 | KP7: 187.63 | KQ7: 189.28 | KR7: 190.75 | KS7: 189.99 | KT7: 185.62
A8: x | D8: 4 | E8: Merck | F8: MRK | G8: 128.58 | H8: =+G8*L8 -> 317570.02 | I8: =+[4]Main!$J$5-[4]Main!$J$6 -> -45543 | J8: =H8-I8 -> 363113.02 | K8: Q226 | L8: =+[4]Main!$J$3 -> 2469.8244 | M8: 46243 | N8: =[4]Model!$EQ$115 -> 82.709451 | O8: =N8/G8-1 -> -0.35674715 | P8: =[4]Model!$EQ$111 -> 0.01 | Q8: =[4]Model!$EQ$112 -> -0.01 | R8: =[4]Model!$EQ$113 -> 0.07 | S8: =($J8/$L8)/AB8 -> 21.557151 | T8: =($J8/$L8)/AC8 -> 21.748487 | U8: =($J8/$L8)/AD8 -> 21.002825 | V8: =($J8/$L8)/AE8 -> 18.286041 | W8: =($J8/$L8)/AF8 -> 15.125491 | X8: =($J8/$L8)/AG8 -> 15.410878 | Y8: =($J8/$L8)/AH8 -> 14.068878 | Z8: =($J8/$L8)/AI8 -> 14.556413 | AA8: =($J8/$L8)/AJ8 -> 14.643404 | AB8: 6.82 | AC8: 6.76 | AD8: 7 | AE8: 8.04 | AF8: 9.72 | AG8: 9.54 | AH8: 10.45 | AI8: 10.1 | AJ8: 10.04 | AK8: 9.79 | AL8: 1919 | AM8: New Jersey | AN8: United States | AO8: =BD8/FV8-1 -> 0.22230667 | AP8: =BD8/BX8-1 -> 0.083726415 | AQ8: =BD8/CA8-1 -> 0.07467424 | AR8: =BD8/KT8-1 -> 0.62531582 | BD8: 128.66 | BE8: 125.45 | BF8: 120.6 | BG8: 119.6 | BH8: 115.48 | BJ8: 113.87 | BK8: 115.44 | BL8: 115.17 | BM8: 114.9 | BN8: 119.05 | BO8: 120.76 | BP8: 119.09 | BQ8: 119.6 | BR8: 119.52 | BS8: 120.79 | BT8: 120.26 | BU8: 114.7 | BV8: 115.65 | BW8: 115.17 | BX8: 118.72 | BY8: 119.89 | BZ8: 120.24 | CA8: 119.72 | CB8: 122.41 | CC8: 115.88 | CD8: 113 | CE8: 114.24 | CF8: 112.56 | CG8: 111.38 | CH8: 113.41 | CI8: 113.45 | CJ8: 112.37 | CK8: 111.28 | CL8: 111.38 | CM8: 112.3 | CN8: 113.56 | CO8: 113.15 | CP8: 113.11 | CQ8: 112.16 | CR8: 109.18 | CS8: 110.95 | CT8: 110.03 | CU8: 110.23 | CV8: 111.9 | CW8: 114.62 | CX8: 112.89 | CY8: 112.56 | CZ8: 117.1 | DA8: 119.07 | DB8: 115.46 | DC8: 117.9 | DD8: 119.96 | DE8: 120.15 | DF8: 121.42 | DG8: 122.68 | DH8: 123.18 | DI8: 119.28 | DJ8: 120.85 | DK8: 120.87 | DL8: 120.84 | DM8: 120.29 | DN8: 118.1 | DO8: 119.63 | DP8: 118.93 | DQ8: 119.37 | DR8: 116.37 | DS8: 115.68 | DT8: 114.18 | DU8: 114.2 | DV8: 114.5 | DW8: 115.87 | DX8: 115.43 | DY8: 115.61 | DZ8: 115.91 | EA8: 116.21 | EB8: 117.09 | EC8: 117.11 | ED8: 115.79 | EE8: 116.07 | EF8: 120.28 | EG8: 119.83 | EH8: 121.41 | EI8: 123.82 | EJ8: 119.3 | EK8: 122.46 | EL8: 123.93 | EM8: 123.82 | EN8: 122.26 | EO8: 121.86 | EP8: 121.66 | EQ8: 121.57 | ER8: 121.41 | ES8: 119.24 | ET8: 119.31 | EU8: 117.15 | EV8: 117.65 | EW8: 121.93 | EX8: 119.75 | EY8: 118.33 | EZ8: 115.84 | FA8: 113.37 | FB8: 110.27 | FC8: 108.34 | FD8: 106.9 | FE8: 107.92 | FF8: 107.4 | FG8: 108.18 | FH8: 109.18 | FI8: 111.11 | FJ8: 109.45 | FK8: 108.83 | FL8: 110.97 | FM8: 111.01 | FN8: 108.26 | FO8: 109.19 | FP8: 110.53 | FQ8: 110.99 | FR8: 108.6 | FS8: 108.87 | FT8: 107.44 | FU8: 106.45 | FV8: 105.26 | FW8: 106.06 | FX8: 106.62 | FY8: 106.78 | FZ8: 106.45 | GA8: 105.04 | GB8: 104.72 | GC8: 101.09 | GD8: 100.69 | GE8: 99.18 | GF8: 98.27 | GG8: 100.26 | GH8: 100.3 | GI8: 99.01 | GJ8: 97.62 | GK8: 96.89 | GL8: 98.93 | GM8: 99.72 | GN8: 100.89 | GO8: 102.27 | GP8: 101.03 | GQ8: 101.83 | GR8: 104.83 | GS8: 104.63 | GT8: 105.66 | GU8: 100.4 | GV8: 97.76 | GW8: 94.97 | GX8: 95.05 | GY8: 96.43 | GZ8: 92.86 | HA8: 92.92 | HB8: 92.93 | HC8: 91.45 | HD8: 90.95 | HE8: 86.75 | HF8: 86.28 | HG8: 85.78 | HH8: 84.39 | HI8: 83.86 | HJ8: 82.49 | HK8: 85.98 | HL8: 86.28 | HM8: 86.58 | HN8: 87.03 | HO8: 88 | HP8: 87.49 | HQ8: 87.18 | HR8: 87.61 | HS8: 87.62 | HT8: 86.32 | HU8: 84.79 | HV8: 83.92 | HW8: 84.11 | HX8: 84.7 | HY8: 85.7 | HZ8: 85.99 | IA8: 87.5 | IB8: 86.4 | IC8: 87.61 | ID8: 88.8 | IE8: 89.19 | IF8: 89.51 | IG8: 90.13 | IH8: 83.93 | II8: 78.58 | IJ8: 78.56 | IK8: 77.6 | IL8: 79.67 | IM8: 79.96 | IN8: 80.4 | IO8: 81.51 | IP8: 81.53 | IQ8: 81.14 | IR8: 81.09 | IS8: 81.02 | IT8: 82.81 | IU8: 85.15 | IV8: 84.03 | IW8: 84.61 | IX8: 84.09 | IY8: 84.71 | IZ8: 84.05 | JA8: 84.18 | JB8: 85.48 | JC8: 84.12 | JD8: 83.21 | JE8: 84.07 | JF8: 84.99 | JG8: 85.31 | JH8: 87.37 | JI8: 86.08 | JJ8: 84.66 | JK8: 84.93 | JL8: 84.22 | JM8: 84.21 | JN8: 82.76 | JO8: 82.71 | JP8: 80.3 | JQ8: 80.03 | JR8: 80.69 | JS8: 80.37 | JT8: 79.44 | JU8: 80.79 | JV8: 79.86 | JW8: 79.29 | JX8: 78.12 | JY8: 81.75 | JZ8: 82.63 | KA8: 84.06 | KB8: 84.71 | KC8: 84.11 | KD8: 83.98 | KE8: 81.61 | KF8: 79.31 | KG8: 79.96 | KH8: 81.52 | KI8: 82.43 | KJ8: 81.52 | KK8: 83.67 | KL8: 83.36 | KM8: 84.02 | KN8: 83.71 | KO8: 81.37 | KP8: 80.9 | KQ8: 80.93 | KR8: 82.39 | KS8: 81.81 | KT8: 79.16
A9: x | D9: 5 | E9: Novartis | F9: NVS | G9: 157.44 | H9: =+G9*L9 -> 301340.16 | I9: =+[5]Main!$K$6-[5]Main!$K$7 -> -39400 | J9: =H9-I9 -> 340740.16 | K9: Q126 | L9: =+[5]Main!$K$4 -> 1914 | M9: 46227 | S9: =($J9/$L9)/AB9 -> 43.848562 | T9: =($J9/$L9)/AC9 -> 33.275731 | U9: =($J9/$L9)/AD9 -> 26.650473 | V9: =($J9/$L9)/AE9 -> 23.18036 | W9: =($J9/$L9)/AF9 -> 20.1614 | X9: =($J9/$L9)/AG9 -> 18.147315 | Y9: =($J9/$L9)/AH9 -> 16.392741 | Z9: =($J9/$L9)/AI9 -> 15.202832 | AA9: =($J9/$L9)/AJ9 -> 14.438375 | AB9: 4.06 | AC9: 5.35 | AD9: 6.68 | AE9: 7.68 | AF9: 8.83 | AG9: 9.81 | AH9: 10.86 | AI9: 11.71 | AJ9: 12.33 | AK9: 11.89 | AM9: Basel | AN9: Switzerland
A10: x | D10: =+D9 -> 5 | E10: Novartis | F10: NOVN VX | G10: 126.6 | H10: =+G10*L10/CHF -> 296225.43 | I10: =+[5]Main!$K$6-[5]Main!$K$7 -> -39400 | J10: =H10-I10 -> 335625.43 | K10: Q126 | L10: =+[5]Main!$K$4 -> 1914 | M10: 46227 | N10: - | O10: - | P10: - | Q10: - | R10: - | S10: - | T10: - | U10: - | V10: - | W10: - | X10: - | Y10: - | Z10: - | AA10: - | AB10: - | AC10: - | AD10: - | AE10: - | AF10: - | AG10: - | AH10: - | AI10: - | AJ10: - | AK10: - | AM10: Basel | AN10: Switzerland
A11: x | D11: =+D10+1 -> 6 | E11: Roche | F11: ROP SW | G11: 353.6 | H11: =+L11*G11 -> 281465.6 | I11: =+[6]Main!$J$5-[6]Main!$J$6 -> -16160 | J11: =H11-I11 -> 297625.6 | K11: Q425 | L11: =+[6]Main!$J$3 -> 796 | M11: 46227 | S11: - | T11: - | U11: =($J11/$L11)/AD11 -> 16.435231 | V11: =($J11/$L11)/AE11 -> 19.545296 | W11: =($J11/$L11)/AF11 -> 18.310554 | X11: =($J11/$L11)/AG11 -> 17.127875 | Y11: =($J11/$L11)/AH11 -> 15.86345 | Z11: =($J11/$L11)/AI11 -> 14.896474 | AA11: =($J11/$L11)/AJ11 -> 14.061734 | AB11: 19.55 | AC11: 19.27 | AD11: 22.75 | AE11: 19.13 | AF11: 20.42 | AG11: 21.83 | AH11: 23.57 | AI11: 25.1 | AJ11: 26.59 | AK11: 28.32 | AL11: 1896 | AM11: Basel | AN11: Switzerland | AP11: =BD11/BW11-1 -> 0.058601134 | AQ11: =BD11/BZ11-1 -> 0.015412511 | BD11: 336 | BE11: 335.3 | BF11: 332 | BG11: 325.2 | BH11: 318.6 | BI11: 319.8 | BJ11: 319 | BK11: 327.8 | BL11: 324 | BM11: 326.1 | BN11: 330 | BO11: 325.3 | BP11: 323.9 | BQ11: 318.8 | BR11: 322.7 | BS11: 327.1 | BT11: 324.6 | BU11: 311.6 | BV11: 309.7 | BW11: 317.4 | BX11: 329.3 | BY11: 328.9 | BZ11: 330.9 | CA11: 331.2 | CB11: 334.5 | CC11: 330.4 | CD11: 328.1 | CE11: 329.5 | CF11: 321.7 | CG11: 322.8 | CI11: 320 | CJ11: 321.5 | CK11: 319.4 | CL11: 315.3 | CM11: 318.3 | CN11: 321.9 | CO11: 318.5 | CP11: 316.5 | CR11: 318.4 | CS11: 317.3 | CT11: 321.1 | CU11: 321.2 | CV11: 322 | CW11: 324.9 | CX11: 313.1 | CY11: 317.2 | CZ11: 320.9 | DA11: 320 | DB11: 313.5 | DC11: 317 | DD11: 318.1 | DE11: 317.2 | DF11: 315.6 | DG11: 316.7 | DH11: 314.1 | DI11: 311.3 | DK11: 318 | DL11: 318.3 | DM11: 314.7 | DN11: 314.1 | DO11: 312.5 | DP11: 312.8 | DQ11: 312 | DR11: 305.8 | DS11: 303.9 | DT11: 300.9 | DU11: 305.7 | DV11: 314.8 | DW11: 323.9
A12: x | D12: =+D11+1 -> 7 | E12: AstraZeneca | F12: AZN | G12: 169.64 | H12: =+G12*L12 -> 264808.04 | I12: =+[7]Main!$K$5-[7]Main!$K$6 -> -25944 | J12: =H12-I12 -> 290752.04 | K12: Q126 | L12: =+[7]Main!$K$3 -> 1561 | M12: 46227 | S12: =($J12/$L12)/AB12 -> 175.71709 | T12: =($J12/$L12)/AC12 -> 97.010477 | U12: =($J12/$L12)/AD12 -> 82.052914 | V12: =($J12/$L12)/AE12 -> 41.29936 | W12: =($J12/$L12)/AF12 -> 18.136331 | X12: =($J12/$L12)/AG12 -> 16.253064 | Y12: =($J12/$L12)/AH12 -> 14.643091 | Z12: =($J12/$L12)/AI12 -> 12.91679 | AA12: =($J12/$L12)/AJ12 -> 11.455112 | AB12: 1.06 | AC12: 1.92 | AD12: 2.27 | AE12: 4.51 | AF12: 10.27 | AG12: 11.46 | AH12: 12.72 | AI12: 14.42 | AJ12: 16.26 | AK12: 17.23 | AM12: London | AN12: United Kingdom | AO12: =BD12/FV12-1 -> 0.073561254 | AP12: =BD12/BX12-1 -> 0.014757365 | AQ12: =BD12/CA12-1 -> 0.0065174422 | AR12: =BD12/KS12-1 -> 0.3485792 | BD12: 188.41 | BE12: 185.68 | BF12: 183.02 | BG12: 181.02 | BH12: 176.43 | BJ12: 174.93 | BK12: 177.89 | BL12: 178.71 | BM12: 177.27 | BN12: 178.75 | BO12: 182.28 | BP12: 178.96 | BQ12: 183.43 | BR12: 181.55 | BS12: 185.95 | BT12: 181.8 | BU12: 176.28 | BV12: 177.45 | BW12: 179.71 | BX12: 185.67 | BY12: 185.33 | BZ12: 185.65 | CA12: 187.19 | CB12: 187.03 | CC12: 189.75 | CD12: 187.46 | CE12: 184.64 | CF12: 183.92 | CG12: 181.58 | CH12: 184.96 | CI12: 187.72 | CJ12: 184.54 | CK12: 181.86 | CL12: 182.85 | CM12: 182.52 | CN12: 184.92 | CO12: 181.24 | CP12: 183.46 | CQ12: 184.74 | CR12: 187.37 | CS12: 185.2 | CT12: 186.68 | CU12: 187.51 | CV12: 189.75 | CW12: 192.3 | CX12: 194.81 | CY12: 195.78 | CZ12: 200.69 | DA12: 204.8 | DB12: 200.47 | DC12: 201.21 | DD12: 204.38 | DE12: 202.24 | DF12: 204.03 | DG12: 204.99 | DH12: 204.27 | DI12: 200.81 | DJ12: 202.83 | DK12: 203.49 | DL12: 200.73 | DM12: 197.22 | DN12: 193.88 | DO12: 188.42 | DP12: 183.4 | DQ12: 187.14 | DR12: 185.78 | DS12: 184.07 | DT12: 183.6 | DU12: 188.93 | DV12: 188.42 | DW12: 191.29 | DX12: 192.01 | DY12: 189.9 | DZ12: 192.5 | EA12: 193.31 | EB12: 194.99 | EC12: 194.95 | ED12: 194.22 | EE12: 197.52 | EF12: 201.53 | EG12: 201.76 | EH12: 203.73 | EI12: 208.45 | EJ12: 203.98 | EK12: 205.79 | EL12: 206.61 | EM12: 204.94 | EN12: 204.2 | EO12: 208.62 | EP12: 208.67 | EQ12: 209.48 | ER12: 205.55 | ES12: 204.52 | ET12: 204.76 | EU12: 193.4 | EV12: 188.01 | EW12: 193.03 | EX12: 187.16 | EY12: 187.45 | EZ12: 184.32 | FA12: 188.41 | FB12: 187.1 | FC12: 183.17 | FD12: 187.8 | FE12: 188.065 | FF12: 179.05 | FG12: 177.5 | FH12: 179.5 | FI12: 175 | FJ12: 183.2 | FK12: 191.125 | FL12: 188.835 | FM12: 190.23 | FN12: 188.66 | FO12: 185.4799 | FP12: 190.985 | FQ12: 188.5 | FR12: 190.775 | FS12: 190.49 | FT12: 179.057 | FU12: 182.675 | FV12: 175.5 | FW12: 180.85 | FX12: 187.06 | FY12: 181.275 | FZ12: 186.4 | GA12: 183 | GB12: 180.75 | GC12: 181.23 | GD12: 180.5399 | GE12: 184.75 | GG12: 183.86 | GJ12: 181.92 | GK12: 179.0999 | GL12: 180.94 | GM12: 179.4875 | GO12: 183.275 | GP12: 179.0999 | GQ12: 180.35 | GR12: 183.74 | GS12: 188.5 | GT12: 187.72 | GU12: 182.7 | GV12: 182.58 | GW12: 177.85 | GX12: 179.82 | GY12: 175.2049 | GZ12: 175.245 | HA12: 174.8249 | HB12: 177.5 | HC12: 175.66 | HD12: 175.2 | HE12: 174.9 | HF12: 166.17 | HG12: 169 | HI12: 165.26 | HJ12: 161.9 | HM12: 163.675 | HN12: 165.58 | HO12: 163.99 | HP12: 163.75 | HQ12: 168.24 | HS12: 168.28 | HT12: 166.9799 | HU12: 170.88 | HV12: 169.12 | HW12: 168.065 | HX12: 169.1 | HZ12: 169.3353 | IA12: 169.85 | IB12: 172.1 | IC12: 170 | ID12: 172.3 | IE12: 170.51 | IF12: 164.675 | IG12: 162.555 | IH12: 149.5 | II12: 146.0999 | IJ12: 146.16 | IK12: 149.75 | IL12: 149.0399 | IM12: 150.74 | IN12: 156.82 | IO12: 154.38 | IP12: 153.385 | IQ12: 156.025 | IR12: 153.0028 | IS12: 154.58 | IT12: 159.56 | IU12: 162 | IV12: 160.1399 | IW12: 160.5399 | IY12: 164.5 | IZ12: 162 | JA12: 162.2599 | JB12: 160.66 | JC12: 161.13 | JD12: 158.1999 | JE12: 160.65 | JF12: 160.3 | JG12: 162.98 | JH12: 157.09 | JJ12: 157.8 | JL12: 160.46 | JM12: 155.5 | JN12: 155.75 | JO12: 154.3 | JP12: 148.28 | JQ12: 146.12 | JR12: 141.772 | JS12: 147.235 | JT12: 148.68 | JU12: 150.29 | JV12: 150.32 | JW12: 147.5 | JX12: 147.39 | JY12: 155.67 | JZ12: 150.48 | KA12: 144.1 | KC12: 146.92 | KD12: 147.3 | KE12: 141.9 | KF12: 139.7 | KI12: 142.02 | KJ12: 140.4 | KK12: 143.15 | KL12: 140.2599 | KN12: 141.4 | KO12: 140.15 | KP12: 142.63 | KQ12: 140.685 | KR12: 143.88 | KS12: 139.71
A13: x | D13: =+D12 -> 7 | E13: AstraZeneca | F13: AZN LN | G13: 12632 | H13: =+G13*L13/100*GBP -> 262769.42 | I13: =+[7]Main!$K$5-[7]Main!$K$6 -> -25944 | J13: =H13-I13 -> 288713.42 | K13: Q126 | L13: =+[7]Main!$K$3 -> 1561 | M13: =+M12 -> 46227 | N13: - | O13: - | P13: - | Q13: - | R13: - | S13: - | T13: - | U13: - | V13: - | W13: - | X13: - | Y13: - | Z13: - | AA13: - | AB13: - | AC13: - | AD13: - | AE13: - | AF13: - | AG13: - | AH13: - | AI13: - | AJ13: - | AK13: - | AM13: London | AN13: United Kingdom
A14: x | D14: =+D13+1 -> 8 | E14: Amgen | F14: AMGN | G14: 394 | H14: =+G14*L14 -> 214336 | I14: =[8]Main!$J$5-[8]Main!$J$6 -> -45300 | J14: =H14-I14 -> 259636 | K14: Q126 | L14: =[8]Main!$J$3 -> 544 | M14: 46204 | N14: =+[8]Model!$EU$60 -> 384.37785 | O14: =N14/G14-1 -> -0.024421702 | P14: =+[8]Model!$EU$56 -> 0.01 | Q14: =+[8]Model!$EU$57 -> -0.02 | R14: =+[8]Model!$EU$58 -> 0.08 | S14: =($J14/$L14)/AB14 -> 35.804356 | T14: =($J14/$L14)/AC14 -> 37.729017 | U14: =($J14/$L14)/AD14 -> 55.112247 | V14: =($J14/$L14)/AE14 -> 34.262172 | W14: =($J14/$L14)/AF14 -> 20.85068 | X14: =($J14/$L14)/AG14 -> 19.820268 | Y14: =($J14/$L14)/AH14 -> 18.879433 | Z14: =($J14/$L14)/AI14 -> 17.768878 | AA14: =($J14/$L14)/AJ14 -> 16.746388 | AB14: 13.33 | AC14: 12.65 | AD14: 8.66 | AE14: 13.93 | AF14: 22.89 | AG14: 24.08 | AH14: 25.28 | AI14: 26.86 | AJ14: 28.5 | AK14: 29.64 | AL14: 1980 | AM14: California | AN14: United States | AO14: =BD14/FV14-1 -> 0.09477254 | AP14: =BD14/BX14-1 -> 0.063956768 | AQ14: =BD14/CA14-1 -> 0.066648806 | AR14: =BD14/KT14-1 -> 0.28337094 | BD14: 358.33 | BE14: 352.82 | BF14: 351.43 | BG14: 347.01 | BH14: 344.72 | BJ14: 337.6 | BK14: 341.66 | BL14: 347.84 | BM14: 350.53 | BN14: 355.2 | BO14: 354.06 | BP14: 337.73 | BQ14: 344.565 | BR14: 345.73 | BS14: 349.58 | BT14: 345.6 | BU14: 338.22 | BV14: 328.26 | BW14: 329.13 | BX14: 336.79 | BY14: 336.48 | BZ14: 336.06 | CA14: 335.94 | CB14: 339.3 | CC14: 337.42 | CD14: 331.57 | CE14: 330.75 | CF14: 324.39 | CG14: 326.31 | CH14: 336.23 | CI14: 336.45 | CJ14: 336.29 | CK14: 329.59 | CL14: 331.7 | CM14: 329.09 | CN14: 331.11 | CO14: 329.59 | CP14: 323.85 | CQ14: 329.82 | CR14: 346.25 | CS14: 338.02 | CT14: 339.57 | CU14: 340.18 | CV14: 344.55 | CW14: 348.62 | CX14: 345.92 | CY14: 344.86 | CZ14: 350.16 | DA14: 355.3 | DB14: 349.39 | DC14: 348.22 | DD14: 350.95 | DE14: 349.82 | DF14: 351.02 | DG14: 355.6 | DH14: 349.81 | DI14: 340 | DJ14: 342.57 | DK14: 347.94 | DL14: 353.28 | DM14: 351.85 | DN14: 349 | DO14: 348.77 | DP14: 353.16 | DQ14: 353.93 | DR14: 348.43 | DS14: 349.77 | DT14: 347.8 | DU14: 349.92 | DV14: 351.48 | DW14: 361.13 | DX14: 366.25 | DY14: 366.21 | DZ14: 367.79 | EA14: 377.64 | EB14: 375.43 | EC14: 376.97 | ED14: 369.53 | EE14: 367.6 | EF14: 379.27 | EG14: 377 | EH14: 385.7 | EI14: 388.16 | EJ14: 379.33 | EK14: 384.33 | EL14: 382.87 | EM14: 379.42 | EN14: 374.75 | EO14: 375.5 | EP14: 379.73 | EQ14: 373.36 | ER14: 369.19 | ES14: 366.2 | ET14: 366.58 | EU14: 364.65 | EV14: 375.82 | EW14: 384.32 | EX14: 367.8 | EY14: 366.2 | EZ14: 338.59 | FA14: 344.68 | FB14: 341.88 | FC14: 342.94 | FD14: 342.22 | FE14: 351.32 | FF14: 349.69 | FG14: 344.75 | FH14: 347.07 | FI14: 343.6 | FJ14: 331 | FK14: 330.41 | FL14: 330.03 | FM14: 328.97 | FN14: 324.3 | FO14: 325.54 | FP14: 326.1 | FQ14: 330.11 | FR14: 341.64 | FS14: 330.17 | FT14: 320.72 | FU14: 327.64 | FV14: 327.31 | FW14: 328.69 | FX14: 329.63 | FY14: 332.93 | FZ14: 333.96 | GA14: 331.49 | GB14: 331.39 | GC14: 327.38 | GD14: 324.42 | GE14: 326.01 | GF14: 326.74 | GG14: 325.31 | GH14: 317.74 | GI14: 317.38 | GJ14: 315.38 | GK14: 313.85 | GL14: 321.23 | GM14: 329.89 | GN14: 340.16 | GO14: 345.42 | GP14: 338.36 | GQ14: 337.49 | GR14: 345.46 | GS14: 344.57 | GT14: 341.11 | GU14: 334.3 | GV14: 337.54 | GW14: 336.07 | GX14: 342.4 | GY14: 343.99 | GZ14: 341.71 | HA14: 336.74 | HB14: 336 | HC14: 336.28 | HD14: 338.45 | HE14: 323.66 | HF14: 320.2 | HG14: 315.59 | HH14: 319.86 | HI14: 296.7 | HJ14: 296.3 | HK14: 298.43 | HL14: 292 | HM14: 291.77 | HN14: 292.09 | HO14: 291.16 | HP14: 291.76 | HQ14: 292.89 | HR14: 295.98 | HS14: 301.14 | HT14: 303.33 | HU14: 298.81 | HV14: 295.81 | HW14: 297.32 | HX14: 293.85 | HY14: 292.405 | HZ14: 290.13 | IA14: 295.43 | IB14: 294.62 | IC14: 295.54 | ID14: 294.12 | IE14: 297.89 | IF14: 297.4 | IG14: 298.5 | IH14: 282.2 | II14: 273.97 | IJ14: 272.98 | IK14: 271.18 | IL14: 279.22 | IM14: 286.81 | IN14: 286 | IO14: 285.41 | IP14: 275.83 | IQ14: 274.71 | IR14: 273.085 | IS14: 274.4 | IT14: 276.39 | IU14: 282.73 | IV14: 278.51 | IW14: 279.97 | IX14: 280.19 | IY14: 283.64 | IZ14: 280.1 | JA14: 283.85 | JB14: 286.92 | JC14: 287.71 | JD14: 285.61 | JE14: 287.97 | JF14: 289.58 | JG14: 288.47 | JH14: 293.72 | JI14: 295.76 | JJ14: 296.45 | JK14: 295.55 | JL14: 292.62 | JM14: 296.47 | JN14: 290.29 | JO14: 289.33 | JP14: 284.98 | JQ14: 285.09 | JR14: 288.23 | JS14: 284.7 | JT14: 284.67 | JU14: 300.08 | JV14: 301.94 | JW14: 296.88 | JX14: 295.1 | JY14: 301.37 | JZ14: 303.56 | KA14: 301.29 | KB14: 306.58 | KC14: 308.55 | KD14: 309.22 | KE14: 305.69 | KF14: 295.87 | KG14: 294.76 | KH14: 298.25 | KI14: 299.02 | KJ14: 292.51 | KK14: 297.03 | KL14: 295.27 | KM14: 300.37 | KN14: 296.52 | KO14: 297 | KP14: 292.95 | KQ14: 298.24 | KR14: 296.85 | KS14: 290.52 | KT14: 279.21
A15: x | D15: =+D14+1 -> 9 | E15: Novo Nordisk | F15: NVO | G15: 46.92 | H15: =+L15*G15 -> 208733 | I15: =([9]Main!$J$5-[9]Main!$J$6)/DKK -> -17878.526 | J15: =H15-I15 -> 226611.53 | K15: Q126 | L15: =+[9]Main!$J$3 -> 4448.7 | M15: 46227 | N15: - | O15: - | P15: - | Q15: - | R15: - | S15: =($J15/$L15)/AB15 -> 29.107897 | T15: =($J15/$L15)/AC15 -> 18.456094 | U15: =($J15/$L15)/AD15 -> 14.348963 | V15: =($J15/$L15)/AE15 -> 14.110477 | W15: =($J15/$L15)/AF15 -> 14.93807 | X15: =($J15/$L15)/AG15 -> 15.482924 | Y15: =($J15/$L15)/AH15 -> 14.512484 | Z15: =($J15/$L15)/AI15 -> 13.128562 | AA15: =($J15/$L15)/AJ15 -> 12.244909 | AB15: 1.75 | AC15: 2.76 | AD15: 3.55 | AE15: 3.61 | AF15: 3.41 | AG15: 3.29 | AH15: 3.51 | AI15: 3.88 | AJ15: 4.16 | AK15: 4.41 | AL15: 1923 | AM15: Copenhagen | AN15: Denmark | AO15: =BD15/FV15-1 -> -0.055227987 | AP15: =BD15/BX15-1 -> 0.054629223 | AQ15: =BD15/CA15-1 -> 0.08780267 | AR15: =BD15/KT15-1 -> -0.30353521 | BD15: 48.07 | BE15: 47.64 | BF15: 47.41 | BG15: 47.42 | BH15: 45.88 | BJ15: 43.19 | BK15: 43.52 | BL15: 43.55 | BM15: 43.92 | BN15: 43.88 | BO15: 43.96 | BP15: 42.81 | BQ15: 42.19 | BR15: 41.02 | BS15: 42.96 | BT15: 43.75 | BU15: 42 | BV15: 42.92 | BW15: 44.07 | BX15: 45.58 | BY15: 45.51 | BZ15: 44.55 | CA15: 44.19 | CB15: 44.96 | CC15: 44.39 | CD15: 45.07 | CE15: 44.28 | CF15: 44.28 | CG15: 44.74 | CH15: 45.8 | CI15: 47.08 | CJ15: 47 | CK15: 46.4 | CL15: 46.07 | CM15: 45.8 | CN15: 45.76 | CO15: 44.87 | CP15: 44.39 | CQ15: 43.88 | CR15: 42.22 | CS15: 40.29 | CT15: 41.17 | CU15: 41.2 | CV15: 41.17 | CW15: 38.52 | CX15: 39.15 | CY15: 39.42 | CZ15: 40.46 | DA15: 40.52 | DB15: 40.93 | DC15: 40.81 | DD15: 39.32 | DE15: 37.98 | DF15: 37.52 | DG15: 37.44 | DH15: 37.61 | DI15: 36.91 | DJ15: 36.67 | DK15: 36.98 | DL15: 36.48 | DM15: 36.75 | DN15: 35.29 | DO15: 36.04 | DP15: 36.4 | DQ15: 36.33 | DR15: 36.89 | DS15: 36.82 | DT15: 36.53 | DU15: 37.08 | DV15: 37.45 | DW15: 38.43 | DX15: 38.58 | DY15: 37.96 | DZ15: 38.02 | EA15: 38.83 | EB15: 38.72 | EC15: 39.78 | ED15: 38.58 | EE15: 39.07 | EF15: 38.5 | EG15: 36.66 | EH15: 37.76 | EI15: 37.45 | EJ15: 37.62 | EK15: 38.16 | EL15: 38.59 | EM15: 39.63 | EN15: 47.42 | EO15: 48.45 | EP15: 49.23 | EQ15: 49.37 | ER15: 49.57 | ES15: 48.93 | ET15: 48.74 | EU15: 49.12 | EV15: 49.37 | EW15: 47.64 | EX15: 43.34 | EY15: 47.19 | EZ15: 50.3 | FA15: 58.93 | FB15: 59.43 | FC15: 59.33 | FD15: 60.33 | FE15: 62.89 | FF15: 63.98 | FG15: 62.26 | FH15: 62.23 | FI15: 59.32 | FJ15: 60.68 | FK15: 62.33 | FL15: 57.12 | FM15: 58.91 | FN15: 59.64 | FO15: 59.86 | FP15: 58.81 | FQ15: 57.34 | FR15: 56.57 | FS15: 56.26 | FT15: 55.11 | FU15: 52.39 | FV15: 50.88 | FW15: 51.22 | FX15: 51.47 | FY15: 52.4 | FZ15: 52.56 | GA15: 51.61 | GB15: 48.1 | GC15: 48.09 | GD15: 47.61 | GE15: 47.77 | GF15: 48.96 | GG15: 50.37 | GH15: 50.18 | GI15: 50.29 | GJ15: 49.05 | GK15: 46.36 | GL15: 46.77 | GM15: 47.86 | GN15: 47.99 | GO15: 47.57 | GP15: 47.43 | GQ15: 48.43 | GR15: 49.35 | GS15: 48.71 | GT15: 47.06 | GU15: 44.97 | GV15: 47.63 | GW15: 47.6 | GX15: 49 | GY15: 47.55 | GZ15: 48.46 | HA15: 48.26 | HB15: 49.16 | HC15: 50.26 | HD15: 49.15 | HE15: 45.94 | HF15: 45.68 | HG15: 46.51 | HH15: 48.46 | HI15: 48.25 | HJ15: 49.11 | HK15: 49.46 | HL15: 50.04 | HM15: 51.37 | HN15: 52.05 | HO15: 52.89 | HP15: 52.96 | HQ15: 53.23 | HR15: 53.38 | HS15: 54.78 | HT15: 55.74 | HU15: 54.37 | HV15: 56.09 | HW15: 56.72 | HX15: 56.66 | HY15: 57.5 | HZ15: 56.93 | IA15: 58.68 | IB15: 59.61 | IC15: 59.02 | ID15: 59.65 | IE15: 59.63 | IF15: 58.74 | IG15: 59.17 | IH15: 55.49 | II15: 55.5 | IJ15: 55.61 | IK15: 56.04 | IL15: 58.74 | IM15: 59.54 | IN15: 60.71 | IO15: 61.4 | IP15: 61.85 | IQ15: 58.2 | IR15: 57.2 | IS15: 55.62 | IT15: 54.87 | IU15: 54.3 | IV15: 54.37 | IW15: 54.3 | IX15: 54.28 | IY15: 55.23 | IZ15: 56.14 | JA15: 56.74 | JB15: 56.38 | JC15: 56.46 | JD15: 56.11 | JE15: 56.44 | JF15: 55.34 | JG15: 56.34 | JH15: 56.98 | JI15: 55.45 | JJ15: 54.3 | JK15: 54.78 | JL15: 53.75 | JM15: 52.41 | JN15: 50.95 | JO15: 50.9 | JP15: 49.78 | JQ15: 49.87 | JR15: 51.08 | JS15: 48.76 | JT15: 45.38 | JU15: 47.22 | JV15: 48.81 | JW15: 48.19 | JX15: 47.07 | JY15: 50.03 | JZ15: 53.94 | KA15: 69 | KB15: 71.7 | KC15: 70.73 | KD15: 70.03 | KE15: 66.78 | KF15: 64.92 | KG15: 64.31 | KH15: 65.29 | KI15: 67.04 | KJ15: 67.22 | KK15: 68.94 | KL15: 68.93 | KM15: 71.01 | KN15: 69.69 | KO15: 69.64 | KP15: 69.32 | KQ15: 69.17 | KR15: 69.82 | KS15: 69.82 | KT15: 69.02
A16: x | D16: =+D15 -> 9 | E16: Novo Nordisk | F16: NOVOB | G16: 306.5 | H16: =+G16*L16/DKK -> 210300.68 | I16: =([9]Main!$J$5-[9]Main!$J$6)/DKK -> -17878.526 | J16: =H16-I16 -> 228179.21 | K16: Q126 | L16: =+[9]Main!$J$3 -> 4448.7 | M16: =+M15 -> 46227 | N16: =+[9]Model!$DQ$64 -> 325.56685 | O16: =N16/G16-1 -> 0.062208323 | P16: =[9]Model!$DQ$60*-1 -> 0.01 | Q16: =+[9]Model!$DQ$61 -> -0.01 | R16: =+[9]Model!$DQ$62 -> 0.08 | S16: - | T16: - | U16: - | V16: - | W16: - | X16: - | Y16: - | Z16: - | AA16: - | AB16: - | AC16: - | AD16: - | AE16: - | AF16: - | AG16: - | AH16: - | AI16: - | AJ16: - | AK16: - | AL16: 1923 | AM16: Copenhagen | AN16: Denmark
A17: x | D17: =+D16+1 -> 10 | E17: Pfizer | F17: PFE | G17: 25.04 | H17: =+L17*G17 -> 142714.08 | I17: =+[10]Main!$K$5-[10]Main!$K$6 -> -49754 | J17: =H17-I17 -> 192468.08 | K17: Q126 | L17: =+[10]Main!$K$3 -> 5699.4442 | M17: 46227 | S17: =($J17/$L17)/AB17 -> 5.4467134 | T17: =($J17/$L17)/AC17 -> 27.680019 | U17: =($J17/$L17)/AD17 -> 14.682445 | V17: =($J17/$L17)/AE17 -> 9.6761098 | W17: =($J17/$L17)/AF17 -> 11.370243 | X17: =($J17/$L17)/AG17 -> 11.684991 | Y17: =($J17/$L17)/AH17 -> 13.671912 | Z17: =($J17/$L17)/AI17 -> 14.129549 | AA17: =($J17/$L17)/AJ17 -> 13.671912 | AB17: 6.2 | AC17: 1.22 | AD17: 2.3 | AE17: 3.49 | AF17: 2.97 | AG17: 2.89 | AH17: 2.47 | AI17: 2.39 | AJ17: 2.47 | AK17: 2.54 | AM17: New York | AN17: United States | AO17: =BD17/FV17-1 -> -0.024497992 | AP17: =BD17/BX17-1 -> -0.072192513 | AQ17: =BD17/CA17-1 -> -0.060348162 | AR17: =BD17/KT17-1 -> 0.0020627063 | BD17: 24.29 | BE17: 23.67 | BF17: 24.04 | BG17: 24.72 | BH17: 25.08 | BJ17: 25.21 | BK17: 25.92 | BL17: 26.04 | BM17: 26 | BN17: 26.21 | BO17: 26.17 | BP17: 25.6 | BQ17: 25.7 | BR17: 25.62 | BS17: 26.04 | BT17: 25.69 | BU17: 25.34 | BV17: 25.55 | BW17: 25.63 | BX17: 26.18 | BY17: 26.14 | BZ17: 26.21 | CA17: 25.85 | CB17: 25.9 | CC17: 25.95 | CD17: 25.79 | CE17: 25.66 | CF17: 25.33 | CG17: 25.33 | CH17: 25.75 | CI17: 25.96 | CJ17: 25.87 | CK17: 25.81 | CL17: 25.68 | CM17: 26.48 | CN17: 26.53 | CO17: 26.45 | CP17: 26.3 | CQ17: 26.33 | CR17: 26.7 | CS17: 26.26 | CT17: 26.48 | CU17: 26.79 | CV17: 27 | CW17: 26.67 | CX17: 26.8 | CY17: 27.31 | CZ17: 27.52 | DA17: 27.56 | DB17: 27.22 | DC17: 27.19 | DD17: 27.11 | DE17: 27.34 | DF17: 26.92 | DG17: 27.22 | DH17: 27.47 | DI17: 27.1 | DJ17: 27.83 | DK17: 28.32 | DL17: 28.55 | DM17: 28.08 | DN17: 27.77 | DO17: 27.04 | DP17: 27.57 | DQ17: 27.28 | DR17: 26.96 | DS17: 26.77 | DT17: 26.97 | DU17: 27.41 | DV17: 27.32 | DW17: 27.45 | DX17: 26.61 | DY17: 26.58 | DZ17: 26.86 | EA17: 27.3 | EB17: 27.16 | EC17: 26.81 | ED17: 27.05 | EE17: 26.61 | EF17: 26.62 | EG17: 26.58 | EH17: 27.26 | EI17: 27.65 | EJ17: 27.1 | EK17: 27.09 | EL17: 27.14 | EM17: 27.06 | EN17: 26.65 | EO17: 26.86 | EP17: 27.37 | EQ17: 27.37 | ER17: 27.58 | ES17: 27.47 | ET17: 27.73 | EU17: 27.61 | EV17: 27.05 | EW17: 27.22 | EX17: 26.49 | EY17: 26.78 | EZ17: 25.77 | FA17: 26.66 | FB17: 26.44 | FC17: 26.1 | FD17: 25.86 | FE17: 26.5 | FF17: 25.88 | FG17: 25.65 | FH17: 26.1 | FI17: 25.89 | FJ17: 25.52 | FK17: 25.65 | FL17: 25.89 | FM17: 25.58 | FN17: 25.15 | FO17: 25.27 | FP17: 25.48 | FQ17: 25.29 | FR17: 25.28 | FS17: 25.43 | FT17: 25.17 | FU17: 25.18 | FV17: 24.9 | FW17: 24.99 | FX17: 25 | FY17: 25.09 | FZ17: 25.03 | GA17: 24.88 | GB17: 25.21 | GC17: 25.19 | GD17: 25.04 | GE17: 25.04 | GF17: 25.53 | GG17: 26.43 | GH17: 25.85 | GI17: 25.8 | GJ17: 25.78 | GK17: 25.33 | GL17: 25.77 | GM17: 26.03 | GN17: 25.7 | GO17: 25.57 | GP17: 25.15 | GQ17: 25.27 | GR17: 25.74 | GS17: 25.71 | GT17: 25.72 | GU17: 25.22 | GV17: 25.04 | GW17: 24.4 | GX17: 24.88 | GY17: 25.45 | GZ17: 25.08 | HA17: 25.06 | HB17: 25.79 | HC17: 25.87 | HD17: 25.51 | HE17: 24.39 | HF17: 24.43 | HG17: 24.85 | HH17: 24.61 | HI17: 24.3 | HJ17: 24.66 | HK17: 24.65 | HL17: 24.29 | HM17: 24.29 | HN17: 24.5 | HO17: 24.77 | HP17: 24.76 | HQ17: 24.67 | HR17: 24.72 | HS17: 24.85 | HT17: 24.69 | HU17: 24.51 | HV17: 24.23 | HW17: 24.39 | HX17: 24.52 | HY17: 24.73 | HZ17: 24.78 | IA17: 25.24 | IB17: 25.68 | IC17: 26.27 | ID17: 26.43 | IE17: 27.37 | IF17: 27.08 | IG17: 27.21 | IH17: 25.48 | II17: 23.85 | IJ17: 23.76 | IK17: 23.6 | IL17: 24.09 | IM17: 24.13 | IN17: 24.04 | IO17: 24.03 | IP17: 24.15 | IQ17: 24.05 | IR17: 23.9 | IS17: 23.97 | IT17: 23.87 | IU17: 24.86 | IV17: 24.57 | IW17: 24.71 | IX17: 24.55 | IY17: 24.88 | IZ17: 24.54 | JA17: 24.79 | JB17: 24.98 | JC17: 24.76 | JD17: 24.6 | JE17: 25.07 | JF17: 24.92 | JG17: 25.14 | JH17: 25.88 | JI17: 25.74 | JJ17: 25.38 | JK17: 25.32 | JL17: 25.07 | JM17: 25.14 | JN17: 25.11 | JO17: 25.16 | JP17: 24.65 | JQ17: 24.58 | JR17: 24.58 | JS17: 24.23 | JT17: 23.93 | JU17: 24.75 | JV17: 23.53 | JW17: 23.49 | JX17: 23.29 | JY17: 23.81 | JZ17: 24.3 | KA17: 24.31 | KB17: 24.79 | KC17: 25.35 | KD17: 25.36 | KE17: 25.14 | KF17: 24.26 | KG17: 24.47 | KH17: 24.58 | KI17: 24.61 | KJ17: 24.61 | KK17: 25.35 | KL17: 25.65 | KM17: 25.78 | KN17: 25.56 | KO17: 25.62 | KP17: 25.24 | KQ17: 25.38 | KR17: 25.32 | KS17: 25.04 | KT17: 24.24
A18: x | D18: =+D17+1 -> 11 | E18: Gilead | F18: GILD | G18: 130.02 | H18: =+G18*L18 -> 163045.08 | I18: =+[11]Main!$J$5-[11]Main!$J$6 -> -13548 | J18: =H18-I18 -> 176593.08 | K18: Q126 | L18: =+[11]Main!$J$3 -> 1254 | M18: 45768 | S18: =($J18/$L18)/AB18 -> 21.434373 | T18: =($J18/$L18)/AC18 -> 23.431585 | U18: =($J18/$L18)/AD18 -> 23.123781 | V18: =($J18/$L18)/AE18 -> 19.185808 | W18: =($J18/$L18)/AF18 -> 16.528618 | X18: =($J18/$L18)/AG18 -> 14.267865 | Y18: =($J18/$L18)/AH18 -> 13.310381 | Z18: =($J18/$L18)/AI18 -> 11.974815 | AA18: =($J18/$L18)/AJ18 -> 11.079766 | AB18: 6.57 | AC18: 6.01 | AD18: 6.09 | AE18: 7.34 | AF18: 8.52 | AG18: 9.87 | AH18: 10.58 | AI18: 11.76 | AJ18: 12.71 | AK18: 13.56 | AM18: California | AN18: United States | AO18: =BD18/FV18-1 -> 0.041877139 | AP18: =BD18/BX18-1 -> -0.048724243 | AQ18: =BD18/CA18-1 -> -0.043744859 | AR18: =BD18/KT18-1 -> 0.15342293 | BD18: 127.88 | BE18: 123.84 | BF18: 125.16 | BG18: 125.05 | BH18: 124.87 | BJ18: 123.76 | BK18: 125.45 | BL18: 127.23 | BM18: 124.3 | BN18: 125.59 | BO18: 125.87 | BP18: 121.48 | BQ18: 125.5 | BR18: 128.1 | BS18: 129.16 | BT18: 129.18 | BU18: 128.99 | BV18: 127.57 | BW18: 131.1 | BX18: 134.43 | BY18: 136.22 | BZ18: 133.69 | CA18: 133.73 | CB18: 134.36 | CC18: 130.5 | CD18: 130.69 | CE18: 130.5 | CF18: 129.67 | CG18: 129.58 | CH18: 132.06 | CI18: 133.05 | CJ18: 134.94 | CK18: 133.52 | CL18: 131.33 | CM18: 134.06 | CN18: 136.3 | CO18: 133.48 | CP18: 132.69 | CQ18: 131.65 | CR18: 130.84 | CS18: 128.84 | CT18: 129.26 | CU18: 127.75 | CV18: 130.4 | CW18: 133.64 | CX18: 132.9 | CY18: 133.29 | CZ18: 135.87 | DA18: 137.64 | DB18: 138.55 | DC18: 139.77 | DD18: 140.45 | DE18: 139.03 | DF18: 138.99 | DG18: 142.09 | DH18: 141.54 | DI18: 138.8 | DJ18: 140.13 | DK18: 139.71 | DL18: 140.3 | DM18: 139.37 | DN18: 136.34 | DO18: 134.25 | DP18: 136.88 | DQ18: 138.26 | DR18: 138.11 | DS18: 137.34 | DT18: 137.21 | DU18: 141.11 | DV18: 141.29 | DW18: 144.4 | DX18: 145.21 | DY18: 144.99 | DZ18: 145.21 | EA18: 146 | EB18: 148.56 | EC18: 146.63 | ED18: 143.93 | EE18: 145.14 | EF18: 148.22 | EG18: 147.83 | EH18: 150.03 | EI18: 148.95 | EJ18: 143.77 | EK18: 147.12 | EL18: 147.64 | EM18: 149.83 | EN18: 151.4 | EO18: 151.12 | EP18: 152.74 | EQ18: 155.27 | ER18: 154.98 | ES18: 151.81 | ET18: 155.8 | EU18: 147.23 | EV18: 151.68 | EW18: 152.5 | EX18: 149.37 | EY18: 146.23 | EZ18: 143.28 | FA18: 142.89 | FB18: 141.95 | FC18: 139.55 | FD18: 139.72 | FE18: 140.97 | FF18: 137.78 | FG18: 135.93 | FH18: 131.14 | FI18: 129.11 | FJ18: 124.14 | FK18: 124.91 | FL18: 121.26 | FM18: 124.07 | FN18: 121.76 | FO18: 122.6 | FP18: 121.1 | FQ18: 120.67 | FR18: 124.35 | FS18: 121.36 | FT18: 118.3 | FU18: 121.6 | FV18: 122.74 | FW18: 123.18 | FX18: 124.91 | FY18: 124.7 | FZ18: 125.67 | GA18: 125.19 | GB18: 124.16 | GC18: 124.29 | GD18: 121.47 | GE18: 121.36 | GF18: 118.78 | GG18: 119.78 | GH18: 120.4 | GI18: 123.21 | GJ18: 121.34 | GK18: 119.36 | GL18: 121.19 | GM18: 121.22 | GN18: 122.62 | GO18: 125 | GP18: 123.91 | GQ18: 124.33 | GR18: 125.84 | GS18: 127.51 | GT18: 127.12 | GU18: 125.27 | GV18: 126.64 | GW18: 124.99 | GX18: 128.07 | GY18: 127.18 | GZ18: 124.09 | HA18: 125.02 | HB18: 125.2 | HC18: 123.4 | HD18: 122.56 | HE18: 118.15 | HF18: 118.84 | HG18: 123.4 | HH18: 122.58 | HI18: 123 | HJ18: 122.05 | HK18: 119.79 | HL18: 118.44 | HM18: 118.5 | HN18: 117.88 | HO18: 120.47 | HP18: 120.94 | HQ18: 120.74 | HR18: 121.46 | HS18: 124.08 | HT18: 123.11 | HU18: 122.81 | HV18: 117.85 | HW18: 118.3 | HX18: 118.48 | HY18: 118.21 | HZ18: 117.18 | IA18: 116.74 | IB18: 118.25 | IC18: 116.78 | ID18: 113.58 | IE18: 112.69 | IF18: 110.56 | IG18: 111.15 | IH18: 111 | II18: 112.62 | IJ18: 112.1 | IK18: 110.99 | IL18: 113.67 | IM18: 114.4 | IN18: 112.49 | IO18: 114.09 | IP18: 113.62 | IQ18: 112.26 | IR18: 110.86 | IS18: 112.54 | IT18: 114.55 | IU18: 117.86 | IV18: 115.25 | IW18: 115.76 | IX18: 115.88 | IY18: 115.05 | IZ18: 112.77 | JA18: 112.99 | JB18: 112.71 | JC18: 112.97 | JD18: 112.56 | JE18: 113.92 | JF18: 114.75 | JG18: 114.15 | JH18: 114.77 | JI18: 116.14 | JJ18: 118.73 | JK18: 117.98 | JL18: 117.99 | JM18: 118.37 | JN18: 119.02 | JO18: 120.14 | JP18: 120.02 | JQ18: 120.47 | JR18: 119.41 | JS18: 110.28 | JT18: 110.28 | JU18: 112.46 | JV18: 114.51 | JW18: 113.18 | JX18: 112.29 | JY18: 114.76 | JZ18: 114.23 | KA18: 113.03 | KB18: 116.2 | KC18: 113.2 | KD18: 113.56 | KE18: 110.17 | KF18: 108.28 | KG18: 108.22 | KH18: 108.8 | KI18: 109.85 | KJ18: 109.06 | KK18: 112.09 | KL18: 109.64 | KM18: 114.54 | KN18: 113.24 | KO18: 111.06 | KP18: 111.78 | KQ18: 111.75 | KR18: 111.51 | KS18: 111.73 | KT18: 110.87
A19: x | B19: -1 | C19: 5 | D19: =+D18+1 -> 12 | E19: Bristol-Myers | F19: BMY | G19: 65.4 | H19: =+G19*L19 -> 133551.46 | I19: =+[12]Main!$K$5-[12]Main!$K$6 -> -33608 | J19: =H19-I19 -> 167159.46 | K19: Q126 | L19: =+[12]Main!$K$3 -> 2042.0712 | M19: 46217 | S19: =($J19/$L19)/AB19 -> 20.16202 | T19: =($J19/$L19)/AC19 -> 17.951272 | U19: =($J19/$L19)/AD19 -> 12.612912 | V19: =($J19/$L19)/AE19 -> 12.383933 | W19: =($J19/$L19)/AF19 -> 11.829162 | X19: =($J19/$L19)/AG19 -> 12.421517 | Y19: =($J19/$L19)/AH19 -> 14.437002 | Z19: =($J19/$L19)/AI19 -> 16.082082 | AA19: =($J19/$L19)/AJ19 -> 16.082082 | AB19: 4.06 | AC19: 4.56 | AD19: 6.49 | AE19: 6.61 | AF19: 6.92 | AG19: 6.59 | AH19: 5.67 | AI19: 5.09 | AJ19: 5.09 | AK19: 5.28 | AL19: 1887 | AM19: New Jersey | AN19: United States | AO19: =BD19/FV19-1 -> 0.066370041 | AP19: =BD19/BX19-1 -> 0.005946135 | AQ19: =BD19/CA19-1 -> -0.0087885576 | AR19: =BD19/KT19-1 -> 0.24260099 | BD19: 57.52 | BE19: 55.39 | BF19: 55 | BG19: 55.53 | BH19: 54.7 | BJ19: 54 | BK19: 55.28 | BL19: 55.92 | BM19: 56.24 | BN19: 57.13 | BO19: 56.9 | BP19: 55.6 | BQ19: 56.48 | BR19: 55.57 | BS19: 57.27 | BT19: 56.6 | BU19: 54.72 | BV19: 54.46 | BW19: 54.95 | BX19: 57.18 | BY19: 56.91 | BZ19: 57.52 | CA19: 58.03 | CB19: 59.46 | CC19: 59.55 | CD19: 58.54 | CE19: 58.31 | CF19: 57.31 | CG19: 57 | CH19: 56.77 | CI19: 56.39 | CJ19: 56.45 | CK19: 55.67 | CL19: 56.16 | CM19: 56.25 | CN19: 56.59 | CO19: 56.95 | CP19: 57.38 | CQ19: 58.22 | CR19: 60.59 | CS19: 57.59 | CT19: 58.26 | CU19: 57.78 | CV19: 58.71 | CW19: 59.02 | CX19: 58.8 | CY19: 59.39 | CZ19: 59.13 | DA19: 60.17 | DB19: 58.96 | DC19: 57.89 | DD19: 58.08 | DE19: 58.06 | DF19: 58.62 | DG19: 59.47 | DH19: 59.2 | DI19: 57.67 | DJ19: 59.33 | DK19: 59.6 | DL19: 61.73 | DM19: 60.65 | DN19: 59.73 | DO19: 58.54 | DP19: 59.43 | DQ19: 58.94 | DR19: 57.39 | DS19: 57 | DT19: 57.48 | DU19: 58.11 | DV19: 59.37 | DW19: 59.71 | DX19: 59.71 | DY19: 59.08 | DZ19: 58.95 | EA19: 59.98 | EB19: 60.13 | EC19: 60.63 | ED19: 60.29 | EE19: 60.74 | EF19: 62.33 | EG19: 61.22 | EH19: 62.34 | EI19: 62.37 | EJ19: 61.1 | EK19: 61.3 | EL19: 61.6 | EM19: 61.25 | EN19: 60.66 | EO19: 60.3 | EP19: 59.73 | EQ19: 60.35 | ER19: 60.74 | ES19: 59.86 | ET19: 59.93 | EU19: 60.86 | EV19: 60.77 | EW19: 61.99 | EX19: 59.52 | EY19: 57.62 | EZ19: 55.99 | FA19: 55.89 | FB19: 55.05 | FC19: 54.28 | FD19: 54.62 | FE19: 55.56 | FF19: 54.6 | FG19: 54.65 | FH19: 54.94 | FI19: 54.5 | FJ19: 54.22 | FK19: 55.26 | FL19: 56.62 | FM19: 57.02 | FN19: 55.92 | FO19: 55.77 | FP19: 55.86 | FQ19: 55.9 | FR19: 56.72 | FS19: 54.42 | FT19: 53.06 | FU19: 53.46 | FV19: 53.94 | FW19: 54.21 | FX19: 54.11 | FY19: 54.64 | FZ19: 54.71 | GA19: 54.28 | GB19: 54.66 | GC19: 54.19 | GD19: 53.33 | GE19: 53.55 | GF19: 54.23 | GG19: 54.29 | GH19: 52.41 | GI19: 51.2 | GJ19: 51.21 | GK19: 50.65 | GL19: 51.67 | GM19: 52.15 | GN19: 51.95 | GO19: 50.96 | GP19: 48.25 | GQ19: 49.18 | GR19: 49.2 | GS19: 49.25 | GT19: 49.05 | GU19: 47.76 | GV19: 46.25 | GW19: 45.94 | GX19: 45.79 | GY19: 47.06 | GZ19: 46.81 | HA19: 46.65 | HB19: 48.63 | HC19: 49.08 | HD19: 48.72 | HE19: 47.26 | HF19: 46.69 | HG19: 46.63 | HH19: 46.47 | HI19: 45.59 | HJ19: 46.02 | HK19: 46.07 | HL19: 45.62 | HM19: 42.6 | HN19: 42.82 | HO19: 43.39 | HP19: 43.83 | HQ19: 43.83 | HR19: 44.39 | HS19: 44.54 | HT19: 43.59 | HU19: 43.63 | HV19: 43.39 | HW19: 43.61 | HX19: 43.8 | HY19: 43.54 | HZ19: 43.96 | IA19: 44.68 | IB19: 44.54 | IC19: 44.66 | ID19: 45.14 | IE19: 45.45 | IF19: 45.73 | IG19: 47.43 | IH19: 45.1 | II19: 44.15 | IJ19: 44.12 | IK19: 43.41 | IL19: 44.16 | IM19: 44.91 | IN19: 44.98 | IO19: 45.02 | IP19: 45.6 | IQ19: 46.15 | IR19: 46.34 | IS19: 46.35 | IT19: 46.2 | IU19: 47.54 | IV19: 47.15 | IW19: 47.23 | IX19: 46.72 | IY19: 47.14 | IZ19: 46.69 | JA19: 47.5 | JB19: 47.41 | JC19: 47.18 | JD19: 46.88 | JE19: 47.63 | JF19: 47.21 | JG19: 47.14 | JH19: 47.92 | JI19: 48.43 | JJ19: 48.26 | JK19: 48.34 | JL19: 48.19 | JM19: 48.44 | JN19: 47.81 | JO19: 47.85 | JP19: 46.55 | JQ19: 45.93 | JR19: 45.95 | JS19: 45.36 | JT19: 44.82 | JU19: 45.85 | JV19: 45.4 | JW19: 44.23 | JX19: 43.31 | JY19: 45.98 | JZ19: 46.86 | KA19: 47.51 | KB19: 48.43 | KC19: 48.94 | KD19: 48.98 | KE19: 48.02 | KF19: 46.69 | KG19: 47.36 | KH19: 48.06 | KI19: 47.17 | KJ19: 46.43 | KK19: 47.34 | KL19: 46.86 | KM19: 48.52 | KN19: 47.66 | KO19: 47.04 | KP19: 46.49 | KQ19: 46.92 | KR19: 47.63 | KS19: 47.51 | KT19: 46.29
A20: x | D20: =+D19+1 -> 13 | E20: GSK | F20: GSK US | G20: 51.81 | H20: =+G20*L20/2 -> 104215.82 | I20: =([13]Main!$J$6-[13]Main!$J$7)*GBP -> -20805.884 | J20: =H20-I20 -> 125021.7 | K20: Q126 | L20: =+[13]Main!$J$4 -> 4023 | M20: 46227 | S20: =($J20/$L20)/AB20 -> 10.024753 | T20: =($J20/$L20)/AC20 -> 8.9817149 | U20: =($J20/$L20)/AD20 -> 8.8286175 | V20: =($J20/$L20)/AE20 -> 7.6543679 | W20: - | X20: - | Y20: - | Z20: - | AA20: - | AB20: 3.1 | AC20: 3.46 | AD20: 3.52 | AE20: 4.06 | AF20: 4.79 | AG20: 5.17 | AH20: 5.44 | AI20: 5.8 | AJ20: 5.86 | AK20: 6.17 | AM20: London | AN20: United Kingdom
A21: x | D21: =+D20 -> 13 | E21: GSK | F21: GSK LN | G21: 1931.5 | H21: =+G21*L21/100*GBP -> 103548.68 | I21: =([13]Main!$J$6-[13]Main!$J$7)*GBP -> -20805.884 | J21: =H21-I21 -> 124354.56 | K21: Q126 | L21: =+L20 -> 4023 | M21: 46227 | N21: - | O21: - | P21: - | Q21: - | R21: - | S21: =($J21/$L21)/AB21 -> 0.24728722 | T21: =($J21/$L21)/AC21 -> 0.22238059 | U21: =($J21/$L21)/AD21 -> 0.22399205 | V21: =($J21/$L21)/AE21 -> 0.20072015 | W21: =($J21/$L21*100)/AF21 -> 17.365676 | X21: =($J21/$L21*100)/AG21 -> 16.099428 | Y21: =($J21/$L21*100)/AH21 -> 15.302427 | Z21: =($J21/$L21*100)/AI21 -> 14.310603 | AA21: =($J21/$L21*100)/AJ21 -> 14.179313 | AB21: 125 | AC21: 139 | AD21: 138 | AE21: 154 | AF21: 178 | AG21: 192 | AH21: 202 | AI21: 216 | AJ21: 218 | AK21: 230 | AM21: London | AN21: United Kingdom
A22: x | D22: =+D21+1 -> 14 | E22: Sanofi | F22: SNY | G22: 43.08 | H22: =+G22*L22*2 -> 107786.16 | I22: =([14]Main!$K$5-[14]Main!$K$6)*EUR -> -14319 | J22: =H22-I22 -> 122105.16 | K22: =+K23 -> Q126 | L22: =+L23 -> 1251 | M22: =+M23 -> 46224 | N22: - | O22: - | P22: - | Q22: - | R22: - | S22: - | T22: - | U22: - | V22: - | W22: =($J22/$L22)/AF22 -> 19.639043 | X22: =($J22/$L22)/AG22 -> 18.556282 | Y22: =($J22/$L22)/AH22 -> 17.034213 | Z22: =($J22/$L22)/AI22 -> 16.027265 | AA22: =($J22/$L22)/AJ22 -> 15.016314 | AB22: 3.73 | AC22: 2.83 | AD22: 2.77 | AE22: 3.28 | AF22: 4.97 | AG22: 5.26 | AH22: 5.73 | AI22: 6.09 | AJ22: 6.5 | AK22: 6.74 | AM22: Paris | AN22: France
A23: x | D23: =+D22 -> 14 | E23: Sanofi | F23: SAN | G23: 74.47 | H23: =+G23*L23*EUR -> 103409.79 | I23: =([14]Main!$K$5-[14]Main!$K$6)*EUR -> -14319 | J23: =H23-I23 -> 117728.79 | K23: Q126 | L23: =+[15]Main!$K$3 -> 1251 | M23: 46224 | S23: - | T23: - | U23: - | V23: =($J23/$L23)/AE23 -> 20.547542 | W23: - | X23: - | Y23: - | Z23: - | AA23: - | AB23: - | AC23: - | AD23: - | AE23: 4.58 | AF23: 5.03 | AG23: - | AH23: - | AI23: - | AJ23: - | AK23: - | AM23: Paris | AN23: France
