Workbook
Name CNY: FX!$B$4
Name JPY: FX!$C$6
Name KRW: FX!$C$3
Name None: FX!$B$4
Name NTD: FX!$C$2

Sheet Semiconductors
B2: Average | M2: =AVERAGE(M5:M17) -> 53.942377 | N2: =AVERAGE(N5:N17) -> 35.702809
L3: EV/E | Q3: EPS | Z3: =AVERAGE(Z5:Z33) -> 1052549.8 | AA3: =AVERAGE(AA5:AA33) -> 792600.5
B4: Name | C4: Ticker | D4: Price | E4: MC | F4: NC | G4: EV | H4: SO | I4: Update | J4: Last | K4: Founded | L4: 2025 | M4: 2026 | N4: =+M4+1 -> 2027 | O4: =+N4+1 -> 2028 | P4: =+O4+1 -> 2029 | Q4: 2024 | R4: 2025 | S4: 2026 | T4: =+S4+1 -> 2027 | U4: =+T4+1 -> 2028 | V4: =+U4+1 -> 2029 | W4: City | X4: State | Y4: Country | Z4: CEO Salary | AA4: CTO Salary
A5: x | B5: #VALUE! | C5: {=_FV(B5,"Ticker symbol",TRUE)} -> NVDA | D5: {=_FV(B5,"Price")} -> 225.16 | E5: =+D5*H5 -> 5471388 | F5: =+[1]Main!$K$5-[1]Main!$K$6 -> 48325 | G5: =+E5-F5 -> 5423063 | H5: =+[1]Main!$K$3 -> 24300 | I5: Q126 | J5: 46101 | K5: 1993 | L5: =($G5/$H5)/R5 -> 75.908611 | M5: =($G$5/$H$5)/S5 -> 45.545167 | N5: =($G$5/$H$5)/T5 -> 26.953058 | O5: =($G$5/$H$5)/U5 -> 20.051331 | Q5: 1.19 | R5: 2.94 | S5: 4.9 | T5: 8.28 | U5: 11.13 | Z5: 1486199 | AA5: 844087
A6: x | B6: #VALUE! | C6: {=_FV(B6,"Ticker symbol",TRUE)} -> TSM | D6: {=_FV(B6,"Price")} -> 426.35 | E6: =+D6*H6/5 -> 2211136.4 | F6: =([2]Main!$J$7-[2]Main!$J$8)/FX!C5 -> -87685.152 | G6: =+E6-F6 -> 2298821.5 | H6: =+[2]Main!$J$4 -> 25931 | I6: Q324 | J6: 45652 | L6: =($G6/$H6)/R6*5 -> 41.69872 | M6: =($G6/$H6)/S6*5 -> 28.377554 | N6: =($G6/$H6)/T6*5 -> 22.649842 | Q6: 7.04 | R6: 10.63 | S6: 15.62 | T6: 19.57 | Z6: =17000000/NTD -> 520195.84
A7: x | B7: Taiwan Semi | C7: 2330 TT | D7: 2375 | E7: =+D7*H7/FX!C2 -> 1884520.3 | F7: =([2]Main!$J$7-[2]Main!$J$8)/FX!C5 -> -87685.152 | G7: =+E7-F7 -> 1972205.5 | H7: =+[2]Main!$J$4 -> 25931 | I7: =+I6 -> Q324 | J7: =+J6 -> 45652 | Z7: =+Z6 -> 520195.84
A8: x | B8: #VALUE! | C8: {=_FV(B8,"Ticker symbol",TRUE)} -> AVGO | D8: {=_FV(B8,"Price")} -> 392.99 | E8: =+D8*H8 -> 1920935.1 | F8: =+[3]Main!$J$5-[3]Main!$J$6 -> -51883 | G8: =+E8-F8 -> 1972818.1 | H8: =+[3]Main!$J$3 -> 4888 | I8: Q224 | J8: 45722 | L8: =($G8/$H8)/R8 -> 84.613074 | M8: =($G8/$H8)/S8 -> 35.654096 | N8: =($G8/$H8)/T8 -> 22.434928 | Q8: 1.23 | R8: 4.77 | S8: 11.32 | T8: 17.99 | Z8: 1200000 | AA8: 721000
A9: x | B9: Samsung | C9: 005930 KS | D9: 277500 | E9: =+D9*H9/KRW -> 1291958 | F9: =+([4]Main!$K$5-[4]Main!$K$6)/KRW*1000 -> 119758.15 | G9: =+E9-F9 -> 1172199.9 | H9: =+[4]Main!$K$3 -> 6758.9192 | I9: Q126 | J9: 46211
A10: x | B10: #VALUE! | C10: AMD | D10: 484 | E10: =+D10*H10 -> 794244 | F10: =+[5]Main!$M$5-[5]Main!$M$6 -> 4023 | G10: =+E10-F10 -> 790221 | H10: =+[5]Main!$M$3 -> 1641 | I10: Q225 | J10: 45939 | K10: 1969 | L10: =($G10/$H10)/R10 -> 181.71639 | M10: =($G10/$H10)/S10 -> 70.299043 | N10: =($G10/$H10)/T10 -> 42.918756 | Q10: 1 | R10: 2.65 | S10: 6.85 | T10: 11.22 | Z10: 1291258 | AA10: 820000
A11: x | B11: #VALUE! | C11: {=_FV(B11,"Ticker symbol",TRUE)} -> INTC | D11: 91 | E11: =+D11*H11 -> 464464 | F11: =+[6]Main!$L$5-[6]Main!$L$6 -> -12400 | G11: =+E11-F11 -> 476864 | H11: =+[6]Main!$L$3 -> 5104 | I11: Q126 | J11: 46198 | L11: =($G11/$H11)/R11 -> -1557.1578 | M11: =($G11/$H11)/S11 -> 89.836026 | N11: =($G11/$H11)/T11 -> 63.557461 | Q11: -4.38 | R11: -0.06 | S11: 1.04 | T11: 1.47 | Z11: 1000000 | AA11: 1000000
A12: x | B12: #VALUE! | C12: ARM | D12: {=_FV(B12,"Price")} -> 279.44 | E12: =+D12*H12 -> 291874.25 | F12: =+[7]Main!$L$5-[7]Main!$L$6 -> 3664 | G12: =+E12-F12 -> 288210.25 | H12: =+[7]Main!$L$3 -> 1044.497 | I12: Q424 | AA12: 1350000
A13: x | B13: #VALUE! | C13: TXN | D13: {=_FV(B13,"Price")} -> 279.58 | E13: =+D13*H13 -> 253738.9 | F13: =+[8]Main!$K$5-[8]Main!$K$6 -> 1153 | G13: =+E13-F13 -> 252585.9 | H13: =+[8]Main!$K$3 -> 907.57171 | I13: Q322 | J13: 44946 | AA13: 830000
A14: x | B14: #VALUE! | C14: QCOM | D14: {=_FV(B14,"Price")} -> 165.79 | E14: =+D14*H14 -> 184690.06 | F14: =+[9]Main!$L$5-[9]Main!$L$6 -> -1522 | G14: =+E14-F14 -> 186212.06 | H14: =+[9]Main!$L$3 -> 1114 | I14: Q224 | J14: 45581 | Z14: 1350000 | AA14: 800000
A15: x | B15: #VALUE! | C15: MRVL | D15: {=_FV(B15,"Price")} -> 222.02 | E15: =+D15*H15 -> 194223.1 | F15: =+[10]Main!$H$5-[10]Main!$H$6 -> -1117.7 | G15: =+E15-F15 -> 195340.8 | H15: =[10]Main!$H$3 -> 874.8 | I15: Q126 | J15: 46203
A16: x | B16: #VALUE! | C16: ADI | D16: {=_FV(B16,"Price")} -> 389.39 | E16: =+D16*H16 -> 189666.82 | F16: =+[11]Main!$J$5-[11]Main!$J$6 -> -4695.343 | G16: =+E16-F16 -> 194362.17 | H16: =+[11]Main!$J$3 -> 487.08704 | I16: Q126 | J16: 46211 | AA16: 700000
A17: x | B17: #VALUE! | C17: 2454 TT | D17: {=_FV(B17,"Price")} -> 4050 | E17: =+D17*H17/FX!C5 -> 202943.11 | F17: =([12]Main!$K$5-[12]Main!$K$6)/FX!C5 -> 9981.0878 | G17: =+E17-F17 -> 192962.02 | H17: =+[12]Main!$K$3 -> 1603 | I17: Q126 | J17: 46213 | K17: 1997
A18: x | B18: Tokyo Electron | C18: 8035 JP | D18: 41720 | E18: =124700 -> 124700
A19: x | B19: Advantest | C19: 6857 JP | D19: 25535 | E19: 119990
B20: Shin-Etsu Chemical | C20: 4063 JP | D20: 6226 | E20: 73070
A21: x | B21: NXP Semiconductor | C21: NXPI | D21: 209.6 | E21: 52970 | AA21: 580000
A22: x | B22: Microchip | C22: MCHP | D22: 67.91 | E22: 36740 | AA22: 280918
B23: Longi Green | C23: 601012 CH | D23: 17.76 | E23: =134230/CNY -> 19175.714
A24: x | B24: Super Micro | C24: SMCI | D24: 20.65 | E24: =+D24*H24 -> 13216 | F24: =+[13]Main!$M$5-[13]Main!$M$6 -> -504 | G24: =+E24-F24 -> 13720 | H24: =+[13]Main!$M$3 -> 640 | I24: Q224 | J24: 45560
B25: Hygon Information Technology | C25: 688041 CH
B26: Cambricon | C26: 688256 CH
A27: x | B27: Eoptolink | C27: 300502 CH
B28: Hoya | C28: 7741 JP
B29: Samsung Electro-Mechanics | C29: 009150 KS
A30: x | B30: Infineon | C30: IFX GR
B31: Cerebras | C31: CBRS | D31: 220
A32: x | B32: Monolithic | C32: MPWR
A33: x | B33: STMicro | C33: STM | D33: 32.51 | E33: 28890
A34: x | B34: Disco | C34: 6146 JP
A35: x | B35: Renesas | C35: 6723 JP
A36: x | B36: United Micro | C36: 2303 TT
A37: x | B37: Astera | C37: ALAB | D37: 118.63 | AA37: 615000
A38: x | B38: Naura | C38: 002371 CH
A39: x | B39: ASM International | C39: ASM NA | D39: 717 | E39: 41130
A40: x | B40: GigaDevice | C40: 3986 HK
A41: x | B41: ASE Technology | C41: 3711 TT | D41: 353.5
...

Sheet Memory
A1: Semis
M2: EV/E | S2: EPS
B3: Name | C3: Name | D3: Ticker | E3: Price | F3: MC | G3: NC | H3: EV | I3: SO | J3: Update | K3: Last | L3: Founded | M3: 2025 | N3: 2026 | O3: =+N3+1 -> 2027 | P3: =+O3+1 -> 2028 | Q3: =+P3+1 -> 2029 | R3: 2030 | S3: 2025 | T3: 2026 | U3: 2027 | V3: =+U3+1 -> 2028 | W3: =+V3+1 -> 2029 | X3: 2030
A4: x | B4: Samsung | C4: Samsung | D4: 005930 KS | E4: 285000 | F4: =+E4*I4/KRW -> 1326875.8 | G4: =([4]Main!$K$5-[4]Main!$K$6)/KRW*1000 -> 119758.15 | H4: =+F4-G4 -> 1207117.7 | I4: =+[4]Main!$K$3 -> 6758.9192 | J4: Q424 | K4: 46207
A5: x | B5: #VALUE! | C5: Micron | D5: MU | E5: 830 | F5: =+E5*I5 -> 950350 | G5: =+[17]Main!$J$5-[17]Main!$J$6 -> 25303 | H5: =+F5-G5 -> 925047 | I5: =+[17]Main!$J$3 -> 1145 | J5: Q226 | K5: 46207 | L5: 1978 | M5: =($H5/$I5)/S5 -> 1154.1447 | N5: =($H5/$I5)/T5 -> 106.44286 | O5: =($H5/$I5)/U5 -> 11.045957 | P5: =($H5/$I5)/V5 -> 5.2952829 | Q5: =($H5/$I5)/W5 -> 9.0877538 | R5: =($H5/$I5)/X5 -> 12.916088 | S5: 0.7 | T5: 7.59 | U5: 73.14 | V5: 152.57 | W5: 88.9 | X5: 62.55 | AB5: 1446185 | AC5: 749323
A6: x | B6: SK Hynix | C6: SK Hynix | D6: 000660 KS | E6: 1816000 | F6: =+E6*I6/KRW -> 890643.71 | G6: =([18]Main!$L$5-[18]Main!$L$6)/KRW -> 47783.709 | H6: =+F6-G6 -> 842860 | I6: =+[18]Main!$L$3 -> 712 | J6: Q126 | K6: 46230
A7: x | B7: Kioxia | C7: Kioxia | D7: 285A JP | E7: 54550 | F7: =+E7*I7/JPY -> 187342.34 | G7: =([19]Main!$J$5-[19]Main!$J$6)/JPY -> -2171.4005 | H7: =+F7-G7 -> 189513.74 | I7: =+[19]Main!$J$3 -> 541.45542 | J7: Q126 | K7: 46230
A8: x | B8: #VALUE! | C8: Sandisk | D8: SNDK | E8: {=_FV(B8,"Price")} -> 1641.11 | F8: =+E8*I8 -> 243031.58 | G8: =+[20]Main!$L$5-[20]Main!$L$6 -> 3735 | H8: =+F8-G8 -> 239296.58 | I8: =+[20]Main!$L$3 -> 148.08976 | J8: Q126 | K8: 46230 | AC8: 625000
A9: x | B9: #VALUE! | C9: Seagate | D9: STX | E9: {=_FV(B9,"Price")} -> 973.44
A10: x | B10: #VALUE! | C10: Western Digital | D10: WDC | E10: {=_FV(B10,"Price")} -> 508.8

Sheet CapEquiment
B2: Name | C2: Name | D2: Ticker | E2: Price | F2: MC | G2: NC | H2: EV | I2: SO | J2: Update | K2: Last | L2: Founded
B3: ASML | C3: ASML | D3: 1348 | E3: =+D3*H3 -> 530438 | F3: =+[21]Main!$L$5-[21]Main!$L$6 -> 1413 | G3: =+E3-F3 -> 529025 | H3: =+[21]Main!$L$3 -> 393.5 | I3: Q224 | J3: 45581 | AA3: 784000
B4: Applied Materials | C4: AMAT | D4: 360 | E4: 267520 | F4: =+[22]Main!$K$5-[22]Main!$K$6 -> 6926 | G4: =+E4-F4 -> 260594 | H4: =+[22]Main!$K$3 -> 799 | I4: Q425 | L4: =($G4/$H4)/R4 -> 37.661684 | M4: =($G4/$H4)/S4 -> 29.462528 | N4: =($G4/$H4)/T4 -> 23.082108 | Q4: 8.61 | R4: 8.66 | S4: 11.07 | T4: 14.13 | Z4: 1030000 | AA4: 665000
B5: Lam Research | C5: LRCX | D5: 226 | E5: 260830 | G5: =E5-F5 -> 260830 | J5: 46089 | K5: 1980 | W5: Fremont | X5: California | Y5: United States | Z5: 1236539 | AA5: 714596
B6: KLA Corp | C6: KLAC | D6: 1462 | E6: 182590 | AA6: 750000

Sheet Optical
B3: Name | C3: Name | D3: Ticker | E3: Price | F3: MC | G3: NC | H3: EV | I3: SO | J3: Update | K3: Last | L3: Founded | M3: 2025 | N3: 2026 | O3: =+N3+1 -> 2027 | P3: =+O3+1 -> 2028 | Q3: =+P3+1 -> 2029 | R3: 2030 | S3: 2025 | T3: 2026 | U3: 2027 | V3: =+U3+1 -> 2028 | W3: =+V3+1 -> 2029 | X3: 2030
A4: x | B4: Coherent | C4: Coherent | D4: COHR
A5: x | B5: Lumentum | C5: Lumentum | D5: LITE | E5: 819 | F5: =+E5*I5 -> 78787.8 | G5: =+[23]Main!$I$5-[23]Main!$I$6 -> -109.5 | H5: =+F5-G5 -> 78897.3 | I5: =+[23]Main!$I$3 -> 96.2 | J5: Q126 | K5: 46217
A6: x | B6: Credo | C6: Credo | D6: CRDO
A7: x | B7: Suzhou TFC Optical Communication | C7: 300394 CH
A8: x | B8: Yangtze Optical Fibre and Cable | C8: 6869 HK
A9: x | B9: Fabrinet | C9: FN
B10: Applied Optoelectronics | C10: Applied Optoelectronics | D10: AAOI | E10: 118 | F10: =+E10*I10 -> 9979.17 | G10: =+[24]Main!$J$5-[24]Main!$J$6 -> 442.479 | H10: =+F10-G10 -> 9536.691 | I10: =+[24]Main!$J$3 -> 84.569237 | J10: Q226 | K10: 46240

Sheet Quantum
A1: Main
B2: Name | C2: Ticker | D2: Price | E2: MC | F2: NC | G2: EV | H2: SO | I2: Update | J2: Last | K2: Founded
B3: Quantinuum | C3: QNT | D3: 56.14 | E3: 20000
B4: PsiQuantum | C4: Private | E4: 16000
B5: IonQ | C5: IONQ | D5: 37 | E5: =+D5*H5 -> 13727 | F5: =+[25]Main!$J$5-[25]Main!$J$6 -> 3091.896 | G5: =+E5-F5 -> 10635.104 | H5: =+[25]Main!$J$3 -> 371 | I5: Q126 | J5: 46230
B6: Rigetti | C6: RGTI | D6: 14.95 | E6: =+D6*H6 -> 4239.0257 | F6: =+[26]Main!$L$5-[26]Main!$L$6 -> 217 | G6: =E6-F6 -> 4022.0257 | H6: =+[26]Main!$L$3 -> 283.54687 | I6: Q324 | J6: 45664
B7: Quantum Computing Inc | C7: QUBT | D7: 7.15 | E7: 2000
B8: D-Wave | C8: QBTS | D8: 15.75 | E8: =+D8*H8 -> 5460.8177 | F8: =+[27]Main!$L$5-[27]Main!$L$6 -> 804.033 | G8: =+E8-F8 -> 4656.7847 | H8: =+[27]Main!$L$3 -> 346.71858 | I8: Q324 | J8: 45663
B9: SealSQ | C9: LAES | D9: 3.03
B10: Infeqtion | C10: INFQ | D10: 8.93
B12: Xanadu
B13: IQM Quantum Computers
B14: Multiverse Computing
B15: Infleqtion
B16: Quantum Brilliance
B17: Nu Quantum
B18: BlueQubit
B19: Alice & Bob
B20: Quanscient
B21: Quantum Circuits
B22: Qblox
B23: Quantum Motion
... B34: Quibtekk
B35: Zapata Computing | C35: ZPTA
B36: UbiQD
B37: T-Rize Group
B38: Algorithmiq
B39: Fabric Cryptography
B40: Oxford Quantum Circuits
B41: planqc
B42: Terra Quantum
B43: SemiQon
B45: BosonQ Psi
B46: Quantum Source
B47: Quandela
B48: Arctic Instruments
... B63: Silicon Spin Qubits

Sheet Networking
B2: Name | C2: Ticker | D2: Price | E2: MC | F2: NC | G2: EV | H2: SO | I2: Update | J2: Last | K2: Founded
A3: x | B3: Cisco | C3: CSCO | D3: 48.51 | E3: 199280
A4: x | B4: Arista | C4: ANET
A5: x | B5: Marvel | C5: MRVL
A6: x | B6: Palo Alto | C6: PANW
A7: x | B7: Motorola | C7: MSI
A8: x | B8: Nokia | C8: NOKIA FH
A9: x | B9: Ericsson | C9: ERICB SS
A10: x | B10: ZTE | C10: 000063 CH
A11: x | B11: ZTE | C11: 763 HK
A12: x | B12: Ubiquiti | C12: UI
A13: x | B13: Fortinet | C13: FTNT
A14: x | B14: Ciena | C14: CIEN
A15: x | B15: Accton Technology Corp. | C15: 2345 TT

Sheet Electronics-Computers
A1: Semis
B2: Name | C2: Ticker | D2: Price | E2: MC | F2: NC | G2: EV | H2: S/O | I2: Update | J2: Last | K2: NPV | L2: Upside | M2: Discount | N2: Terminal | O2: ROIC | P2: Founded
A3: x | B3: Apple | C3: AAPL | D3: 334.36 | E3: =+D3*H3 -> 4998013.3 | F3: =+[28]Main!$O$5-[28]Main!$O$6 -> 31288 | G3: =+E3-F3 -> 4966725.3 | H3: =+[28]Main!$O$3 -> 14948 | I3: Q424 | J3: 45750 | K3: =[28]Model!$CE$39 -> 0.46906012 | L3: =+K3/D3-1 -> -0.99859714 | M3: =+[28]Model!$CE$36 -> 0.041953408 | N3: =+[28]Model!$CE$37 -> 0.03632 | O3: 0 | P3: 1977
A4: x | B4: Samsung | C4: 005930 KS | D4: 57600 | E4: {=+D4*H4/KRW} -> 268168.59 | F4: =([4]Main!$K$5-[4]Main!$K$6)/KRW -> 119.75815 | G4: =+E4-F4 -> 268048.83 | H4: =+[4]Main!$K$3 -> 6758.9192 | I4: Q424 | J4: 45750
B5: Midea Group | C5: 000333 CH | D5: 73.36 | E5: =+D5*H5/CNY -> 79962.4 | G5: =+E5-F5 -> 79962.4 | H5: 7630
B6: Bloom Energy | C6: BE
A7: x | B7: Hon Hai | C7: 2317 TT
B8: Hitachi | C8: 6501 JP
A9: x | B9: Hangzhou Hikvision | C9: 002415 CH
A10: x | B10: Xiaomi | C10: 1810 HK
A11: x | B11: HP | C11: HPQ
A12: x | B12: HP Enterprise | C12: HPE
A13: x | B13: Dell | C13: DELL
A14: x | B14: Amphenol | C14: APH
A15: x | B15: Murata Manufacturing | C15: 6981 JP
A16: x | B16: Motorola Solutions | C16: MSI
A17: x | B17: Canon | C17: 7751 JP
A18: x | B18: Foxconn | C18: 601138 CH
A19: x | B19: Delta Electronics Thai | C19: DELTA TB
A20: x | B20: Delta Electronics | C20: 2308 TT
... A38: x | B38: Chaozhou Three-Circle | C38: 300408 CH
B39: TDK | C39: 6762 JP
A40: x | B40: Luxshare | C40: 002475 CH
A41: x | B41: Super Micro | C41: SMCI
A42: x | B42: Seiko Epson | C42: 6724 JP
A43: x | B43: Sanmina | C43: SANM
A44: x | B44: Asustek | C44: 2357 HK
A45: x | B45: Shennan Circuit Co | C45: 002916 CH
A46: x | B46: IBIDEN | C46: 4062 JP
A47: x | B47: Fujitsu | C47: 6702 JP
A48: x | B48: Logitech | C48: LOGN
A49: x | B49: Quantinuum | C49: QNT
A50: x | B50: Lenovo | C50: 992 HK
A51: x | B51: IonQ | C51: IONQ | D51: 39 | E51: =+D51*H51 -> 14469 | F51: =+[25]Main!$J$5-[25]Main!$J$6 -> 3091.896 | G51: =+E51-F51 -> 11377.104 | H51: =+[25]Main!$J$3 -> 371 | I51: Q423 | J51: 45534
A52: x | B52: Rigetti | C52: RGTI | D52: 8.51 | E52: =+D52*H52 -> 2412.9839 | F52: =+[26]Main!$L$5-[26]Main!$L$6 -> 217 | G52: =+E52-F52 -> 2195.9839 | H52: =+[26]Main!$L$3 -> 283.54687 | I52: Q224 | J52: 45534
A53: x | B53: D-Wave | C53: QBTS
A54: x | B54: IBM | C54: IBM
A55: x | B55: Jabil | C55: JBL | D55: 101.64
A56: x | B56: Celestica | C56: CLS | D56: 247 | E56: =+D56*H56 -> 28641.902 | F56: =+[29]Main!$I$5-[29]Main!$I$6 -> -373.4 | G56: =+E56-F56 -> 29015.302 | H56: =+[29]Main!$I$3 -> 115.95912 | I56: Q125 | J56: 45915
B60: Private
...

Sheet FX
B2: NTD | C2: 32.68
B3: KRW | C3: 1451.75
B4: 7 | C4: CNY
B5: TWD | C5: 31.99
B6: JPY | C6: 157.66
B7: EUR
