Workbook

Sheet Main
B2: Name | C2: Indication | D2: Approved | E2: Economics | F2: Mechanism | G2: IP | I2: Price | J2: 800
B3: Arcalyst (rilonacept) | C3: CAPS | D3: 39479 | F3: IL-1 | I3: Shares | J3: 106 | K3: Q226
B4: Eylea (aflibercept) | C4: AMD | D4: 40865 | E4: BAY | F4: VEGF | I4: MC | J4: =J2*J3 -> 84800
B5: Zaltrap (aflibercept) | C5: mCRC | D5: 41124 | E5: SNY | F5: VEGF | I5: Cash | J5: =2962.6+5791.1+9786 -> 18539.7 | K5: Q126
B6: Praluent (alirocumab) | C6: Hypercholesterolemia | D6: 42209 | E6: SNY | F6: PCSK9 | I6: Debt | J6: 1986.2 | K6: Q126
B7: Dupixent (dupilumab) | C7: Asthma, AD | D7: 42822 | E7: SNY | F7: IL-4 | I7: EV | J7: =J4-J5+J6 -> 68246.5
B8: Kevzara (sarilumab) | C8: RA | D8: 42969 | E8: SNY | F8: IL-6R
B9: Libtayo (cemiplimab) | C9: NSCLC | D9: 43371 | F9: PD-1 | I9: CEO: Len Schleifer
B10: Veopoz (pozelimab) | C10: CHAPLE | D10: 45156 | E10: 1 | F10: C5 | I10: CSO: George Yancopoulos
B11: Evkeeza (evinacumab) | C11: Hypercholesterolemia | D11: 44238 | E11: 1 | F11: ANGPTL3 | I11: CFO: Chris Fenimore
D12: Phase | I12: SVP, Internal Medicine: Boaz Hirshberg
B13: Ordspono (odronextamab) | C13: DLBCL | D13: Filed | E13: 1 | F13: CD20xCD3 | G13: =129.4+96.3+66 -> 291.7 | I13: Founded: 1988
B14: mibavademab | C14: Lipodystrophy | D14: III | E14: 1 | F14: LEPR agonist | I14: IPO: 1991
B15: Lynozyfic (linvoseltamab) | C15: MM | D15: Filed | E15: 1 | F15: BCMAxCD3 | G15: =141.9+78.7+45.5 -> 266.1
B16: fianlimab | C16: Melanoma | D16: Failed | E16: 1 | F16: LAG3 | G16: =215.5+112.2+43.4 -> 371.1
B17: itepekimab | C17: CRSsNP, COPD | D17: III | F17: IL-33 | G17: =96.2+70.3+26.5 -> 193
B18: REGN9933 | C18: Thrombosis | D18: III | F18: Factor XI
B19: REGN7508 (cenvacibart) | C19: Thrombosis | D19: III | F19: Factor XI
B20: nexiguran ziclumeran (NTLA-2001) | C20: ATTR | D20: III | E20: NTLA | F20: CRISPR
B21: HS-20094 (olatorepatide) | C21: Obesity | D21: II | E21: Hansoh | F21: GLP/GIP
B22: REGN7257 | C22: Aplastic Anemia | F22: IL-2Rgamma
B23: trevogrumab | C23: obesity | D23: II | E23: 1 | F23: myostatin
B24: ALN-CIDEB | C24: NASH | D24: I | E24: ALNY | I24: REGN5713-5715, , REGN1908-1909, mibavademab
B25: garetosmab | C25: FOP/obesity | D25: II | E25: 1 | F25: Activin A
B26: REGN7075 | C26: NSCLC | F26: EGFR/CD28
B27: REGN7999 | C27: Iron Overload | F27: TMPRSS6
B28: cemdisiran | C28: Myasthenia Gravis | D28: Filed | E28: ALNY | F28: C5
B29: REGN4018 (ubamatamab) | C29: ovarian cancer | F29: MUC16xCD3
B30: REGN6569 | F30: GITR
B31: Otarmeni (lunsotogene parvec) | C31: otoferlin deafness | D31: Approved | F31: otoferlin AAV
B32: REGN5093 | F32: MET
B33: 27T51 | C33: ovarian cancer | D33: I | E33: 2SeventyBio | F33: MUC16 cell therapy
B34: ALN-F1202 | C34: Factor XII | D34: I | E34: ALNY
B35: ALN-PNP | E35: ALNY | F35: PNPLA3
B36: REGN9533 | C36: Factor XII | D36: I
B37: REGN10597 | C37: Oncology | D37: I | F37: PD-1-IL2RA-IL2 Fusion Protein
B38: REGN5459 (vonsetamig) | C38: Multiple Myeloma, Kidney Translation, LN | D38: II | F38: CD3xBCMA
B39: REGN7945 | D39: II | F39: CD38xCD28
B40: REGN5668 | C40: Ovarian/Uterine Cancer | D40: I/II | F40: MUC16xCD28
B41: REGN5381 | C41: Hypertension | D41: II | F41: NPR1 antagonist
...

Sheet Model
A1: Main
C2: Q111 | D2: Q211 | E2: Q311 | F2: Q411 | G2: Q112 | H2: Q212 | I2: Q312 | J2: Q412 | K2: Q113 | L2: Q213 | M2: Q313 | N2: Q413 | O2: Q114 | P2: Q214 | Q2: Q314 | R2: Q414 | S2: Q115 | T2: Q215 | U2: Q315 | V2: Q415 | W2: Q116 | X2: Q216 | Y2: Q316 | Z2: Q416 | AA2: Q117 | AB2: Q217 | AC2: Q317 | AD2: Q417 | AE2: Q118 | AF2: Q218 | AG2: Q318 | AH2: Q418 | AI2: Q119 | AJ2: Q219 | AK2: Q319 | AL2: Q419 | AM2: Q120 | AN2: Q220 | AO2: Q320 | AP2: Q420 | AQ2: Q121 | AR2: Q221 | AS2: Q321 | AT2: Q421 | AU2: Q122 | AV2: Q222 | AW2: Q322 | AX2: Q422 | AY2: Q123 | AZ2: Q223 | BA2: Q323 | BB2: Q423 | BC2: Q124 | BD2: Q224 | BE2: Q324 | BF2: Q424 | BG2: Q125 | BH2: Q225 | BI2: Q325 | BJ2: Q425 | BK2: Q126 | BL2: Q226 | BM2: Q326 | BN2: Q426 | BO2: Q127 | BP2: Q227 | BQ2: Q327 | BR2: Q427 | BT2: 2010 | BU2: =+BT2+1 -> 2011 | BV2: =+BU2+1 -> 2012 | BW2: =+BV2+1 -> 2013 | BX2: =+BW2+1 -> 2014 | BY2: =+BX2+1 -> 2015 | BZ2: =+BY2+1 -> 2016 | CA2: =+BZ2+1 -> 2017 | CB2: =+CA2+1 -> 2018 | ... DB2: =+DA2+1 -> 2044
B3: Eylea | C3: 0 | D3: 0 | E3: 0 | F3: 24.8 | G3: 123.5 | H3: 194 | I3: 244.4 | J3: =837.9-I3-H3-G3 -> 276 | K3: 313.9 | L3: 329.8 | M3: 363.1 | N3: =+BW3-M3-L3-K3 -> 401.9 | O3: 359 | P3: 418.022 | Q3: 448.844 | R3: 518 | S3: 541 | T3: 657.819 | U3: 737.562 | V3: 746 | W3: 781 | X3: 831 | Y3: 854 | Z3: 858 | AA3: 854 | AB3: 919 | AC3: 953 | AD3: 975 | AE3: 984 | AF3: 992 | AG3: 1021.8 | AH3: 1078.9 | AI3: 1074.1 | AJ3: 1160 | AK3: 1187.7 | AL3: 1222.1 | AM3: 1172 | AN3: 1114 | AO3: 1318 | AP3: 1343 | AQ3: 1347 | AR3: 1425 | AS3: 1473 | AT3: 1547 | AU3: 1518 | AV3: 1621 | AW3: 1629 | AX3: 1496 | AY3: 1434 | AZ3: 1500 | BA3: 1448 | BB3: 1338 | BC3: 1202 | BD3: 1231 | BE3: 1144.6 | BF3: 1190 | BG3: 736 | BH3: 754 | BI3: 681 | BJ3: 577 | BK3: 473 | BL3: 412 | BU3: =SUM(C3:F3) -> 24.8 | BV3: =SUM(G3:J3) -> 837.9 | BW3: 1408.7 | BX3: 1736.4 | BY3: 2676 | BZ3: 3323.1 | CA3: 3701.9 | CB3: 4076.7 | CC3: 4644.2 | CD3: =SUM(AM3:AP3) -> 4947 | CE3: =SUM(AQ3:AT3) -> 5792 | CF3: =SUM(AU3:AX3) -> 6264 | CG3: =SUM(AY3:BB3) -> 5720 | CH3: =SUM(Model!BC3:BF3) -> 4767.6 | CI3: =SUM(BG3:BJ3) -> 2748 | CJ3: =CI3*0.7 -> 1923.6 | CK3: =CJ3*0.7 -> 1346.52 | CL3: =CK3*0.7 -> 942.564 | CM3: =CL3*0.7 -> 659.7948 | CN3: =CM3*0.7 -> 461.85636 | CO3: =CN3*0.7 -> 323.29945 | CP3: =CO3*0.7 -> 226.30962 | CQ3: =CP3*0.7 -> 158.41673 | ... CS3: =CR3*0.7 -> 77.624198
B4: Eylea HD | AY4: 0 | AZ4: 0 | BA4: 43 | BB4: 123 | BC4: 200 | BD4: 304 | BE4: 392.3 | BF4: 305 | BG4: 307 | BH4: 393 | BI4: 431 | BJ4: 506 | BK4: 468 | BL4: 596 | CG4: =SUM(AY4:BB4) -> 166 | CH4: =SUM(Model!BC4:BF4) -> 1201.3 | CI4: =SUM(BG4:BJ4) -> 1637 | CJ4: =+CI4*1.1 -> 1800.7 | CK4: =+CJ4*0.7 -> 1260.49 | CL4: =+CK4*0.7 -> 882.343 | CM4: =+CL4*0.7 -> 617.6401 | CN4: =+CM4*0.7 -> 432.34807 | CO4: =+CN4*0.7 -> 302.64365 | CP4: =+CO4*0.7 -> 211.85055 | CQ4: =+CP4*0.7 -> 148.29539 | CR4: =+CQ4*0.7 -> 103.80677 | CS4: =+CR4*0.7 -> 72.66474
B5: Libtayo | X5: 0 | Y5: 0 | Z5: 0 | AA5: 0 | AB5: 0 | AC5: 0 | AD5: 0 | AE5: 0 | AF5: 0 | AG5: 0 | AH5: 14.8 | AI5: 26.8 | AJ5: 40.8 | AK5: 47.6 | AL5: 60.5 | AM5: 61.7 | AN5: 63.3 | AO5: 72 | AP5: 74 | AQ5: 69 | AR5: 78 | AS5: 78 | AT5: 81 | AU5: 79 | AV5: 91 | AW5: =95+31 -> 126 | AX5: =110+42 -> 152 | AY5: 177 | AZ5: 210 | BA5: 232 | BB5: 244 | BC5: 264 | BD5: 297 | BE5: 288.6 | BF5: 367 | BG5: 285 | BH5: 377 | BI5: 365 | BJ5: 425 | BK5: 438 | BL5: 489 | CB5: 14.8 | CC5: 175.7 | CD5: =SUM(AM5:AP5) -> 271 | CE5: =SUM(AQ5:AT5) -> 306 | CF5: =SUM(AU5:AX5) -> 448 | CG5: =SUM(AY5:BB5) -> 863 | CH5: =SUM(Model!BC5:BF5) -> 1216.6 | CI5: =SUM(BG5:BJ5) -> 1452 | CJ5: =CI5*1.01 -> 1466.52 | CK5: =CJ5*1.01 -> 1481.1852 | CL5: =CK5*1.01 -> 1495.9971 | CM5: =CL5*1.01 -> 1510.957 | CN5: =CM5*1.01 -> 1526.0666 | CO5: =CN5*1.01 -> 1541.3273 | CP5: =CO5*1.01 -> 1556.7405 | CQ5: =CP5*1.01 -> 1572.3079 | CR5: =+CQ5*0.9 -> 1415.0771 | CS5: =+CR5*0.7 -> 990.554
B6: Praluent | X6: 0 | Y6: 0 | Z6: 0 | AA6: 0 | AB6: 0 | AC6: 0 | AD6: 0 | AE6: 0 | AF6: 0 | AG6: 0 | AH6: 0 | AI6: 0 | AJ6: 0 | AK6: 0 | AL6: 0 | AM6: 0 | AN6: 47.2 | AO6: 49 | AP6: 55 | AQ6: 43 | AR6: 42 | AS6: 45 | AT6: 40 | AU6: 34 | AV6: 31 | AW6: 30 | AX6: 36 | AY6: 40 | AZ6: 41 | BA6: 40 | BB6: 61 | BC6: 70 | BD6: 56 | BE6: 52.9 | BF6: 63 | BG6: 57 | BH6: 66 | BI6: 67 | BJ6: 73 | BK6: 67 | BL6: 75 | CB6: 181.3 | CC6: 126 | CD6: =SUM(AM6:AP6) -> 151.2 | CE6: =SUM(AQ6:AT6) -> 170 | CF6: =SUM(AU6:AX6) -> 131 | CG6: =SUM(AY6:BB6) -> 182 | CH6: =SUM(Model!BC6:BF6) -> 241.9 | CI6: =SUM(BG6:BJ6) -> 263 | CJ6: =CI6*1.01 -> 265.63 | CK6: =CJ6*1.01 -> 268.2863 | CL6: =CK6*1.01 -> 270.96916 | CM6: =CL6*1.01 -> 273.67885 | CN6: =CM6*1.01 -> 276.41564 | CO6: =CN6*1.01 -> 279.1798 | CP6: =CO6*1.01 -> 281.9716 | CQ6: =CP6*1.01 -> 284.79131 | ... CS6: =CR6*1.01 -> 290.51562
B7: Inmazeb/REGEN-COV | X7: 0 | Y7: 0 | Z7: 0 | AA7: 0 | AB7: 0 | AC7: 0 | AD7: 0 | AE7: 0 | AF7: 0 | AG7: 0 | AH7: 0 | AI7: 0 | AJ7: 0 | AK7: 0 | AL7: 0 | AM7: 0 | AN7: 0 | AO7: 40 | AP7: 146 | AQ7: 262 | AR7: 2591 | AS7: 677 | AT7: 2298 | AU7: 0 | AV7: 0 | AW7: 3 | AX7: 0 | AY7: 2 | AZ7: 2 | BA7: 4 | BB7: 62 | BC7: 1 | BD7: 0 | BE7: 35 | BF7: 40 | BG7: 0 | BH7: 0 | BI7: 0 | BJ7: 37 | BK7: 0 | CB7: 0 | CC7: 0 | CD7: =SUM(AM7:AP7) -> 186 | CE7: =SUM(AQ7:AT7) -> 5828 | CF7: =SUM(AU7:AX7) -> 3 | CG7: =SUM(AY7:BB7) -> 70 | CH7: =SUM(Model!BC7:BF7) -> 76
B8: Lynozyfic | BK8: 11 | BL8: 17
B9: Evkeeza | X9: 0 | Y9: 0 | Z9: 0 | AA9: 0 | AB9: 0 | AC9: 0 | AD9: 0 | AE9: 0 | AF9: 0 | AG9: 0 | AH9: 0 | AI9: 0 | AJ9: 0 | AK9: 0 | AL9: 0 | AM9: 0 | AN9: 0 | AO9: 0 | AP9: 0 | AQ9: 1 | AR9: 2 | AS9: 7 | AT9: 9 | AU9: 8 | AV9: 11 | AW9: 14 | AX9: 15 | AY9: 15 | AZ9: 19 | BA9: 19 | BB9: 24 | BC9: 24 | BD9: 31 | BE9: 32.4 | BF9: 38 | BG9: 31 | BH9: 41 | BI9: 43 | BJ9: 48 | BK9: 46 | BL9: 53 | CB9: 0 | CC9: 0 | CD9: =SUM(AM9:AP9) -> 0 | CE9: =SUM(AQ9:AT9) -> 19 | CF9: =SUM(AU9:AX9) -> 48 | CG9: =SUM(AY9:BB9) -> 77 | CH9: =SUM(Model!BC9:BF9) -> 125.4 | CI9: =SUM(BG9:BJ9) -> 163 | CJ9: =CI9*1.01 -> 164.63 | CK9: =CJ9*1.01 -> 166.2763 | CL9: =CK9*1.01 -> 167.93906 | CM9: =CL9*1.01 -> 169.61845 | CN9: =CM9*1.01 -> 171.31464 | CO9: =CN9*1.01 -> 173.02778 | CP9: =CO9*1.01 -> 174.75806 | CQ9: =CP9*1.01 -> 176.50564 | ... CS9: =CR9*1.01 -> 180.05341
B10: Arcalyst | C10: 4.4 | D10: 5.039 | E10: 5.5 | F10: =19.9-E10-D10-C10 -> 4.961 | G10: 4.4 | H10: 5.5 | I10: 4.8 | J10: =20.2-I10-H10-G10 -> 5.5 | K10: 4.8 | L10: 4.1 | M10: 4 | N10: =+BW10-M10-L10-K10 -> 4.2 | O10: 3 | R10: 3 | S10: 3 | T10: 0 | V10: 3 | W10: 3 | X10: 3 | Y10: 3 | Z10: 5 | AA10: 4 | AB10: 5 | AC10: 4 | AD10: 4 | AE10: 3.9 | AF10: 4.2 | AG10: 3.7 | AH10: 2.7 | AI10: 3.5 | AJ10: 4.2 | AK10: 3 | AL10: 3.8 | AM10: 3 | AN10: 2.7 | AO10: 3 | AP10: 4 | AQ10: 3 | AR10: 0 | AS10: 0 | AT10: 0 | AU10: 0 | AV10: 0 | AW10: 0 | AX10: 0 | AY10: 0 | AZ10: 0 | BA10: 0 | BT10: 25.254 | BU10: =SUM(C10:F10) -> 19.9 | BV10: =SUM(G10:J10) -> 20.2 | BW10: 17.1 | BX10: 14.4 | BY10: 13.5 | BZ10: 15.3 | CA10: 16.5 | CB10: 14.7 | CC10: 14.5 | CD10: =SUM(AM10:AP10) -> 12.7 | CE10: =SUM(AQ10:AT10) -> 3 | CF10: =SUM(AU10:AX10) -> 0 | CG10: =SUM(AY10:BB10) -> 0 | CH10: =SUM(Model!BC10:BF10) -> 0
B11: fianlimab | CI11: 0 | CJ11: 300 | CK11: 600 | CL11: 900 | CM11: 1200 | CN11: =+CM11*1.1 -> 1320 | CO11: =+CN11*1.1 -> 1452 | CP11: =+CO11*1.1 -> 1597.2 | CQ11: =+CP11*1.1 -> 1756.92 | CR11: =+CQ11*1.1 -> 1932.612 | CS11: =+CR11*1.1 -> 2125.8732
B12: itepekimab | CI12: 0 | CJ12: 300 | CK12: 600 | CL12: 900 | CM12: 1200 | CN12: =+CM12*1.1 -> 1320 | CO12: =+CN12*1.1 -> 1452 | CP12: =+CO12*1.1 -> 1597.2 | CQ12: =+CP12*1.1 -> 1756.92 | CR12: =+CQ12*1.1 -> 1932.612 | CS12: =+CR12*1.1 -> 2125.8732
B13: CD3 franchise | CI13: 0 | CJ13: 100 | CK13: 200 | CL13: 300 | CM13: =+CL13*1.01 -> 303 | CN13: =+CM13*1.01 -> 306.03 | CO13: =+CN13*1.01 -> 309.0903 | CP13: =+CO13*1.01 -> 312.1812 | CQ13: =+CP13*1.01 -> 315.30302 | CR13: =+CQ13*1.01 -> 318.45605 | CS13: =+CR13*1.01 -> 321.64061
B14: Sanofi | C14: 85.329 | D14: 84.446 | E14: 79.8 | F14: =326.6-E14-D14-C14 -> 77.025 | G14: 85.005 | H14: 88.988 | I14: 145 | J14: =423.8-I14-H14-G14 -> 104.807 | K14: 99.273 | L14: 85.529 | M14: 134.359 | N14: =+BW14-M14-L14-K14 -> 110.939 | O14: 130.508 | P14: 142.595 | Q14: 132.925 | R14: 135.271 | S14: 173.356 | T14: 195.11 | U14: 224.735 | V14: 165.672 | W14: 219.694 | X14: 163.414 | Y14: 144.392 | Z14: 131.165 | AA14: 210.367 | AB14: 222.128 | AC14: 245.175 | AD14: 199.523 | AE14: 189.5 | AF14: 237.8 | AG14: 256.3 | AH14: 427.6 | AI14: 373.7 | AJ14: 349.1 | AK14: 404.2 | AL14: 427.1 | AM14: =SUM(AM15:AM17) -> 246.9 | AN14: =SUM(AN15:AN17) -> 269.1 | AO14: =SUM(AO15:AO17) -> 353.3 | AP14: =SUM(AP15:AP17) -> 317.1 | AQ14: =SUM(AQ15:AQ17) -> 364.8 | AR14: =SUM(AR15:AR17) -> 437.7 | AS14: =SUM(AS15:AS17) -> 581.8 | AT14: =SUM(AT15:AT17) -> 517.9 | ... AX14: =SUM(AX15:AX17) -> 835.9 | AY14: 798 | AZ14: 944 | BA14: 1065 | BB14: 993 | BC14: 910 | BD14: 1146 | BE14: =SUM(BE15:BE17) -> 1263.4 | BF14: 1213 | BG14: 1183 | BH14: 1444 | BI14: 1617 | BJ14: 1640 | BK14: 1605 | BL14: 2174 | BT14: 311.332 | BU14: =SUM(C14:F14) -> 326.6 | BV14: =SUM(G14:J14) -> 423.8 | BW14: 430.1 | BX14: 541.3 | BY14: 758.9 | BZ14: 658.7 | CA14: 877.2 | CB14: 1111.1 | CC14: 1426.8 | CD14: =SUM(AM14:AP14) -> 1186.4 | CE14: =SUM(AQ14:AT14) -> 1902.2 | CF14: =SUM(AU14:AX14) -> 2855.7 | CG14: =SUM(AY14:BB14) -> 3800 | CH14: =SUM(Model!BC14:BF14) -> 4532.4 | CI14: =SUM(BG14:BJ14) -> 5884 | CJ14: =CI14*1.1 -> 6472.4 | CK14: =CJ14*1.1 -> 7119.64 | CL14: =CK14*1.05 -> 7475.622 | CM14: =CL14*1.05 -> 7849.4031 | CN14: =CM14*1.05 -> 8241.8733 | CO14: =CN14*1.05 -> 8653.9669 | CP14: =+CO14*0.8 -> 6923.1735 | CQ14: =+CP14*0.7 -> 4846.2215 | CR14: =+CQ14*0.6 -> 2907.7329 | CS14: =+CR14*0.6 -> 1744.6397
B15: P&L Share | AM15: 170.9 | AN15: 171.9 | AO15: 212.8 | AP15: 229.6 | AQ15: 260.6 | AR15: 327.6 | AS15: 387 | AT15: 387.8 | AU15: 415.3 | AV15: 496.6 | AW15: 551.1 | AX15: 619 | BE15: 1088.3 | CD15: =SUM(AM15:AP15) -> 785.2 | CE15: =SUM(AQ15:AT15) -> 1363 | CF15: =SUM(AU15:AX15) -> 2082 | CG15: 3136.5 | CH15: 3923.5
B16: Reimbursement | AM16: 80.1 | AN16: 100.6 | AO16: 94.3 | AP16: 93 | AQ16: 105.6 | AR16: 110.9 | AS16: 144.7 | AT16: 127.6 | AU16: 160.8 | AV16: 145.5 | AW16: 160.5 | AX16: 166.9 | BE16: 175.1 | CD16: =SUM(AM16:AP16) -> 368 | CE16: =SUM(AQ16:AT16) -> 488.8 | CF16: =SUM(AU16:AX16) -> 633.7 | CG16: 613 | CH16: 607.9
B17: Other | AM17: =-6.2+2.1 -> -4.1 | AN17: =-6.4+3 -> -3.4 | AO17: =50-4.7+0.9 -> 46.2 | AP17: =-8.4+2.9 -> -5.5 | AQ17: =-6.1+4.7 -> -1.4 | AR17: =-3.5+2.7 -> -0.8 | AS17: =50+3.1-3 -> 50.1 | AT17: =-1+3.5 -> 2.5 | AU17: =50+2.8+2 -> 54.8 | AV17: =28.9+3.9+2.6 -> 35.4 | AW17: -0.2 | AX17: 50 | CD17: =SUM(AM17:AP17) -> 33.2 | CE17: =SUM(AQ17:AT17) -> 50.4 | CF17: =SUM(AU17:AX17) -> 140 | CG17: 50
B18: Dupixent | Z18: 0 | AD18: 139 | AE18: 131.4 | AF18: 209.2 | AG18: 262.6 | AH18: 318.8 | AI18: 373.7 | AJ18: 557.3 | AK18: 633.1 | AL18: 751.5 | AM18: 855 | AN18: 945 | AO18: 1072.6 | AP18: 1172 | AQ18: 1262.9 | AR18: 1499 | AS18: 1662.9 | AT18: 1773.8 | AU18: 1810.4 | AV18: 2091.8 | AW18: 2330.1 | AX18: 2448.9 | AY18: 2485 | AZ18: 2789.4 | BA18: 3097.6 | BB18: 3216.1 | BC18: 3076.8 | BD18: 3556.4 | BE18: 3817.2 | BF18: 3697.6 | BG18: 3670 | BY18: 0 | BZ18: 0 | CA18: 256.5 | CB18: 922 | CC18: 2315.6 | CD18: =SUM(AM18:AP18) -> 4044.6 | CE18: =SUM(AQ18:AT18) -> 6198.6 | CF18: =SUM(AU18:AX18) -> 8681.2 | CG18: =SUM(AY18:BB18) -> 11588.1 | CH18: =SUM(BC18:BF18) -> 14148
B19: Praluent | Z19: 41 | AD19: 63 | AE19: 59.9 | AF19: 73.5 | AG19: 80.2 | AH19: 93.2 | AI19: 63.9 | AJ19: 73.7 | AK19: 69.7 | AL19: 81.4 | AN19: 86.6 | AO19: 91.5 | AP19: 100.9 | AQ19: 104.6 | AR19: 99.4 | AS19: 114.5 | AT19: 102.6 | AU19: 111.4 | AV19: 108.9 | AW19: 113.7 | AX19: 133.4 | AY19: 145.9 | AZ19: 140.3 | BA19: 165.5 | BB19: 187.2 | BC19: 201.3 | BD19: 191.9 | BE19: 191.4 | BF19: 180.4 | BY19: =9.5+1 -> 10.5 | BZ19: =94.4+21.9 -> 116.3 | CA19: =131.4+63.3 -> 194.7 | CD19: =SUM(AM19:AP19) -> 279 | CE19: =SUM(AQ19:AT19) -> 421.1 | CF19: =SUM(AU19:AX19) -> 467.4 | CG19: =SUM(AY19:BB19) -> 638.9 | CH19: =SUM(BC19:BF19) -> 765
B20: Zaltrap | Z20: 16 | AD20: 25 | AE20: 26.3 | AF20: 28.4 | AG20: 25.4 | AH20: 27.8 | AI20: 24.5 | AJ20: 26.6 | AK20: 28.4 | AL20: 28.9 | BY20: 85.7 | BZ20: 72.3 | CA20: 83.8
B21: Kevzara | Z21: 0 | AD21: 9 | AE21: 12.4 | AF21: 24.1 | AG21: 24.9 | AH21: 35.2 | AI21: 33.7 | AJ21: 58.5 | AK21: 54.8 | AL21: 59.7 | AN21: 68.3 | AO21: 70 | AP21: 71.5 | AQ21: 69.1 | AR21: 66.7 | AS21: 97.8 | AT21: 103.9 | AU21: 106.4 | AV21: 82.3 | AW21: 88.1 | AX21: 81.2 | AY21: 78.5 | AZ21: 99.5 | BA21: 95.7 | BB21: 112.2 | BC21: 94.1 | BD21: 109.7 | BE21: 120.1 | BF21: 134.8 | BY21: 0 | BZ21: 0 | CA21: 13.3 | CD21: =SUM(AM21:AP21) -> 209.8 | CE21: =SUM(AQ21:AT21) -> 337.5 | CF21: =SUM(AU21:AX21) -> 358 | CG21: =SUM(AY21:BB21) -> 385.9 | CH21: =SUM(BC21:BF21) -> 458.7
B22: Eylea ROW | BY22: 1413.3 | BZ22: 1872.3 | CA22: 2226.9 | CB22: 2,689 | CC22: 2,897 | CD22: 2962
B23: Bayer | C23: 12.481 | D23: 11.123 | E23: 10.1 | F23: =43.1-E23-D23-C23 -> 9.396 | G23: 12.483 | H23: 9.124 | I23: 26.7 | J23: =70.1-I23-H23-G23 -> 21.793 | K23: 14.907 | L23: 31.104 | M23: 88.583 | N23: =+BW23-M23-L23-K23 -> 85.706 | O23: 125.312 | P23: 97.295 | Q23: 135.853 | R23: 137.095 | S23: 123.846 | T23: 134.237 | U23: 157.596 | V23: 164.809 | W23: 179.592 | X23: 191.896 | Y23: 191.298 | Z23: 181.484 | AA23: 193.939 | AB23: 210.355 | AC23: 236.625 | AD23: 297.133 | AE23: 247.9 | AF23: 262.9 | AG23: 264.4 | AH23: 301.5 | AI23: 264 | AJ23: 289 | AK23: 302.8 | AL23: 320.8 | AM23: 281.4 | AN23: 244.2 | AO23: 299.9 | AP23: 360.6 | AQ23: 322.8 | AR23: 349 | AS23: 365 | AT23: 372.4 | AU23: 385.3 | AV23: 358 | AW23: 333 | AX23: 355.1 | AY23: 357 | AZ23: 377 | BA23: 377 | BB23: 377 | BC23: 356 | BD23: 375 | BE23: =367.6+23.2 -> 390.8 | BF23: 377 | BG23: 344 | BH23: 415 | BI23: 345 | BJ23: 319 | BK23: 287 | BL23: 276 | BU23: =SUM(C23:F23) -> 43.1 | BV23: =SUM(G23:J23) -> 70.1 | BW23: 220.3 | BX23: 495.6 | BY23: 580.5 | BZ23: 744.3 | CA23: 938.1 | CB23: 1076.7 | CC23: 1188.8 | CD23: =SUM(AM23:AP23) -> 1186.1 | CE23: =SUM(AQ23:AT23) -> 1409.2 | CF23: =SUM(AU23:AX23) -> 1431.4 | CG23: =SUM(AY23:BB23) -> 1488 | CH23: =SUM(Model!BC23:BF23) -> 1498.8 | CI23: =SUM(BG23:BJ23) -> 1423 | CJ23: =CI23*0.8 -> 1138.4 | CK23: =CJ23*0.8 -> 910.72 | CL23: =CK23*0.8 -> 728.576 | CM23: =CL23*0.8 -> 582.8608 | CN23: =CM23*0.8 -> 466.28864 | CO23: =CN23*0.8 -> 373.03091 | CP23: =CO23*0.8 -> 298.42473 | CQ23: =CP23*0.8 -> 238.73978 | ... CS23: =CR23*0.8 -> 152.79346
B24: Roche | AN24: 0 | AO24: 0 | AP24: 0 | AQ24: 66.8 | AR24: 168 | AS24: 127.1 | AT24: 0 | AU24: 216.3 | AV24: 8 | AW24: 6 | AX24: 396.4 | AY24: 223 | AZ24: -4 | BC24: 1 | BD24: 3 | CD24: =SUM(AM24:AP24) -> 0 | CE24: =SUM(AQ24:AT24) -> 361.9 | CF24: =SUM(AU24:AX24) -> 626.7 | CG24: =SUM(AY24:BB24) -> 219 | CH24: =SUM(BC24:BF24) -> 4
B25: Other | C25: =7.845+2.122 -> 9.967 | D25: =5.228+1.974 -> 7.202 | E25: =5.9+1.5 -> 7.4 | F25: =24.8+6.6-E25-D25-C25 -> 6.831 | G25: =5.893+0.477 -> 6.37 | H25: =5.893+0.875 -> 6.768 | I25: =5.9+0.9 -> 6.8 | J25: =23.6+2.9-I25-H25-G25 -> 6.562 | K25: =5.893+0.851 -> 6.744 | L25: =5.893+1.223 -> 7.116 | M25: =5.893+1.074 -> 6.967 | N25: =+BW25-M25-L25-K25 -> 7.673 | O25: 7.542 | P25: 7.788 | Q25: 8.166 | R25: 8.445 | S25: 27.837 | T25: 11.451 | U25: 17.529 | V25: 18.072 | W25: 17.381 | X25: 23.1 | Y25: 26.964 | Z25: 51.657 | AA25: 56.44 | AB25: 113.5 | AC25: 61.506 | AD25: 107.073 | AE25: 86.2 | AF25: 110.9 | AG25: 117.3 | AH25: 102.3 | AI25: 22.2 | AJ25: 90.3 | AK25: 103.1 | AL25: 135.2 | AM25: 63.2 | AN25: 211.8 | AO25: 158.6 | AQ25: 50 | AR25: 46 | AS25: 99 | AT25: 86.2 | AU25: 94 | AV25: 59 | AW25: 84 | AX25: 127.7 | AY25: 116 | AZ25: 69 | BA25: =138-3 -> 135 | BB25: 212 | BC25: 117 | BD25: 104 | BE25: =114.2+6 -> 120.2 | BF25: =17+179 -> 196 | BG25: =4+82 -> 86 | BH25: 186 | BI25: =6+198+1 -> 205 | BJ25: =9+12+238 -> 259 | BK25: =7+171+32 -> 210 | BL25: =199 -> 199 | BU25: =SUM(C25:F25) -> 31.4 | BV25: 26.5 | BW25: 28.5 | BX25: 31.9 | BY25: 74.8 | BZ25: 119 | CA25: 338.5 | CB25: 416.8 | CC25: 413.4 | CD25: =SUM(AM25:AP25) -> 433.6 | CE25: =SUM(AQ25:AT25) -> 281.2 | CF25: =SUM(AU25:AX25) -> 364.7 | CG25: =SUM(AY25:BB25) -> 532 | CH25: =SUM(BC25:BF25) -> 537.2 | CI25: =SUM(BG25:BJ25) -> 736 | CJ25: =+CI25*0.9 -> 662.4 | CK25: =+CJ25*0.9 -> 596.16 | CL25: =+CK25*0.9 -> 536.544 | CM25: =+CL25*0.9 -> 482.8896 | CN25: =+CM25*0.9 -> 434.60064 | CO25: =+CN25*0.9 -> 391.14058 | CP25: =+CO25*0.9 -> 352.02652 | CQ25: =+CP25*0.9 -> 316.82387 | ... CS25: =+CR25*0.9 -> 256.62733
B26: Revenue | C26: =+C25+C23+C14+C3+C10 -> 112.177 | D26: =+D25+D23+D14+D3+D10 -> 107.81 | E26: =+E25+E23+E14+E3+E10 -> 102.8 | F26: =+F25+F23+F14+F3+F10 -> 123.013 | G26: =+G25+G23+G14+G3+G10 -> 231.758 | H26: =+H25+H23+H14+H3+H10 -> 304.38 | I26: =+I25+I23+I14+I3+I10 -> 427.7 | J26: =+J25+J23+J14+J3+J10 -> 414.662 | ... O26: =+O25+O23+O14+O3+O10 -> 625.362 | P26: =SUM(P3:P14)+P23+P24+P25 -> 665.7 | Q26: =SUM(Q3:Q14)+Q23+Q24+Q25 -> 725.788 | R26: =SUM(R3:R14)+R23+R24+R25 -> 801.811 | S26: =SUM(S3:S14)+S23+S24+S25 -> 869.039 | T26: =SUM(T3:T14)+T23+T24+T25 -> 998.617 | U26: =SUM(U3:U14)+U23+U24+U25 -> 1137.422 | V26: =SUM(V3:V14)+V23+V24+V25 -> 1097.553 | W26: =SUM(W3:W14)+W23+W24+W25 -> 1200.667 | ... BR26: =SUM(BR3:BR14)+BR23+BR24+BR25 -> 0 | BT26: =SUM(BT3:BT14)+BT23+BT24+BT25 -> 336.586 | BU26: =SUM(BU3:BU14)+BU23+BU24+BU25 -> 445.8 | BV26: =SUM(BV3:BV14)+BV23+BV24+BV25 -> 1378.5 | BW26: =SUM(BW3:BW14)+BW23+BW24+BW25 -> 2104.7 | BX26: =SUM(BX3:BX14)+BX23+BX24+BX25 -> 2819.6 | BY26: =SUM(BY3:BY14)+BY23+BY24+BY25 -> 4103.7 | BZ26: =SUM(BZ3:BZ14)+BZ23+BZ24+BZ25 -> 4860.4 | CA26: =SUM(CA3:CA14)+CA23+CA24+CA25 -> 5872.2 | ... CS26: =SUM(CS3:CS14)+CS23+CS24+CS25 -> 8338.8595
B27: COGS | C27: 0.382 | D27: 0.395 | E27: 0.45 | F27: =BU27-E27-D27-C27 -> 2.989 | G27: 12.298 | H27: 21.843 | I27: 20.145 | J27: =+BV27-I27-H27-G27 -> 30.169 | K27: 29.055 | L27: =27.283+12.33 -> 39.613 | M27: =28.253+10.32 -> 38.573 | N27: =+BW27-M27-L27-K27 -> 48.114 | Z27: =44.534+30.147 -> 74.681 | AD27: =52.733+53.007 -> 105.74 | AE27: =69.2+45.7 -> 114.9 | AF27: =36+55.7 -> 91.7 | AH27: =44+73.2 -> 117.2 | AI27: =70.9+108.3 -> 179.2 | AJ27: =67+85.5 -> 152.5 | AL27: =108.5+115.4 -> 223.9 | AM27: =78.8+138.5 -> 217.3 | AN27: =93.2+173 -> 266.2 | AO27: 122 | AP27: =166+173.5 -> 339.5 | AQ27: =183.2+124.8 -> 308 | AR27: =539.4+154.3 -> 693.7 | AS27: 224 | AT27: =559+170.9 -> 729.9 | AU27: =207.3+197.6 -> 404.9 | AV27: =149.2+147.9 -> 297.1 | AW27: 109 | AX27: =302.2+238.4-133.7-19.7 -> 387.2 | AY27: =208.4+249.1-18.5 -> 439 | AZ27: 163 | BA27: 180.8 | BB27: =258.9+210.2 -> 469.1 | BC27: =240.4+193.4-0.4-23.2 -> 410.2 | BD27: =257.8+222.4-0.8-25.1 -> 454.3 | BE27: =262.3-0.5-26.1+228.8 -> 464.5 | BF27: =270.8+238.6 -> 509.4 | BG27: 217 | BH27: 222 | BI27: 227 | BJ27: 257 | BK27: 209 | BL27: 222 | BU27: 4.216 | BV27: 84.455 | BW27: =118.048+37.307 -> 155.355 | BX27: =129.03+75.988 -> 205.018 | BY27: =151.007+241.702 -> 392.709 | CD27: =SUM(AM27:AP27) -> 945 | CE27: =SUM(AQ27:AT27) -> 1955.6 | CF27: =SUM(AU27:AX27) -> 1198.2 | CG27: =SUM(AY27:BB27) -> 1251.9 | CH27: =SUM(BC27:BF27) -> 1838.4
B28: Gross Margin | C28: =+C26-C27 -> 111.795 | D28: =+D26-D27 -> 107.415 | E28: =+E26-E27 -> 102.35 | F28: =+F26-F27 -> 120.024 | G28: =+G26-G27 -> 219.46 | H28: =+H26-H27 -> 282.537 | I28: =+I26-I27 -> 407.555 | J28: =+J26-J27 -> 384.493 | ... N28: =+N26-N27 -> 562.304 | Z28: =+Z26-Z27 -> 1152.625 | AA28: =+AA26-AA27 -> 1318.746 | AB28: =+AB26-AB27 -> 1469.983 | AC28: =+AC26-AC27 -> 1500.306 | AD28: =+AD26-AD27 -> 1476.989 | AE28: =+AE26-AE27 -> 1396.6 | AF28: =+AF26-AF27 -> 1516.1 | AH28: =+AH26-AH27 -> 1810.6 | AI28: =+AI26-AI27 -> 1585.1 | AJ28: =+AJ26-AJ27 -> 1780.9 | AL28: =+AL26-AL27 -> 1945.6 | AM28: =+AM26-AM27 -> 1610.9 | AN28: =+AN26-AN27 -> 1686.1 | AO28: =+AO26-AO27 -> 2171.8 | AP28: =+AP26-AP27 -> 1960.2 | AQ28: =+AQ26-AQ27 -> 2221.4 | AR28: =+AR26-AR27 -> 4445 | AS28: =+AS26-AS27 -> 3228.9 | ... AX28: =+AX26-AX27 -> 3026.9 | AY28: =AY26-AY27 -> 2723 | AZ28: =AZ26-AZ27 -> 2995 | BA28: =+BA26-BA27 -> 3182.2 | BB28: =+BB26-BB27 -> 2964.9 | BC28: =BC26-BC27 -> 2734.8 | BD28: =BD26-BD27 -> 3092.7 | BE28: =+BE26-BE27 -> 3255.7 | BF28: =+BF26-BF27 -> 3279.6 | BG28: =+BG26-BG27 -> 2812 | BH28: =+BH26-BH27 -> 3454 | BI28: =+BI26-BI27 -> 3527 | BJ28: =+BJ26-BJ27 -> 3627 | BK28: =+BK26-BK27 -> 3396 | BL28: =BL26-BL27 -> 4069 | BU28: =+BU26-BU27 -> 441.584 | BV28: =+BV26-BV27 -> 1294.045 | BW28: =+BW26-BW27 -> 1949.345 | BX28: =+BX26-BX27 -> 2614.582 | BY28: =+BY26-BY27 -> 3710.991 | CD28: =+CD26-CD27 -> 7429 | CE28: =+CE26-CE27 -> 14116.9 | CF28: =+CF26-CF27 -> 10974.3 | CG28: =+CG26-CG27 -> 11865.1 | CH28: =+CH26-CH27 -> 12362.8 | CI28: =CI26*0.9 -> 12875.4 | CJ28: =CJ26*0.9 -> 13134.852 | CK28: =CK26*0.9 -> 13094.35 | CL28: =CL26*0.9 -> 13140.499 | CM28: =CM26*0.9 -> 13364.858 | CN28: =CN26*0.9 -> 13461.114 | CO28: =CO26*0.9 -> 13725.636 | CP28: =CP26*0.9 -> 12178.653 | ... CS28: =CS26*0.9 -> 7504.9735
B29: R&D | C29: 129.392 | D29: 143.149 | E29: 127.924 | F29: =BU29-E29-D29-C29 -> 129.041 | G29: 138.862 | H29: 147.373 | I29: 158.295 | J29: =+BV29-I29-H29-G29 -> 181.024 | K29: 180.299 | L29: 187.463 | M29: 224.045 | N29: =+BW29-M29-L29-K29 -> 268.14 | Z29: 479.206 | AD29: 527.983 | AE29: 198.6 | AF29: 529.3 | AH29: 601.2 | AI29: 641.8 | AJ29: 426.2 | AM29: 583.9 | AN29: 580.1 | AO29: 629 | AP29: 675 | AQ29: 742.9 | AR29: 714.2 | AS29: 592 | AT29: 639 | AU29: 843.8 | AV29: =794.3-14.6 -> 779.7 | AW29: 817 | AX29: =1043.1-1.4 -> 1041.7 | AY29: =1101.2-1.6 -> 1099.6 | AZ29: 974 | BA29: 954.4 | BB29: 1030.9 | BC29: =1248.4-3.8 -> 1244.6 | BD29: =1200-5.3 -> 1194.7 | BE29: =1271.5-2 -> 1269.5 | BF29: 1223.6 | BG29: 1186 | BH29: 1283 | BI29: 1350 | BJ29: 1331 | BK29: 1408 | BL29: 1500 | BU29: 529.506 | BV29: 625.554 | BW29: 859.947 | BX29: 1271.353 | BY29: 1620.577 | CD29: =SUM(AM29:AP29) -> 2468 | CE29: =SUM(AQ29:AT29) -> 2688.1 | CF29: =SUM(AU29:AX29) -> 3482.2 | CG29: =SUM(AY29:BB29) -> 4058.9 | CH29: =SUM(BC29:BF29) -> 4932.4
B30: SG&A | C30: 23.411 | D30: 24.585 | E30: 32.916 | F30: =BU30-E30-D30-C30 -> 36.349 | G30: 58.428 | H30: 47.705 | I30: 46.883 | J30: =+BV30-I30-H30-G30 -> 57.739 | K30: 77.26 | L30: 72.463 | M30: 97.607 | N30: =+BW30-M30-L30-K30 -> 82.085 | Z30: 325.937 | AD30: 409.913 | AE30: 330.8 | AF30: 364.8 | AH30: 491.3 | AI30: 410.8 | AJ30: 251.9 | AM30: =367.3-20.2 -> 347.1 | AN30: 301.4 | AO30: 291 | AP30: 381 | AQ30: 405.6 | AR30: 414.7 | AS30: 391 | AT30: 495 | AU30: 450 | AV30: =476.3-1.1 -> 475.2 | AW30: 467 | AX30: =660.5-3.5 -> 657 | AY30: =601.1-9.6 -> 591.5 | AZ30: 562 | BA30: 533.7 | BB30: 621.8 | BC30: =689-18.8 -> 670.2 | BD30: =758.8-9.7 -> 749.1 | BE30: =714.4-18.2 -> 696.2 | BF30: 680.6 | BG30: 537 | BH30: 542 | BI30: 1146 | BJ30: 691 | BK30: 560 | BL30: 574 | BU30: 117.261 | BV30: 210.755 | BW30: 329.415 | BX30: 504.755 | BY30: 838.526 | CD30: =SUM(AM30:AP30) -> 1320.5 | CE30: =SUM(AQ30:AT30) -> 1706.3 | CF30: =SUM(AU30:AX30) -> 2049.2 | CG30: =SUM(AY30:BB30) -> 2309 | CH30: =SUM(BC30:BF30) -> 2796.1 | CI30: =CI26*0.2 -> 2861.2 | CJ30: =CJ26*0.2 -> 2918.856 | CK30: =CK26*0.2 -> 2909.8556 | CL30: =CL26*0.2 -> 2920.1109 | CM30: =CM26*0.2 -> 2969.9685 | CN30: =CN26*0.2 -> 2991.3588 | CO30: =CO26*0.2 -> 3050.1413 | CP30: =CP26*0.2 -> 2706.3673 | ... CS30: =CS26*0.2 -> 1667.7719
B31: OpEx | C31: =+C30+C29 -> 152.803 | D31: =+D30+D29 -> 167.734 | E31: =+E30+E29 -> 160.84 | F31: =+F30+F29 -> 165.39 | G31: =+G30+G29 -> 197.29 | H31: =+H30+H29 -> 195.078 | I31: =+I30+I29 -> 205.178 | J31: =+J30+J29 -> 238.763 | ... N31: =+N30+N29 -> 350.225 | Y31: =+Y30+Y29 -> 0 | Z31: =+Z30+Z29 -> 805.143 | AA31: =+AA30+AA29 -> 0 | AB31: =+AB30+AB29 -> 0 | AC31: =+AC30+AC29 -> 0 | AD31: =+AD30+AD29 -> 937.896 | AE31: =+AE30+AE29 -> 529.4 | AF31: =+AF30+AF29 -> 894.1 | ... BL31: =+BL30+BL29 -> 2074 | BU31: =+BU30+BU29 -> 646.767 | BV31: =+BV30+BV29 -> 836.309 | BW31: =+BW30+BW29 -> 1189.362 | BX31: =+BX30+BX29 -> 1776.108 | BY31: =+BY30+BY29 -> 2459.103 | CD31: =+CD29+CD30 -> 3788.5 | CE31: =+CE29+CE30 -> 4394.4 | CF31: =+CF29+CF30 -> 5531.4 | CG31: =+CG29+CG30 -> 6367.9 | CH31: =+CH29+CH30 -> 7728.5 | CI31: =+CI29+CI30 -> 2861.2 | CJ31: =+CJ29+CJ30 -> 2918.856 | CK31: =+CK29+CK30 -> 2909.8556 | ... CS31: =+CS29+CS30 -> 1667.7719
B32: OpInc | C32: =+C28-C31 -> -41.008 | D32: =+D28-D31 -> -60.319 | E32: =+E28-E31 -> -58.49 | F32: =+F28-F31 -> -45.366 | G32: =+G28-G31 -> 22.17 | H32: =+H28-H31 -> 87.459 | I32: =+I28-I31 -> 202.377 | J32: =+J28-J31 -> 145.73 | ... N32: =+N28-N31 -> 212.079 | Y32: =+Y28-Y31 -> 0 | Z32: =+Z28-Z31 -> 347.482 | AA32: =+AA28-AA31 -> 1318.746 | AB32: =+AB28-AB31 -> 1469.983 | AC32: =+AC28-AC31 -> 1500.306 | AD32: =+AD28-AD31 -> 539.093 | AE32: =+AE28-AE31 -> 867.2 | AF32: =+AF28-AF31 -> 622 | ... BL32: =+BL28-BL31 -> 1995 | BU32: =+BU28-BU31 -> -205.183 | BV32: =+BV28-BV31 -> 457.736 | BW32: =+BW28-BW31 -> 759.983 | BX32: =+BX28-BX31 -> 838.474 | BY32: =+BY28-BY31 -> 1251.888 | CD32: =+CD28-CD31 -> 3640.5 | CE32: =+CE28-CE31 -> 9722.5 | CF32: =+CF28-CF31 -> 5442.9 | CG32: =+CG28-CG31 -> 5497.2 | CH32: =+CH28-CH31 -> 4634.3 | CI32: =+CI28-CI31 -> 10014.2 | CJ32: =+CJ28-CJ31 -> 10215.996 | CK32: =+CK28-CK31 -> 10184.494 | ... CS32: =+CS28-CS31 -> 5837.2016
B33: Interest Expense | C33: -2.682 | D33: =-4.047+0.998 -> -3.049 | E33: -3.346 | F33: =BU33-E33-D33-C33 -> -8.656 | G33: -10.55 | H33: -10.735 | I33: -10.896 | J33: =+BV33-I33-H33-G33 -> -11.111 | K33: -11.219 | L33: -10.411 | M33: -11.118 | N33: =+BW33-M33-L33-K33 -> -13.92 | Z33: -5.476 | AD33: 15.956 | AE33: 18.2 | AF33: 33.9 | AI33: 66.1 | AJ33: -90.9 | AM33: =40.4+25.3 -> 65.7 | AN33: =-50.2+7.9 -> -42.3 | AO33: -54.8 | AP33: 57.6 | AQ33: =40.5-14.6 -> 25.9 | AR33: =-14.4-31.3 -> -45.7 | AS33: -30.6 | AT33: =15.8-136.3 -> -120.5 | AU33: =20.2-197.4 -> -177.2 | AV33: =-133.6-13.1-17.4 -> -164.1 | AW33: 32.6 | AX33: =195.3-17.4-80.5 -> 97.4 | AY33: =-70.7-18 -> -88.7 | AZ33: =85.3-18.9 -> 66.4 | BB33: =193-18.3+0.5-58.1 -> 117.1 | BC33: -50.7 | BD33: =165.9-14.8 -> 151.1 | BE33: =178.8-13.8 -> 165 | BF33: =-21.6-10.5+212.9 -> 180.8 | BG33: -8.7 | BH33: -3.6 | BI33: -19.3 | BJ33: -12.2 | BK33: -12.9 | BL33: -11 | BU33: -17.733 | BV33: -43.292 | BW33: =-46.437-0.231 -> -46.668 | BX33: =8.157-37.372 -> -29.215 | BY33: =-14.241+6.283 -> -7.958 | CD33: =SUM(AM33:AP33) -> 26.2 | CE33: =SUM(AQ33:AT33) -> -170.9 | CF33: =SUM(AU33:AX33) -> -211.3 | CG33: =SUM(AY33:BB33) -> 94.8 | CH33: =SUM(BC33:BF33) -> 446.2
B34: Pretax Income | C34: =+C32+C33 -> -43.69 | D34: =+D32+D33 -> -63.368 | E34: =+E32+E33 -> -61.836 | F34: =+F32+F33 -> -54.022 | G34: =+G32+G33 -> 11.62 | H34: =+H32+H33 -> 76.724 | I34: =+I32+I33 -> 191.481 | J34: =+J32+J33 -> 134.619 | ... N34: =+N32+N33 -> 198.159 | Y34: =Y32+Y33 -> 0 | Z34: =Z32+Z33 -> 342.006 | AA34: =AA32+AA33 -> 1318.746 | AB34: =AB32+AB33 -> 1469.983 | AC34: =AC32+AC33 -> 1500.306 | AD34: =AD32+AD33 -> 555.049 | AE34: =AE32+AE33 -> 885.4 | AF34: =AF32+AF33 -> 655.9 | ... BL34: =BL32+BL33 -> 1984 | BU34: =+BU32+BU33 -> -222.916 | BV34: =+BV32+BV33 -> 414.444 | BW34: =+BW32+BW33 -> 713.315 | BX34: =+BX32+BX33 -> 809.259 | BY34: =+BY32+BY33 -> 1243.93 | CD34: =+CD32+CD33 -> 3666.7 | CE34: =+CE32+CE33 -> 9551.6 | CF34: =+CF32+CF33 -> 5231.6 | CG34: =+CG32+CG33 -> 5592 | CH34: =+CH32+CH33 -> 5080.5 | CI34: =+CI32+CI33 -> 10014.2 | CJ34: =+CJ32+CJ33 -> 10215.996 | CK34: =+CK32+CK33 -> 10184.494 | ... CS34: =+CS32+CS33 -> 5837.2016
B35: Taxes | C35: -0.216 | D35: -0.863 | E35: 0.562 | F35: =BU35-E35-D35-C35 -> -0.615 | G35: 0 | H35: 0 | I35: 0 | J35: =+BV35-I35-H35-G35 -> 0 | K35: 42.957 | L35: 60.316 | M35: 84.378 | N35: =+BW35-M35-L35-K35 -> 101.347 | Z35: 88.412 | AD35: 381.248 | AE35: 107.4 | AF35: 104.7 | AI35: 85 | AJ35: -31.6 | AM35: 44 | AN35: 21.6 | AO35: 156.2 | AP35: 75.4 | AQ35: 137.8 | AR35: 653.9 | AS35: 184.4 | AT35: 274.4 | AU35: 87.6 | AV35: 111.1 | AW35: 194.1 | AX35: 127.6 | AY35: 40.2 | AZ35: 114.5 | BA35: 103 | BB35: =-12+45.3 -> 33.3 | BC35: -21.3 | BD35: 195.8 | BE35: =152.4+23.4 -> 175.8 | BF35: =40.4+112.5 -> 152.9 | BG35: =+BG34*0.116 -> 125.3148 | BH35: 127.1 | BI35: 303.3 | BJ35: 199.1 | BK35: 104 | BL35: 230.9 | BU35: -1.132 | BV35: 0 | BW35: 288.998 | BX35: 427.673 | BY35: 589.041 | CD35: =SUM(AM35:AP35) -> 297.2 | CE35: =SUM(AQ35:AT35) -> 1250.5 | CF35: =SUM(AU35:AX35) -> 520.4 | CG35: =SUM(AY35:BB35) -> 291 | CH35: =SUM(BC35:BF35) -> 503.2 | CI35: =CI34*0.15 -> 1502.13 | CJ35: =CJ34*0.15 -> 1532.3994 | CK35: =CK34*0.15 -> 1527.6742 | CL35: =CL34*0.15 -> 1533.0582 | CM35: =CM34*0.15 -> 1559.2335 | CN35: =CN34*0.15 -> 1570.4634 | CO35: =CO34*0.15 -> 1601.3242 | CP35: =CP34*0.15 -> 1420.8428 | ... CS35: =CS34*0.15 -> 875.58025
B36: Net Income | C36: =+C34-C35 -> -43.474 | D36: =+D34-D35 -> -62.505 | E36: =+E34-E35 -> -62.398 | F36: =+F34-F35 -> -53.407 | G36: =+G34-G35 -> 11.62 | H36: =+H34-H35 -> 76.724 | I36: =+I34-I35 -> 191.481 | J36: =+J34-J35 -> 134.619 | ... N36: =+N34-N35 -> 96.812 | Y36: =+Y34-Y35 -> 0 | Z36: =+Z34-Z35 -> 253.594 | AA36: =+AA34-AA35 -> 1318.746 | AB36: =+AB34-AB35 -> 1469.983 | AC36: =+AC34-AC35 -> 1500.306 | AD36: =+AD34-AD35 -> 173.801 | AE36: =+AE34-AE35 -> 778 | AF36: =+AF34-AF35 -> 551.2 | ... BL36: =+BL34-BL35 -> 1753.1 | BT36: =+BT34-BT35 -> 0 | BU36: =+BU34-BU35 -> -221.784 | BV36: =+BV34-BV35 -> 414.444 | BW36: =+BW34-BW35 -> 424.317 | BX36: =+BX34-BX35 -> 381.586 | BY36: =+BY34-BY35 -> 654.889 | CD36: =+CD34-CD35 -> 3369.5 | CE36: =+CE34-CE35 -> 8301.1 | CF36: =+CF34-CF35 -> 4711.2 | CG36: =+CG34-CG35 -> 5301 | CH36: =+CH34-CH35 -> 4577.3 | CI36: =+CI34-CI35 -> 8512.07 | CJ36: =+CJ34-CJ35 -> 8683.5966 | CK36: =+CK34-CK35 -> 8656.8203 | ... CS36: =+CS34-CS35 -> 4961.6214 | CT36: =CS36*(1+$CU$40) -> 4812.7728 | CU36: =CT36*(1+$CU$40) -> 4668.3896 | CV36: =CU36*(1+$CU$40) -> 4528.3379 | CW36: =CV36*(1+$CU$40) -> 4392.4878 | CX36: =CW36*(1+$CU$40) -> 4260.7131 | CY36: =CX36*(1+$CU$40) -> 4132.8917 | CZ36: =CY36*(1+$CU$40) -> 4008.905 | DA36: =CZ36*(1+$CU$40) -> 3888.6378 | ... EH36: =EG36*(1+$CU$40) -> 1423.196
B37: EPS | C37: =+C36/C38 -> -0.4875844 | D37: =+D36/D38 -> -0.69115175 | E37: =+E36/E38 -> -0.68534587 | F37: =+F36/F38 -> -0.58659359 | G37: =+G36/G38 -> 0.10785824 | H37: =+H36/H38 -> 0.6964336 | I37: =+I36/I38 -> 1.653121 | J37: =+J36/J38 -> 1.1622119 | ... N37: =+N36/N38 -> 0.82948772 | P37: =+P36/P38 -> 0 | Q37: =+Q36/Q38 -> #DIV/0! | R37: =+R36/R38 -> #DIV/0! | S37: =+S36/S38 -> #DIV/0! | T37: =+T36/T38 -> 0 | U37: =+U36/U38 -> #DIV/0! | V37: =+V36/V38 -> #DIV/0! | W37: =+W36/W38 -> #DIV/0! | ... BL37: =+BL36/BL38 -> 16.538679 | BT37: =+BT36/BT38 -> 0 | BU37: =+BU36/BU38 -> -2.4476769 | BV37: =+BV36/BV38 -> 3.5919294 | BW37: =+BW36/BW38 -> 3.8127145 | BX37: =+BX36/BX38 -> 3.3645702 | BY37: =+BY36/BY38 -> 5.6833203 | CD37: =+CD36/CD38 -> 29.268187 | CE37: =+CE36/CE38 -> 73.558706 | CF37: =+CF36/CF38 -> 41.244911 | CG37: =+CG36/CG38 -> 46.296943 | CH37: =+CH36/CH38 -> 39.519102 | CI37: =+CI36/CI38 -> 79.182047 | CJ37: =+CJ36/CJ38 -> 80.777643 | CK37: =+CK36/CK38 -> 80.528561 | ... CS37: =+CS36/CS38 -> 46.154618
B38: Shares | C38: 89.162 | D38: 90.436 | E38: 91.046 | F38: =+E38 -> 91.046 | G38: 107.734 | H38: 110.167 | I38: 115.83 | J38: =+I38 -> 115.83 | K38: 109.369 | L38: 111.06 | M38: 116.713 | N38: =+M38 -> 116.713 | P38: 113.032 | T38: 115.259 | Y38: 116.466 | Z38: 115.788 | AC38: 117.028 | AD38: 115.876 | AE38: 114.9 | AF38: 114.5 | AH38: 114.8 | AI38: 115.5 | AJ38: 114.6 | AL38: 114.3 | AM38: 115.1 | AN38: 119.3 | AO38: 113.9 | AP38: 112.2 | AQ38: 112.1 | AR38: 112.2 | AS38: 113.9 | AT38: 113.2 | AU38: 114.7 | AV38: 115.4 | AW38: 112.8 | AX38: 114 | AY38: 114 | AZ38: 115.4 | BA38: 113.4 | BB38: 115.2 | BC38: 115.1 | BD38: 116.9 | BE38: 116.2 | BF38: 115.1 | BG38: 111.2 | BH38: 108.6 | BI38: 107.2 | BJ38: 107.5 | BK38: 107.7 | BL38: 106 | BT38: 82.926 | BU38: 90.61 | BV38: 115.382 | BW38: 111.29 | BX38: 113.413 | BY38: 115.23 | CD38: =AVERAGE(AM38:AP38) -> 115.125 | CE38: =AVERAGE(AQ38:AT38) -> 112.85 | CF38: =AVERAGE(AU38:AX38) -> 114.225 | CG38: =AVERAGE(AY38:BB38) -> 114.5 | CH38: =AVERAGE(BC38:BF38) -> 115.825 | CI38: =+BJ38 -> 107.5 | CJ38: =CI38 -> 107.5 | CK38: =CJ38 -> 107.5 | CL38: =CK38 -> 107.5 | CM38: =CL38 -> 107.5 | CN38: =CM38 -> 107.5 | CO38: =CN38 -> 107.5 | CP38: =CO38 -> 107.5 | CQ38: =CP38 -> 107.5 | ... CS38: =CR38 -> 107.5
B40: Revenue y/y | Y40: =Y26/U26-1 -> 0.072296826 | Z40: =Z26/V26-1 -> 0.11822026 | AA40: =AA26/W26-1 -> 0.098344504 | AB40: =AB26/X26-1 -> 0.21244711 | AC40: =AC26/Y26-1 -> 0.23010788 | AD40: =AD26/Z26-1 -> 0.28959607 | AE40: =AE26/AA26-1 -> 0.14616461 | AF40: =AF26/AB26-1 -> 0.093754145 | ... BL40: =BL26/BH26-1 -> 0.16730141 | BU40: =+BU26/BT26-1 -> 0.32447577 | BV40: =+BV26/BU26-1 -> 2.0921938 | BW40: =+BW26/BV26-1 -> 0.5268045 | BX40: =+BX26/BW26-1 -> 0.33966836 | BY40: =+BY26/BX26-1 -> 0.45541921 | BZ40: =+BZ26/BY26-1 -> 0.18439457 | CA40: =+CA26/BZ26-1 -> 0.20817217 | CB40: =+CB26/CA26-1 -> 0.17368278 | ... CH40: =+CH26/CG26-1 -> 0.082656095 | CT40: Maturity | CU40: -0.03
B41: Eylea y/y | AA41: =+AA3/W3-1 -> 0.09346991 | AB41: =+AB3/X3-1 -> 0.10589651 | AC41: =+AC3/Y3-1 -> 0.11592506 | AD41: =+AD3/Z3-1 -> 0.13636364 | AE41: =+AE3/AA3-1 -> 0.15222482 | AF41: =+AF3/AB3-1 -> 0.079434168 | AG41: =+AG3/AC3-1 -> 0.072193075 | AH41: =+AH3/AD3-1 -> 0.1065641 | ... BL41: =+BL3/BH3-1 -> -0.4535809 | BV41: =BV3/BU3-1 -> 32.78629 | BW41: =BW3/BV3-1 -> 0.68122688 | BX41: =BX3/BW3-1 -> 0.23262583 | BY41: =BY3/BX3-1 -> 0.54111956 | BZ41: =BZ3/BY3-1 -> 0.24181614 | CA41: =CA3/BZ3-1 -> 0.11398995 | CB41: =CB3/CA3-1 -> 0.10124531 | CC41: =CC3/CB3-1 -> 0.13920573 | ... CH41: =CH3/CG3-1 -> -0.1665035 | CT41: Discount | CU41: 0.08
...

Sheet Dupixent
A1: Main
B2: Brand Name | C2: Dupixent, fka REGN668
B3: Generic Name | C3: dupilumab
B4: Mechanism | C4: IL-4R subunit antibody
D5: Type I receptor: IL-4Ralpha + common gamma chain
D6: Type II receptor: IL-4Ralpha + IL-13Ralpha1
B7: Indication | C7: atopic dermatitis, asthma, eosinophilic esophagitis (EoE), CSU, bullous pemphigoid
B8: Regulatory | C8: BLA 761055 approved 3/28/2017
C9: sBLA for bullous pemphigoid submitted, FDA decision 2H25, submit in EU 1H25
C10: sBLA for CSU resubmitted, 4/18/25 PDUFA
C11: EC approves childhood EoE
B12: Economics
B13: Administration
B14: Clinical Trials
C15: Phase III lichen simplex chronicus
C17: bullous pemphigoid
C19: Phase 2 in eosinophilic asthma
C23: Phase 1 in asthma

Sheet Eylea
A1: Main
B2: Brand Name | C2: Eylea, Eylea HD
B3: Generic Name | C3: aflibercept
B4: Mechanism | C4: VEGF A/B trap. Intraocular half life estimated to be 65% longer than Lucentis, but on par with Avastin.
B5: Indication | C5: AMD
B6: Regulatory | C6: BLA 125387 approved 11/18/2011
C7: BLA 761355 approved 8/18/2023
C8: FDA submission for Eylea HD pre-filled syringe, decision mid-2025
C9: Filing sBLA for Eylea HD for q4w dosing regimen in Q125, FDA decision 2H25
C10: Filing sBLA for Eylea HD for RVO in Q125, decision 2H25
C11: sBLA two-year wAMD, DME data decision 4/20/2025
B12: Competition | C12: Lucentis, Avastin
B13: Economics | C13: Bayer 50/50 outside US, all Regeneron in the US.
B14: Administration | C14: intravitreal 4mg, HD 8mg
B15: IP
B16: Clinical Trials
C18: Phase III "QUASAR" - Eylea HD in macular edema following RVO
C19: monthly dosing followed by q8w were non-inferior to monthly Eylea
C20: sBLA Q125, prefilled syringe PDUFA mid-2025
C23: Phase 3 - VIEW-1
C24: n = 1217, double blinded, radomized, Lucentis control
C25: 4 groups. Eylea 2 mg/q4 weeks, 0.5 mg/q4 weeks, 2 mg/8 weeks, Lucentis 0.5 mg/q4 weeks.
C26: Primary endpoint was vision maintenance at 1 year, measured by letters readable.
C27: Secondary endpoint was mean change in BCVA.
C28: % completing 52 weeks | H28: Luc | I28: 2mg/q4wk Eyl | J28: 0.5mg/q4wk Eyl | K28: 2mg/q8wk Eyl
C29: Luc: | E29: 0.93 | G29: n | H29: 304 | I29: 304 | J29: 301 | K29: 301
C30: 2mg/q4wk Eyl | E30: 0.96 | G30: Age | H30: 78 | I30: 78 | J30: 78 | K30: 78
C31: 0.5mg/q4wk Eyl | E31: 0.91 | G31: Female % | H31: 57 | I31: 64 | J31: 56 | K31: 59
C32: 2mg/q8wk Eyl | E32: 0.91 | G32: ETDRS BCVA | H32: 54 | I32: 55 | J32: 56 | K32: 56
G33: Vision maint at 1 yr | H33: 0.94 | I33: 0.95 | J33: 0.96 | K33: 0.96
G34: Change vis acquity 1 yr | H34: 8.1 | I34: 10.9 | J34: 6.9* | K34: 7.9* | L34: * p = NS vs luc
G35: % gaining >15 letters | H35: 31 | I35: 38 | J35: 25 | K35: 31
C37: Phase 3 - VIEW-2
C38: n = 1240, double blinded, radomized, Lucentis control
C39: 4 groups. Eylea 2 mg/q4 weeks, 0.5 mg/q4 weeks, 2 mg/8 weeks, Lucentis 0.5 mg/q4 weeks.
C40: Primary endpoint was vision maintenance at 1 year, measured by letters readable.
C41: Secondary endpoint was mean change in BCVA.
C42: % completing 52 weeks
C43: Luc: | E43: 0.91 | H43: Luc | I43: 2mg/q4wk Eyl | J43: 0.5mg/q4wk Eyl | K43: 2mg/q8wk Eyl
C44: 2mg/q4wk Eyl | E44: 0.9 | G44: n | H44: 291 | I44: 309 | J44: 296 | K44: 306
...

Sheet linvoseltamab
A1: Main
B2: Brand
B3: Generic | C3: linvoseltamab
B4: Indication | C4: R/R Multiple Myeloma
B5: Mechanism | C5: BCMAxCD3
B6: Regulatory | C6: resubmitted BLA 1/2025, FDA decision mid-2025
B7: Competition | C7: Tecvayli, Elrexfio already approved
B8: Clinical Trials
C9: Phase II "LINKER-MM1" n=252 MM - NCT03761108
C10: 64% ORR
C14: Phase I with dupilumab in severe food allergy

Sheet odronextamab
A1: Main
B2: Brand
B3: Generic | C3: odronextamab
B4: Indication | C4: R/R FL
B5: MOA | C5: CD20xCD3
B6: Regulatory | C6: resubmitted BLA 1/2025, decision 2H25
B7: Competition | C7: Epkinly (epcoritamab, ABBV/GMAB), Columvi (glofitamab, Roche) 52-63% ORR, 39% CR
C8: Lunsumio (mosunetuzumab), imvotamab (IGM-2323)
B9: Clinical Trials

Sheet pozelimab
A1: Main
B2: Brand
B3: Generic | C3: pozelimab
B4: Indication | C4: CHAPLE, PNH
B5: MOA | C5: C5 antibody
B6: Regulatory | C6: BLA 761339 approved 8/18/2023
B7: Clinical Trials
C8: combination with cemdisiran vs. ravulizumab - 66th ASH
C9: better disease control vs. ravulizumab
C11: Phase III myasthenia gravis with cemdisiran
C12: 2H25 results

Sheet mibavademab
A1: Main
B2: Brand
B3: Generic | C3: mibavademab
B4: Indication | C4: generalized lipodystrophy
B5: MOA | C5: agonist antibody to leptin receptor
B6: Clinical Trials
C7: Phase III initiated
C10: Phase II obesity with tirzepatide
C11: 2H25 data

Sheet DB-OTO
A1: Main
B2: Brand | C2: DB-OTO
B3: Indication | C3: otoferlin deafness
B4: Clinical Trials
C5: Phase I/II
C6: new data mid 2025

Sheet trevogrumab
A1: Main
B2: Brand
B3: Generic | C3: trevogrumab
B4: MOA | C4: GDF8/myostatin mab
B5: Indication | C5: obesity
B6: Clinical Trials
C7: Phase II with semaglutide and +- garetosmab
C8: data 2H25 | H8: =149*26 -> 3874
D9: Lean Mass | E9: Fat Mass | G9: TEAE
C10: Ozempic | D10: -7.9 | E10: -15.3 | F10: =+E10+D10 -> -23.2 | G10: 0.47
C11: Low-dose combo | D11: -3.7 | E11: -16.9 | F11: =+E11+D11 -> -20.6 | G11: 0.486 | H11: 26 weeks
C12: higher-dose | D12: -4.2 | E12: -18.9 | F12: =+E12+D12 -> -23.1 | G12: 0.563 | H12: n=149
C13: triplet | D13: -2 | E13: -25.4 | F13: =+E13+D13 -> -27.4 | G13: 0.638 | H13: TWO DEATHS!?!?

Sheet fianlimab
A1: Main
B2: Brand
B3: Generic | C3: fianlimab
B4: Indication | C4: Metastatic Melanoma
B5: MOA | C5: LAG-3 mab
B6: Clinical Trials
C7: Phase III with Libtayo vs. pembro 1L MM
C8: 2H25 results
C11: Phase II with Libtayo 1L NSCLC
C12: 1H25 results

Sheet garetosmab
A1: Main
B2: Brand
B3: Generic | C3: garetosmab
B4: Indication | C4: fibrodysplasia ossificans progressiva
B5: MOA | C5: activin A mab
B6: Clinical Trials
C7: Phase III - reports 2H25

Sheet itepekimab
A1: Main
B2: Brand
B3: Generic | C3: itepekimab
B4: MOA | C4: IL-33
B5: Indication | C5: CRSsNP
B6: Clinical Trials
C7: Phase II CRS without NP
C10: Phase III "AERIFY-1" COPD
C11: data 2H25, BLA 2H25
C13: Phase III "AERIFY-2" COPD
C16: more Phase III studies to be initiated 1H25

Sheet REGN7508
A1: Main
B2: Brand | C2: REGN7508
B3: Indication
B4: MOA | C4: Factor XI catalytic domain antibody
C5: Designed to maximize anticoagulant activity while minimizing bleeding risk
B6: Clinical Trials
C7: Phase III - initiate 2025
C11: Phase II
C12: robust antithrombotic effect, no clinically relevant bleeding

Sheet REGN9933
A1: Main
B2: Brand | C2: REGN9933
B3: Indication
B4: MOA | C4: Factor XI A2 domain antibody
C5: For patients with highest bleeding risk
B6: Clinical Trials
C7: Phase III - initiate 2025
C11: Phase II
C12: robust antithrombotic effect, no clinically relevant bleeding

Sheet Arcalyst
A1: Main
B2: Brand Name | C2: Arcalyst, fka IL-1 TRAP
B3: Generic Name | C3: rilonacept
B4: Indication | C4: Gout and CAPS (CIAS1-associated periodic syndrome, Cryopyrin-Associated Periodic Syndromes).
C5: 1000 patients WW
B6: Mechanism | C6: IL-1 receptor.
C7: IL1 is a Protein secreted naturally by the body
C8: acts as a messenger to help regulate immune and inflammitory responses by attaching to cell surface receptors in cells that participate in the immune system
C9: In excess it is harmful and has been linked to a variety of inflammitory diseases
C10: The Il 1 trap is designed to attach to and neutralize IL1 in the bloodstream before it can generate signals that can trigger disease activity
C11: Once attached to the trap, IL1 cannot bind to the cell surface and is flushed from the body together with the trap
B12: Clinical Trials
C13: 6/10/2005 - Phase II results
C14: preliminary results from once weekly dosing of interleukin-1 trap in patients with cias1 associated periodic syndrome (caps)
D15: (a family of autoinflammitory diseases)
C16: all 4 patients enrolled to date experienced a positive response to a subcutaneous loading dose regimen
D17: this includes a sizable reduction in daily patient diary scores and acute phase reactant levels
C18: the study was conducted with the National Institute of Arthriits and Musculoskeletal and Skin Diseases
D19: The senior investigators in this study are Raphaela Goldbach-Mansky, M.D., Staff Clinician with NIAMS, and Daniel Kastner, M.D., Ph.D., Chief, Genetics and Genomics Branch with NIAMS
C21: Phase 3 gout study (n = 248)
C22: 16 week study, Arcalyst dosed SC.
D23: PBO | E23: 80 mg Arcalyst | F23: 160 mg Artcalyst
C24: # gout flares | D24: 1.23 | E24: 0.35 | F24: 0.34
C26: Drug appears to reduce gout flares, which occur even with urate inhibitors.
C27: Would be used when patients start on urate inhibitors, but just be used short term. REGN estimates ~750K/year in US.
C28: sBLA expected to be filed in 2011.

Sheet Zaltrap
A1: Main
B2: Brand Name | C2: Zaltrap
B3: Generic Name | C3: aflibercept
B4: Mechanism | C4: VEGF A/B trap.
B5: Indication | C5: Colorectal cancer
B6: Competition
B7: Economics | C7: 50/50 with SNY
B8: Administration | C8: IV
B9: Clinical Trials
C11: Phase 3 Refractory metastatic colorectal cancer (VELOUR)'
C12: ECOG 3200 | E12: Velour
C13: FOLFOX | D13: AV + Folfox | E13: FOLFIRI | F13: ZAL + FOL
B14: n | C14: 292 | D14: 293 | E14: 612 | F14: 614
B15: ORR | C15: 0.086 | D15: 0.227 | E15: 0.111 | F15: 0.198
B16: Median PFS (mths) | C16: 4.5 | D16: 7.5 | E16: 4.7 | F16: 6.9
B17: Median OS (mths) | C17: 10.8 | D17: 12.9 | E17: 12.1 | F17: 13.5
C19: Expect BLA filing by end of year.
C20: Not clear why this drug would garner much market share
C22: Phase 3, 2nd line NSCLC
C23: n = 913, in combination with Docetaxel
C24: Did not improve OS

Sheet VEGF Trap
A1: Main
B2: Brand Name | C2: ZALTRAP
B3: Generic Name | C3: afilbercept
B4: Indication | C4: Cancer
B5: Mechanism | C5: VEGF and PLGF binder.
B6: Economics | C6: WW collaboration with SNY who pays 100% of expenses. REGN repays 50% of dev costs paid by SNY out of VEGF trap profits.
B7: Clinical Trials
C8: Phase III HRPC n=1200 - Taxotere combination - 2009 data? "VENICE"?
C10: Phase III mNSCLC 2L n=900 - Taxotere combination - 2010 data? "VITAL"?
C12: Phase III mCRC 2L n=1200 - IFL combination - 2010 data? "VELOUR"?
C14: Phase III mPC n=650 "VANILLA"? - terminated
C16: Phase II malignant ascites
C17: 77.5% response rate, 80% rate of doubling in time to paracentesis in symptomatic malignant ascites.
C18: Final data expected in 1H09 and may support approval - Birchenough.
C20: Phase II GBM - AAN 2008, ASCO 2008
C21: 30% RR, 3% 6-month PFS vs 43% with Avastin. Lower PFS was a function of patient advancement.
C22: 32% RR update?
C24: Phase II mOC - Failed
C25: n=215 failed to demonstrate >5% RR with ORR of 4.6% to 0.9%.
... C28: Abstract: Background: Vascular endothelial growth factor (VEGF) is an important target in MCRC. Aflibercept (VEGF Trap) is a recombinant fusion protein of the human VEGFR1 and R2 extracellular domains and the Fc portion of human IgG1. Methods: This is an open-label, multi-centre, 2-stage phase II trial in pts with MCRC. Eligibility criteria: >1 prior systemic therapy for MCRC, ECOG < 2. Exclusion criteria: prior treatment with a VEGF or VEGFR inhibitor other than bevacizumab (BEV). IV VEGF Trap (4 mg/kg) was administered every 2 weeks (1 cycle). The primary endpoint was RR and 4-month PFS. Pts were enrolled in two cohorts: BEV naïve and prior BEV. Planned sample size in each cohort was 40 pts. Results: In total, 51 pts were enrolled (BEV naive = 24 pts; prior BEV = 27; median age=59, range 39-80; M:F = 30:21; ECOG 0:1:2 = 21:27:3; median # prior regimens for MCRC = 2, range 1-6). After 287 cycles of therapy, most common treatment adverse events (TAEs) of any grade were (#pts): fatigue (40), hypertension (28), proteinuria (25), headache (22), voice alteration (16), anorexia (12), and joint pain (9). Grade 3+ TAEs in > 1 pt were (#pts): hypertension (4), proteinuria (4), fatigue (3), headache (3). One pt died on treatment due to PD. In the BEV naïve cohort (n=24), 4 pts were inevaluable: 7 pts maintained 4-mo PFS, disease control rate (PR + SD > 16 wks) = 29% [95% CI 13-51%], and median PFS was 2.0 mo [95% CI 1.7- not reached(NR)]. In the prior BEV cohort (n=27), 1 pt was inevaluable. There was 1 confirmed PR and 7 pts maintained 4-mo PFS, disease control rate 30% [95% CI 14-50%], and median PFS was 3.4 mo [95% CI 1.9-NR]. Conclusions: Aflibercept (VEGF Trap) is well tolerated in pretreated pts with MCRC. Single agent activity has been observed in the prior BEV cohort, and accrual is ongoing in this stratum. Based on the study results, studies of aflibercept as single agent or in combination should be explored.

Sheet Praluent
A1: Main
B2: Brand Name | C2: Praluent
B3: Generic Name | C3: REGN727
B4: Mechanism | C4: fully human monoclonal antibody against PCSK9 antibody (proprotein convertase subtilisin/kexin type 9)
B5: Indication | C5: reduce LDL
B6: Competition | C6: statins
B7: Economics | C7: Sanofi
B8: Administration | C8: IV, SC
B9: Clinical Trials
C10: Phase 2 in hypercholesterolemia pts in combo w statin tx -- started in early 2011
C13: Phase 1 in healthy volunteers -- May 2010 announced interim analyses of Ph1 healthy volunteer study
C14: dose-escalating, randomized, double-blind, each dosing cohort consisted of 6 tx and 2 placebo pts
C15: July 2010 further data presented
C16: at highest IV dose, single dose achieved >60% max mean reduction of LDL fr baseline that lasted for >1 mo
C17: at highest SC dose, single dose achieved >60% mas mean reduction of LDL fr baseline that lasted for >2 wks
C19: Phase 1 in hyperlipidemic pts (familial & non-familial hypercholesterolemia) -- July 2010 interim analyses
C20: dose-escalating, randomized, double-blind, on pts on stalbe doses of statins whose LDL levels were >100 mg/dL
C21: at highest dose tested (at the time), in 11 pts, a single dose achieved ~40% max mean add'l reduction of LDL fr baseline

Sheet Libtayo
A1: Main
B2: Brand | C2: Libtayo
B3: Generic | C3: cemiplimab
B4: Indication | C4: cSCC
B5: Regulatory | C5: BLA 761097 approved 9/28/2018
C6: submit sBLA for adjuvant CSCC - 1H25
B7: Clinical Trials
C8: Phase III adjuvant CSCC
C9: DFS improvement
C11: Phase III intralesional early-stage CSCC

Sheet Kevzara
A1: Main
B2: Brand Name | C2: Kevzara
B3: Generic Name | C3: REGN88
B4: Mechanism | C4: fully human monoclonal antibody against IL-R6
B5: Indication | C5: RA, ankylosing spondylitis
B6: Competition | C6: Actemra (IL-6R antibody tocilizumab fr DNA), TNFs, etc
B7: Regulatory | C7: EC approved polymyalgia rheumatica and pJIA
B8: Economics | C8: Sanofi
B9: Administration
B10: Clinical Trials
C11: Phase 2/3 in RA
C14: Phase 2 in ankylosing spondylitis
C17: Phase 1 data from EULAR 2010 and ACR 2010
C18: dose-related reductions in biomarkers of inflammation
